Workbook
Name adj_allocation_rate: 'ARF Projections'!#REF!
Name adj_upfront_commission: 'ARF Projections'!$C$72
Name Altered_Initial_Commission_Indicator: 'ARF Projections'!$C$71
Name Commission_Uplift_Factor: 'ARF Projections'!$C$63
Name Current_Age: 'ARF Projections'!$C$43
Name Custom_Reg_Inc_Perc_annual: 'ARF Projections'!$C$51
Name Custom_Regular_Income_Perc_Monthly: 'ARF Projections'!$D$51
Name Default_IncomeRate_table: Parameters!$C$73:$E$75
Name External_Fund_Charge_Monthly: 'ARF Projections'!$D$60
Name Fund_Charge_Monthly: 'ARF Projections'!$D$61
Name Fund_Rates_Table: Parameters!$C$54:$G$67
Name Fund_Zero_Year: 'ARF Projections'!$C$67
Name Fund_Zero_Year_2: 'ARF Projections'!$C$686
Name Growth_Rate_1: 'ARF Projections'!$C$45
Name Growth_Rate_1_Monthly: 'ARF Projections'!$D$45
Name Growth_Rate_2: 'ARF Projections'!$C$46
Name Growth_Rate_2_Monthly: 'ARF Projections'!$D$46
Name Gtee_Charge_Monthly: 'ARF Projections'!$D$62
Name Gtee_Flag: 'ARF Projections'!$C$48
Name Income_Escalation_Rate_Annual: 'ARF Projections'!$C$54
Name Income_Escalation_Rate_Monthly: 'ARF Projections'!$D$54
Name Income_Type: 'ARF Projections'!$C$49
Name Initial_income__Perc_used: 'ARF Projections'!$C$52
Name Minimum_Fund_Value: 'ARF Projections'!$C$66
Name new_allocation_rate: 'ARF Projections'!$C$75
Name new_upfront_commission: 'ARF Projections'!$C$74
Name Ongoing_Commission_Monthly: 'ARF Projections'!$D$65
Name Product_Code: 'ARF Projections'!$C$39
Name Product_Parameters: Parameters!$D$5:$P$25
Name Rate_Of_Return_Monthly: 'ARF Projections'!$D$47
Name RateOfReturn_Max: 'ARF Projections'!$C$44
Name Regular_Income_Amount: 'ARF Projections'!$C$53
Name Regular_Income_Start_Age: 'ARF Projections'!$C$55
Name Regular_Income_Start_Month: 'ARF Projections'!$C$56
Name SinglePrem: 'ARF Projections'!$C$42
Name special_deal_indicator: 'ARF Projections'!$C$68
Name special_deal_level: 'ARF Projections'!$C$69
Name Start_Date: 'ARF Projections'!$C$40
Name SurrederPenalty_Table: Parameters!$C$26:$E$27
Name Surrender_Penalty_flag: 'ARF Projections'!$C$58
Name Surrender_Penalty_table: Parameters!$C$26:$E$27
Name upfront_commission: 'ARF Projections'!$C$64
Name Weighted_Guarantee_Charge: 'ARF Projections'!$T$43
Name Weighted_RateOfReturn_Annual: 'ARF Projections'!$T$40
Name Year_of_Income_Reduction: 'ARF Projections'!$B$70
Name Year_Of_Income_Reduction_2: 'ARF Projections'!$C$687

Sheet Version Control
B2: Version | C2: Date | D2: Change By | E2: Review By | F2: Description
B3: V7 | C3: 45807 | D3: Hugh Gannon | F3: Addition of A4, A5, B4, B5 and F1-F5 product codes
B4: V7.1 | C4: 45833 | D4: Gearóid Hughes | F4: Fix for Surrender Penalty Text given 1A enhancement
B5: V8 | C5: 45838 | D5: Hugh Gannon | F5: Updated external fund manager AMCs in line with proposed new share classes
B6: V9 | C6: 45887 | D6: Gearóid Hughes | E6: Hugh Gannon | F6: Updated to allow for Initial Commission Special Deal
B7: V10 | C7: 45926 | D7: Gearóid Hughes | E7: Hugh Gannon | F7: Updated to allow for changes to the allocation rate and initial commission on a case by case basis
B8: V10.1 | C8: 45947 | D8: Gearóid Hughes | F8: Minor update to fix rounding error
B9: V10.2 | C9: 45953 | D9: Gearóid Hughes | F9: Update to fix error with commission calculation
B10: V10.3 | C10: 45954 | D10: Gearóid Hughes | F10: Update to fix reference error
B11: V11 | C11: 46041 | D11: Gearóid Hughes | E11: Hugh Gannon | F11: Updated to reflect change in Actuarial Standard Practice. Upper Rate of Return should reflect chosen asset allocation, limited to a maximum of 6%. Fixes to the RIY calculation
B12: V11.1 | C12: 46070 | D12: Gearóid Hughes | E12: Hugh Gannon | F12: Updated to include extra allocation/initial charge trade-off for upfront commission
B13: V11.2 | C13: 46080 | D13: Gearóid Hughes | E13: Hugh Gannon | F13: Updated to add the new HSBC funds, detailed change notes in email
B14: V11.3 | C14: 46080 | D14: Gearóid Hughes | E14: Hugh Gannon | F14: Updated parameters for AMC and surrender penalties
B15: V12 | C15: 46080 | D15: Gearóid Hughes | E15: Hugh Gannon | F15: Signed off on Updates Included change to the maximum initial commission on the Parameters tab (cell E78) to increase this to 6% (to allow for bonus 1% initial commission)
B16: V13 | C16: 46141 | D16: Gearóid Hughes | F16: Updated prescribed assumptions

Sheet Overview
A1: Overview
A3: Cell Color Key | B3: Cell Color Key | C3: Description
C4: Product and Fund Parameters
C5: Customer specific inputs
C6: Formulas
C7: A flag used where a change in formula occurs during the projection
C8: Regulatory/ ASP inputs
C9: Other Hardcoded Numbers
C10: Summary tables
A14: User Guide | B14: Step | C14: Description
B15: 1 | C15: Update Customer specific inputs on ARF Projection tab
A18: Sheet Description | B18: Sheet Name | C18: Description | D18: HyperLink
B19: Overview | C19: In this tab: (1.) The key information about the EUC is documented. (2.) The user instructions for updating this model is documented. (3.) The purpose of each sheet is also documented. | D19: =A1 -> Overview
B20: Parameters | C20: This tab contains: - Product specific parameters - Fund specific parameters - Regulatory specific inputs. This tab should only be updated if there are changes to any of the above. | D20: =B20 -> Parameters
B21: ARF Projection | C21: This tab projections the ARF over the lifetime of the policy on 2 ASP prescribed growth rates - Customer specifc inputs should be updated here | D21: =B21 -> ARF Projection
B22: Inputs for PointOfIssue Doc | C22: This tab contains inputs for the Point of Issue Disclosure Template | D22: =B22 -> Inputs for PointOfIssue Doc

Sheet Parameters
A1: Parameters
E5: Commission | I5: Surrender Penalty
C6: Product Version | D6: Product Code | E6: SP Upfront Base | F6: SP Upfront Special Deal | G6: Fund Based Commission | H6: Admin Charge | I6: 1 | J6: 2 | K6: 3 | L6: 4 | M6: 5 | N6: 6 | O6: 7 | P6: 8
C7: A | D7: A1 | E7: 0 | F7: =E7+IF(special_deal_indicator = "Yes", special_deal_level, 0) -> 0 | G7: 0.0075 | H7: 0.011 | I7: 0 | J7: 0 | K7: 0 | L7: 0 | M7: 0 | N7: 0 | O7: 0 | P7: 0
C8: A | D8: A2 | E8: 0.01 | F8: =E8+IF(special_deal_indicator = "Yes", special_deal_level, 0) -> 0.01 | G8: 0.006 | H8: 0.011 | I8: 0.02 | J8: 0.01 | K8: 0.01 | L8: 0 | M8: 0 | N8: 0 | O8: 0 | P8: 0
C9: A | D9: A3 | E9: 0.02 | F9: =E9+IF(special_deal_indicator = "Yes", special_deal_level, 0) -> 0.02 | G9: 0.005 | H9: 0.011 | I9: 0.03 | J9: 0.03 | K9: 0.02 | L9: 0.02 | M9: 0.01 | N9: 0 | O9: 0 | P9: 0
C10: A | D10: A4 | E10: 0.03 | F10: =E10+IF(special_deal_indicator = "Yes", special_deal_level, 0) -> 0.03 | G10: 0.0035 | H10: 0.011 | I10: 0.04 | J10: 0.03 | K10: 0.03 | L10: 0.02 | M10: 0.01 | N10: 0 | O10: 0 | P10: 0
C11: A | D11: A5 | E11: 0.04 | F11: =E11+IF(special_deal_indicator = "Yes", special_deal_level, 0) -> 0.04 | G11: 0.0025 | H11: 0.011 | I11: 0.05 | J11: 0.04 | K11: 0.03 | L11: 0.02 | M11: 0.01 | N11: 0 | O11: 0 | P11: 0
C12: B | D12: B1 | E12: 0 | F12: =E12+IF(special_deal_indicator = "Yes", special_deal_level, 0) -> 0 | G12: 0.005 | H12: 0.0085 | I12: 0 | J12: 0 | K12: 0 | L12: 0 | M12: 0 | N12: 0 | O12: 0 | P12: 0
C13: B | D13: B2 | E13: 0.01 | F13: =E13+IF(special_deal_indicator = "Yes", special_deal_level, 0) -> 0.01 | G13: 0.0035 | H13: 0.0085 | I13: 0.02 | J13: 0.01 | K13: 0.01 | L13: 0 | M13: 0 | N13: 0 | O13: 0 | P13: 0
C14: B | D14: B3 | E14: 0.02 | F14: =E14+IF(special_deal_indicator = "Yes", special_deal_level, 0) -> 0.02 | G14: 0.0025 | H14: 0.0085 | I14: 0.03 | J14: 0.03 | K14: 0.02 | L14: 0.02 | M14: 0.01 | N14: 0 | O14: 0 | P14: 0
C15: B | D15: B4 | E15: 0.03 | F15: =E15+IF(special_deal_indicator = "Yes", special_deal_level, 0) -> 0.03 | G15: 0.001 | H15: 0.0085 | I15: 0.04 | J15: 0.03 | K15: 0.03 | L15: 0.02 | M15: 0.01 | N15: 0 | O15: 0 | P15: 0
C16: B | D16: B5 | E16: 0.04 | F16: =E16+IF(special_deal_indicator = "Yes", special_deal_level, 0) -> 0.04 | G16: 0 | H16: 0.0085 | I16: 0.05 | J16: 0.04 | K16: 0.03 | L16: 0.02 | M16: 0.01 | N16: 0 | O16: 0 | P16: 0
C17: C | D17: C1 | E17: 0 | F17: =E17+IF(special_deal_indicator = "Yes", special_deal_level, 0) -> 0 | G17: 0.0025 | H17: 0.006 | I17: 0 | J17: 0 | K17: 0 | L17: 0 | M17: 0 | N17: 0 | O17: 0 | P17: 0
C18: C | D18: C2 | E18: 0.01 | F18: =E18+IF(special_deal_indicator = "Yes", special_deal_level, 0) -> 0.01 | G18: 0.0012 | H18: 0.006 | I18: 0.02 | J18: 0.01 | K18: 0.01 | L18: 0 | M18: 0 | N18: 0 | O18: 0 | P18: 0
... C25: F | D25: F5 | E25: 0.04 | F25: =E25+IF(special_deal_indicator = "Yes", special_deal_level, 0) -> 0.04 | G25: 0.005 | H25: 0.0135 | I25: 0.05 | J25: 0.04 | K25: 0.03 | L25: 0.02 | M25: 0.01 | N25: 0 | O25: 0 | P25: 0
C28: Growth Assumptions
C29: Equity | D29: 0.072 | E29: ASP-LA8 | F29: ASP LA-8 | G29: Figures effecive from 01/01/2025
C30: Property | D30: 0.072 | E30: ASP-LA8
C31: Fixed Interest | D31: 0.0425 | E31: ASP-LA8
C32: Cash | D32: 0.032 | E32: ASP-LA8
C35: Fund | D35: Equity | E35: Property | F35: Fixed Income | G35: Cash
C36: Growth Assumptions | D36: =D29 -> 0.072 | E36: =D30 -> 0.072 | F36: =D31 -> 0.0425 | G36: =D32 -> 0.032
C37: Strategy Select 30 | D37: 0.3 | E37: 0 | F37: 0.7 | G37: 0 | H37: =1-SUM(D37:G37) -> 0
C38: Strategy Select 50 | D38: 0.5 | E38: 0 | F38: 0.5 | G38: 0 | H38: =1-SUM(D38:G38) -> 0
C39: Strategy Select 75 | D39: 0.75 | E39: 0 | F39: 0.25 | G39: 0 | H39: =1-SUM(D39:G39) -> 0
C40: Allianz Best Styles Global Equity SRI | D40: 1 | E40: 0 | F40: 0 | G40: 0 | H40: =1-SUM(D40:G40) -> 0
C41: Allianz Advanced Fixed Income Short Duration | D41: 0 | E41: 0 | F41: 1 | G41: 0 | H41: =1-SUM(D41:G41) -> 0
C42: Allianz Advanced Fixed Income Euro | D42: 0 | E42: 0 | F42: 1 | G42: 0 | H42: =1-SUM(D42:G42) -> 0
C43: Allianz Dynamic Multi Asset Strategy SRI 75 | D43: 0.75 | E43: 0 | F43: 0.25 | G43: 0 | H43: =1-SUM(D43:G43) -> 0
C44: Allianz Dynamic Multi Asset Strategy SRI 50 | D44: 0.5 | E44: 0 | F44: 0.5 | G44: 0 | H44: =1-SUM(D44:G44) -> 0
C45: Allianz Dynamic Multi Asset Strategy SRI 15 | D45: 0.15 | E45: 0 | F45: 0.85 | G45: 0 | H45: =1-SUM(D45:G45) -> 0
C46: HSBC EURO STOXX 50 UCITS ETF | D46: 1 | E46: 0 | F46: 0 | G46: 0 | H46: =1-SUM(D46:G46) -> 0
C47: HSBC MSCI World UCITS ETF | D47: 1 | E47: 0 | F47: 0 | G47: 0 | H47: =1-SUM(D47:G47) -> 0
C48: HSBC S&P 500 UCITS ETF | D48: 1 | E48: 0 | F48: 0 | G48: 0 | H48: =1-SUM(D48:G48) -> 0
C49: Allianz Euro Cash | D49: 0 | E49: 0 | F49: 0 | G49: 1 | H49: =1-SUM(D49:G49) -> 0
C54: Fund | D54: Guarantee Charge | E54: Growth Rate p.a. | F54: Growth Rate p.m. | G54: External Fund Manager Charge
C55: Strategy Select 30 | D55: 0.0065 | E55: =SUMPRODUCT($D$36:$G$36,D37:G37) -> 0.05135 | F55: =(1+E55)^(1/12)-1 -> 0.0041816398 | G55: 0.0025 | H55: Ext FM charges updated with new fund classes mid 2025
C56: Strategy Select 50 | D56: 0.0075 | E56: =SUMPRODUCT($D$36:$G$36,D38:G38) -> 0.05725 | F56: =(1+E56)^(1/12)-1 -> 0.0046500445 | G56: 0.0025
C57: Strategy Select 75 | D57: 0.0085 | E57: =SUMPRODUCT($D$36:$G$36,D39:G39) -> 0.064625 | F57: =(1+E57)^(1/12)-1 -> 0.0052321924 | G57: 0.0025
...

Sheet ARF Projections
A1: ARF Projections
B3: Year | C3: A | D3: B | E3: C | F3: D | G3: E | L3: € | M3: €
C4: Total amount of premiums paid into the policy to date | D4: Projected investment growth to date | E4: Projected expenses and charges to date | F4: Cumulative gross income to date | G4: Projected policy value after income | L4: Contributions payable in that year | M4: Projected total intermediary and sales remuneration payable in that year
B5: 1 | C5: =+SUMPRODUCT($I$79:$I$678,$W$79:$W$678) -> 100000 | D5: =SUMPRODUCT($M$79:$M$678,$W$79:$W$678) -> 5853.5778 | E5: =-SUMPRODUCT($N$79:$N$678,$W$79:$W$678)+VLOOKUP($B5*12,$C$78:$T$677,18,FALSE)-$J$79 -> 6385.4821 | F5: =-SUMPRODUCT($R$79:$R$678,$W$79:$W$678) -> 4023.5435 | G5: =VLOOKUP(B5+1,$B$78:$N$677,10,FALSE)-VLOOKUP($B5*12,$C$78:$T$677,18,FALSE) -> 95444.552 | L5: =C5 -> 100000 | M5: =-SUMIF($B$79:$B$678,B5,$S$79:$S$678) -> 4250.8721 | N5: =M5/G5 -> 0.044537608
B6: 2 | C6: =+SUMPRODUCT($I$79:$I$678,$W$79:$W$678) -> 100000 | D6: =SUMPRODUCT($M$79:$M$678,$X$79:$X$678) -> 11732.878 | E6: =-SUMPRODUCT($N$79:$N$678,$X$79:$X$678)+VLOOKUP($B6*12,$C$78:$T$677,18,FALSE)-$J$79 -> 6765.1612 | F6: =-SUMPRODUCT($R$79:$R$678,$X$79:$X$678) -> 8127.5579 | G6: =VLOOKUP(B6+1,$B$78:$N$677,10,FALSE)-VLOOKUP($B6*12,$C$78:$T$677,18,FALSE) -> 96840.159 | L6: 0 | M6: =-SUMIF($B$79:$B$678,B6,$S$79:$S$678) -> 251.96793 | N6: =M6/G6 -> 0.002601895
B7: 3 | C7: =+SUMPRODUCT($I$79:$I$678,$W$79:$W$678) -> 100000 | D7: =SUMPRODUCT($M$79:$M$678,$Y$79:$Y$678) -> 17634.235 | E7: =-SUMPRODUCT($N$79:$N$678,$Y$79:$Y$678)+VLOOKUP($B7*12,$C$78:$T$677,18,FALSE)-$J$79 -> 7139.8739 | F7: =-SUMPRODUCT($R$79:$R$678,$Y$79:$Y$678) -> 12313.653 | G7: =VLOOKUP(B7+1,$B$78:$N$677,10,FALSE)-VLOOKUP($B7*12,$C$78:$T$677,18,FALSE) -> 98180.709 | L7: 0 | M7: =-SUMIF($B$79:$B$678,B7,$S$79:$S$678) -> 252.90628 | N7: =M7/G7 -> 0.0025759264
B8: 4 | C8: =+SUMPRODUCT($I$79:$I$678,$W$79:$W$678) -> 100000 | D8: =SUMPRODUCT($M$79:$M$678,$Z$79:$Z$678) -> 23553.721 | E8: =-SUMPRODUCT($N$79:$N$678,$Z$79:$Z$678)+VLOOKUP($B8*12,$C$78:$T$677,18,FALSE)-$J$79 -> 7510.5673 | F8: =-SUMPRODUCT($R$79:$R$678,$Z$79:$Z$678) -> 16583.469 | G8: =VLOOKUP(B8+1,$B$78:$N$677,10,FALSE)-VLOOKUP($B8*12,$C$78:$T$677,18,FALSE) -> 99459.684 | L8: 0 | M8: =-SUMIF($B$79:$B$678,B8,$S$79:$S$678) -> 253.67577 | N8: =M8/G8 -> 0.0025505387
B9: 5 | C9: =+SUMPRODUCT($I$79:$I$678,$W$79:$W$678) -> 100000 | D9: =SUMPRODUCT($M$79:$M$678,$AA$79:$AA$678) -> 29487.126 | E9: =-SUMPRODUCT($N$79:$N$678,$AA$79:$AA$678)+VLOOKUP($B9*12,$C$78:$T$677,18,FALSE)-$J$79 -> 7878.3078 | F9: =-SUMPRODUCT($R$79:$R$678,$AA$79:$AA$678) -> 20938.682 | G9: =VLOOKUP(B9+1,$B$78:$N$677,10,FALSE)-VLOOKUP($B9*12,$C$78:$T$677,18,FALSE) -> 100670.14 | L9: 0 | M9: =-SUMIF($B$79:$B$678,B9,$S$79:$S$678) -> 254.26445 | N9: =M9/G9 -> 0.0025257187
B10: 10 | C10: =+SUMPRODUCT($I$79:$I$678,$W$79:$W$678) -> 100000 | D10: =SUMPRODUCT($M$79:$M$678,$AB$79:$AB$678) -> 58745.716 | E10: =-SUMPRODUCT($N$79:$N$678,$AB$79:$AB$678)-$J$79 -> 13669.697 | F10: =-SUMPRODUCT($R$79:$R$678,$AB$79:$AB$678) -> 47172.843 | G10: =VLOOKUP(B10+1,$B$78:$N$677,10,FALSE) -> 97903.177 | L10: 0 | M10: =-SUMIF($B$79:$B$678,B10,$S$79:$S$678) -> 246.41475 | N10: =M10/G10 -> 0.0025169229
B11: 15 | C11: =+SUMPRODUCT($I$79:$I$678,$W$79:$W$678) -> 100000 | D11: =SUMPRODUCT($M$79:$M$678,$AC$79:$AC$678) -> 86308.355 | E11: =-SUMPRODUCT($N$79:$N$678,$AC$79:$AC$678)-$J$79 -> 20083.32 | F11: =-SUMPRODUCT($R$79:$R$678,$AC$79:$AC$678) -> 76288.71 | G11: =VLOOKUP(B11+1,$B$78:$N$677,10,FALSE) -> 89936.325 | L11: 0 | M11: =-SUMIF($B$79:$B$678,B11,$S$79:$S$678) -> 227.6194 | N11: =M11/G11 -> 0.002530895
B12: 20 | C12: =+SUMPRODUCT($I$79:$I$678,$W$79:$W$678) -> 100000 | D12: =SUMPRODUCT($M$79:$M$678,$AD$79:$AD$678) -> 110808.23 | E12: =-SUMPRODUCT($N$79:$N$678,$AD$79:$AD$678)-$J$79 -> 25784.262 | F12: =-SUMPRODUCT($R$79:$R$678,$AD$79:$AD$678) -> 108434.98 | G12: =VLOOKUP(B12+1,$B$78:$N$677,10,FALSE) -> 76588.993 | L12: 0 | M12: =-SUMIF($B$79:$B$678,B12,$S$79:$S$678) -> 195.72757 | N12: =M12/G12 -> 0.0025555575
B13: 25 | C13: =+SUMPRODUCT($I$79:$I$678,$W$79:$W$678) -> 100000 | D13: =SUMPRODUCT($M$79:$M$678,$AE$79:$AE$678) -> 130439.75 | E13: =-SUMPRODUCT($N$79:$N$678,$AE$79:$AE$678)-$J$79 -> 30352.372 | F13: =-SUMPRODUCT($R$79:$R$678,$AE$79:$AE$678) -> 143927.06 | G13: =VLOOKUP(B13+1,$B$78:$N$677,10,FALSE) -> 56160.32 | L13: 0 | M13: =-SUMIF($B$79:$B$678,B13,$S$79:$S$678) -> 146.58369 | N13: =M13/G13 -> 0.0026100935
B14: 30 | C14: =+SUMPRODUCT($I$79:$I$678,$W$79:$W$678) -> 100000 | D14: =SUMPRODUCT($M$79:$M$678,$AF$79:$AF$678) -> 142836.67 | E14: =-SUMPRODUCT($N$79:$N$678,$AF$79:$AF$678)-$J$79 -> 33237.044 | F14: =-SUMPRODUCT($R$79:$R$678,$AF$79:$AF$678) -> 183113.18 | G14: =VLOOKUP(B14+1,$B$78:$N$677,10,FALSE) -> 26486.442 | L14: 0 | M14: =-SUMIF($B$79:$B$678,B14,$S$79:$S$678) -> 74.89966 | N14: =M14/G14 -> 0.002827849
B15: 35 | C15: =+SUMPRODUCT($I$79:$I$678,$W$79:$W$678) -> 100000 | D15: =SUMPRODUCT($M$79:$M$678,$AG$79:$AG$678) -> 145597.89 | E15: =-SUMPRODUCT($N$79:$N$678,$AG$79:$AG$678)-$J$79 -> 33879.559 | F15: =-SUMPRODUCT($R$79:$R$678,$AG$79:$AG$678) -> 211718.33 | G15: =VLOOKUP(B15+1,$B$78:$N$677,10,FALSE) -> 0 | L15: 0 | M15: =-SUMIF($B$79:$B$678,B15,$S$79:$S$678) -> 0 | N15: =M15/G15 -> #DIV/0!
B16: 40 | C16: =+SUMPRODUCT($I$79:$I$678,$W$79:$W$678) -> 100000 | D16: =SUMPRODUCT($M$79:$M$678,$AH$79:$AH$678) -> 145597.89 | E16: =-SUMPRODUCT($N$79:$N$678,$AH$79:$AH$678)-$J$79 -> 33879.559 | F16: =-SUMPRODUCT($R$79:$R$678,$AH$79:$AH$678) -> 211718.33 | G16: =VLOOKUP(B16+1,$B$78:$N$677,10,FALSE) -> 0 | L16: 0 | M16: =-SUMIF($B$79:$B$678,B16,$S$79:$S$678) -> 0 | N16: =M16/G16 -> #DIV/0!
B19: Year | C19: A | D19: B | E19: C | F19: D | G19: E | L19: € | M19: €
C20: Total amount of premiums paid into the policy to date | D20: Projected investment growth to date | E20: Projected expenses and charges to date | F20: Cumulative gross income to date | G20: Projected policy value after income | L20: Contributions payable in that year | M20: Projected total intermediary and sales remuneration payable in that year
B21: 1 | C21: =+SUMPRODUCT($I$691:$I$1290,$W$691:$W$1290) -> 100000 | D21: =SUMPRODUCT($M$691:$M$1290,$W$691:$W$1290) -> 3121.9747 | E21: =-SUMPRODUCT($N$691:$N$1290,$W$691:$W$1290)+VLOOKUP($B21*12,$C$690:$T$1289,18,FALSE)-$J$691 -> 6232.747 | F21: =-SUMPRODUCT($R$691:$R$1290,$W$691:$W$1290) -> 4000.499 | G21: =VLOOKUP(B21+1,$B$690:$N$1289,10,FALSE)-VLOOKUP($B21*12,$C$690:$T$1289,18,FALSE) -> 92888.729 | L21: =C21 -> 100000 | M21: =-SUMIF($B$691:$B$1290,B21,$S$691:$S$1290) -> 4247.5134 | N21: =M21/G21 -> 0.045726898
B22: 2 | C22: =+SUMPRODUCT($I$691:$I$1290,$W$691:$W$1290) -> 100000 | D22: =SUMPRODUCT($M$691:$M$1290,$X$691:$X$1290) -> 6172.1125 | E22: =-SUMPRODUCT($N$691:$N$1290,$X$691:$X$1290)+VLOOKUP($B22*12,$C$690:$T$1289,18,FALSE)-$J$691 -> 6474.1825 | F22: =-SUMPRODUCT($R$691:$R$1290,$X$691:$X$1290) -> 8081.008 | G22: =VLOOKUP(B22+1,$B$690:$N$1289,10,FALSE)-VLOOKUP($B22*12,$C$690:$T$1289,18,FALSE) -> 91616.922 | L22: 0 | M22: =-SUMIF($B$691:$B$1290,B22,$S$691:$S$1290) -> 241.80018 | N22: =M22/G22 -> 0.0026392524
B23: 3 | C23: =+SUMPRODUCT($I$691:$I$1290,$W$691:$W$1290) -> 100000 | D23: =SUMPRODUCT($M$691:$M$1290,$Y$691:$Y$1290) -> 9146.5448 | E23: =-SUMPRODUCT($N$691:$N$1290,$Y$691:$Y$1290)+VLOOKUP($B23*12,$C$690:$T$1289,18,FALSE)-$J$691 -> 6726.1546 | F23: =-SUMPRODUCT($R$691:$R$1290,$Y$691:$Y$1290) -> 12243.127 | G23: =VLOOKUP(B23+1,$B$690:$N$1289,10,FALSE)-VLOOKUP($B23*12,$C$690:$T$1289,18,FALSE) -> 90177.263 | L23: 0 | M23: =-SUMIF($B$691:$B$1290,B23,$S$691:$S$1290) -> 235.77954 | N23: =M23/G23 -> 0.0026146229
B24: 4 | C24: =+SUMPRODUCT($I$691:$I$1290,$W$691:$W$1290) -> 100000 | D24: =SUMPRODUCT($M$691:$M$1290,$Z$691:$Z$1290) -> 12041.281 | E24: =-SUMPRODUCT($N$691:$N$1290,$Z$691:$Z$1290)+VLOOKUP($B24*12,$C$690:$T$1289,18,FALSE)-$J$691 -> 6990.6095 | F24: =-SUMPRODUCT($R$691:$R$1290,$Z$691:$Z$1290) -> 16488.489 | G24: =VLOOKUP(B24+1,$B$690:$N$1289,10,FALSE)-VLOOKUP($B24*12,$C$690:$T$1289,18,FALSE) -> 88562.183 | L24: 0 | M24: =-SUMIF($B$691:$B$1290,B24,$S$691:$S$1290) -> 229.44184 | N24: =M24/G24 -> 0.0025907428
B25: 5 | C25: =+SUMPRODUCT($I$691:$I$1290,$W$691:$W$1290) -> 100000 | D25: =SUMPRODUCT($M$691:$M$1290,$AA$691:$AA$1290) -> 14852.207 | E25: =-SUMPRODUCT($N$691:$N$1290,$AA$691:$AA$1290)+VLOOKUP($B25*12,$C$690:$T$1289,18,FALSE)-$J$691 -> 7269.5949 | F25: =-SUMPRODUCT($R$691:$R$1290,$AA$691:$AA$1290) -> 20818.757 | G25: =VLOOKUP(B25+1,$B$690:$N$1289,10,FALSE)-VLOOKUP($B25*12,$C$690:$T$1289,18,FALSE) -> 86763.855 | L25: 0 | M25: =-SUMIF($B$691:$B$1290,B25,$S$691:$S$1290) -> 222.77719 | N25: =M25/G25 -> 0.0025676267
B26: 10 | C26: =+SUMPRODUCT($I$691:$I$1290,$W$691:$W$1290) -> 100000 | D26: =SUMPRODUCT($M$691:$M$1290,$AB$691:$AB$1290) -> 27496.507 | E26: =-SUMPRODUCT($N$691:$N$1290,$AB$691:$AB$1290)-$J$691 -> 11835.982 | F26: =-SUMPRODUCT($R$691:$R$1290,$AB$691:$AB$1290) -> 43804.348 | G26: =VLOOKUP(B26+1,$B$690:$N$1289,10,FALSE) -> 71856.177 | L26: 0 | M26: =-SUMIF($B$691:$B$1290,B26,$S$691:$S$1290) -> 184.18431 | N26: =M26/G26 -> 0.0025632355
B27: 15 | C27: =+SUMPRODUCT($I$691:$I$1290,$W$691:$W$1290) -> 100000 | D27: =SUMPRODUCT($M$691:$M$1290,$AC$691:$AC$1290) -> 37350.62 | E27: =-SUMPRODUCT($N$691:$N$1290,$AC$691:$AC$1290)-$J$691 -> 16077.725 | F27: =-SUMPRODUCT($R$691:$R$1290,$AC$691:$AC$1290) -> 69182.297 | G27: =VLOOKUP(B27+1,$B$690:$N$1289,10,FALSE) -> 52090.598 | L27: 0 | M27: =-SUMIF($B$691:$B$1290,B27,$S$691:$S$1290) -> 135.77346 | N27: =M27/G27 -> 0.0026064869
B28: 20 | C28: =+SUMPRODUCT($I$691:$I$1290,$W$691:$W$1290) -> 100000 | D28: =SUMPRODUCT($M$691:$M$1290,$AD$691:$AD$1290) -> 43738.562 | E28: =-SUMPRODUCT($N$691:$N$1290,$AD$691:$AD$1290)-$J$691 -> 18827.44 | F28: =-SUMPRODUCT($R$691:$R$1290,$AD$691:$AD$1290) -> 97201.603 | G28: =VLOOKUP(B28+1,$B$690:$N$1289,10,FALSE) -> 27709.519 | L28: 0 | M28: =-SUMIF($B$691:$B$1290,B28,$S$691:$S$1290) -> 75.978055 | N28: =M28/G28 -> 0.0027419478
B29: 25 | C29: =+SUMPRODUCT($I$691:$I$1290,$W$691:$W$1290) -> 100000 | D29: =SUMPRODUCT($M$691:$M$1290,$AE$691:$AE$1290) -> 45885.136 | E29: =-SUMPRODUCT($N$691:$N$1290,$AE$691:$AE$1290)-$J$691 -> 19751.442 | F29: =-SUMPRODUCT($R$691:$R$1290,$AE$691:$AE$1290) -> 126133.69 | G29: =VLOOKUP(B29+1,$B$690:$N$1289,10,FALSE) -> 0 | L29: 0 | M29: =-SUMIF($B$691:$B$1290,B29,$S$691:$S$1290) -> 3.8098528 | N29: =M29/G29 -> #DIV/0!
B30: 30 | C30: =+SUMPRODUCT($I$691:$I$1290,$W$691:$W$1290) -> 100000 | D30: =SUMPRODUCT($M$691:$M$1290,$AF$691:$AF$1290) -> 45885.136 | E30: =-SUMPRODUCT($N$691:$N$1290,$AF$691:$AF$1290)-$J$691 -> 19751.442 | F30: =-SUMPRODUCT($R$691:$R$1290,$AF$691:$AF$1290) -> 126133.69 | G30: =VLOOKUP(B30+1,$B$690:$N$1289,10,FALSE) -> 0 | L30: 0 | M30: =-SUMIF($B$691:$B$1290,B30,$S$691:$S$1290) -> 0 | N30: =M30/G30 -> #DIV/0!
B31: 35 | C31: =+SUMPRODUCT($I$691:$I$1290,$W$691:$W$1290) -> 100000 | D31: =SUMPRODUCT($M$691:$M$1290,$AG$691:$AG$1290) -> 45885.136 | E31: =-SUMPRODUCT($N$691:$N$1290,$AG$691:$AG$1290)-$J$691 -> 19751.442 | F31: =-SUMPRODUCT($R$691:$R$1290,$AG$691:$AG$1290) -> 126133.69 | G31: =VLOOKUP(B31+1,$B$690:$N$1289,10,FALSE) -> 0 | L31: 0 | M31: =-SUMIF($B$691:$B$1290,B31,$S$691:$S$1290) -> 0 | N31: =M31/G31 -> #DIV/0!
B32: 40 | C32: =+SUMPRODUCT($I$691:$I$1290,$W$691:$W$1290) -> 100000 | D32: =SUMPRODUCT($M$691:$M$1290,$AH$691:$AH$1290) -> 45885.136 | E32: =-SUMPRODUCT($N$691:$N$1290,$AH$691:$AH$1290)-$J$691 -> 19751.442 | F32: =-SUMPRODUCT($R$691:$R$1290,$AH$691:$AH$1290) -> 126133.69 | G32: =VLOOKUP(B32+1,$B$690:$N$1289,10,FALSE) -> 0 | L32: 0 | M32: =-SUMIF($B$691:$B$1290,B32,$S$691:$S$1290) -> 0 | N32: =M32/G32 -> #DIV/0!
G35: =IF(T39<>1,"Percentage Invested is not equal to 100%","")
AH36: {=IFERROR(INDEX($G$44:$S$44, SMALL(IF($G$44:$S$44<>"", COLUMN($G$44:$S$44)-COLUMN($G$44)+1), ROW(A11))), "")} | AI36: =IFERROR(HLOOKUP($AH36,$G$38:$S$39,2,FALSE),"")
AF37: {=IFERROR(INDEX($G$44:$S$44, SMALL(IF($G$44:$S$44<>"", COLUMN($G$44:$S$44)-COLUMN($G$44)+1), ROW(A12))), "")}
B38: Inputs: | F38: Investment Stategy | G38: Strategy Select 30 | H38: Strategy Select 50 | I38: Strategy Select 75 | J38: Allianz Best Styles Global Equity SRI | K38: Allianz Advanced Fixed Income Short Duration | L38: Allianz Advanced Fixed Income Euro | M38: Allianz Dynamic Multi Asset Strategy SRI 75 | N38: Allianz Dynamic Multi Asset Strategy SRI 50 | O38: Allianz Dynamic Multi Asset Strategy SRI 15 | P38: HSBC EURO STOXX 50 UCITS ETF | Q38: HSBC MSCI World UCITS ETF | R38: HSBC S&P 500 UCITS ETF | S38: Allianz Euro Cash | T38: Annual Rate | U38: Monthly Rate | AF38: Fund | AG38: Investment %
B39: Product Code | C39: A5 | F39: % invested | I39: 1 | T39: =SUM(G39:S39) -> 1 | AF39: {=IFERROR(INDEX($G$44:$S$44, SMALL(IF($G$44:$S$44<>"", COLUMN($G$44:$S$44)-COLUMN($G$44)+1), ROW(A1))), "")} -> Strategy Select 75 | AG39: =IFERROR(HLOOKUP($AF39,$G$38:$S$39,2,FALSE),"") -> 1
B40: Commencement Date | C40: 51586 | F40: Rate of Return | G40: =VLOOKUP(G$38,Fund_Rates_Table,3,FALSE) -> 0.05135 | H40: =VLOOKUP(H$38,Fund_Rates_Table,3,FALSE) -> 0.05725 | I40: =VLOOKUP(I$38,Fund_Rates_Table,3,FALSE) -> 0.064625 | J40: =VLOOKUP(J$38,Fund_Rates_Table,3,FALSE) -> 0.072 | K40: =VLOOKUP(K$38,Fund_Rates_Table,3,FALSE) -> 0.0425 | L40: =VLOOKUP(L$38,Fund_Rates_Table,3,FALSE) -> 0.0425 | M40: =VLOOKUP(M$38,Fund_Rates_Table,3,FALSE) -> 0.064625 | N40: =VLOOKUP(N$38,Fund_Rates_Table,3,FALSE) -> 0.05725 | ... S40: =VLOOKUP(S$38,Fund_Rates_Table,3,FALSE) -> 0.032 | T40: =MIN(SUMPRODUCT($G$39:$S$39,G40:S40)) -> 0.064625 | U40: =(1+T40)^(1/12)-1 -> 0.0052321924 | AF40: {=IFERROR(INDEX($G$44:$S$44, SMALL(IF($G$44:$S$44<>"", COLUMN($G$44:$S$44)-COLUMN($G$44)+1), ROW(A2))), "")} | AG40: =IFERROR(HLOOKUP($AF40,$G$38:$S$39,2,FALSE),"")
B41: Date of Birth | C41: 27551 | F41: External Fund Charge | G41: =VLOOKUP(G$38,Fund_Rates_Table,5,FALSE) -> 0.0025 | H41: =VLOOKUP(H$38,Fund_Rates_Table,5,FALSE) -> 0.0025 | I41: =VLOOKUP(I$38,Fund_Rates_Table,5,FALSE) -> 0.0025 | J41: =VLOOKUP(J$38,Fund_Rates_Table,5,FALSE) -> 0.0045 | K41: =VLOOKUP(K$38,Fund_Rates_Table,5,FALSE) -> 0.0022 | L41: =VLOOKUP(L$38,Fund_Rates_Table,5,FALSE) -> 0.0027 | M41: =VLOOKUP(M$38,Fund_Rates_Table,5,FALSE) -> 0.0065 | N41: =VLOOKUP(N$38,Fund_Rates_Table,5,FALSE) -> 0.0059 | ... S41: =VLOOKUP(S$38,Fund_Rates_Table,5,FALSE) -> 0.0016 | T41: =SUMPRODUCT($G$39:$S$39,G41:S41) -> 0.0025 | AF41: {=IFERROR(INDEX($G$44:$S$44, SMALL(IF($G$44:$S$44<>"", COLUMN($G$44:$S$44)-COLUMN($G$44)+1), ROW(A3))), "")} | AG41: =IFERROR(HLOOKUP($AF41,$G$38:$S$39,2,FALSE),"")
B42: Single Contribution | C42: 100000 | F42: If Guarantee | G42: No | H42: No | I42: No | AF42: {=IFERROR(INDEX($G$44:$S$44, SMALL(IF($G$44:$S$44<>"", COLUMN($G$44:$S$44)-COLUMN($G$44)+1), ROW(A4))), "")} | AG42: =IFERROR(HLOOKUP($AF42,$G$38:$S$39,2,FALSE),"")
B43: Current Age | C43: =(C40-C41)/365.25 -> 65.804244 | F43: Guarantee Charge | G43: =IF(G42="yes",VLOOKUP(G$38,Fund_Rates_Table,2,FALSE),0) -> 0 | H43: =IF(H42="yes",VLOOKUP(H$38,Fund_Rates_Table,2,FALSE),0) -> 0 | I43: =IF(I42="yes",VLOOKUP(I$38,Fund_Rates_Table,2,FALSE),0) -> 0 | T43: =SUMPRODUCT($G$39:$S$39,G43:S43) -> 0 | U43: =1-(1-T43)^(1/12) -> 0 | AF43: {=IFERROR(INDEX($G$44:$S$44, SMALL(IF($G$44:$S$44<>"", COLUMN($G$44:$S$44)-COLUMN($G$44)+1), ROW(A5))), "")} | AG43: =IFERROR(HLOOKUP($AF43,$G$38:$S$39,2,FALSE),"")
B44: Max Rate of return | C44: 0.06 | F44: Invested Funds | G44: =IF(G39="","",G38) | H44: =IF(H39="","",H38) | I44: =IF(I39="","",I38) -> Strategy Select 75 | J44: =IF(J39="","",J38) | K44: =IF(K39="","",K38) | L44: =IF(L39="","",L38) | M44: =IF(M39="","",M38) | N44: =IF(N39="","",N38) | ... S44: =IF(S39="","",S38) | AF44: {=IFERROR(INDEX($G$44:$S$44, SMALL(IF($G$44:$S$44<>"", COLUMN($G$44:$S$44)-COLUMN($G$44)+1), ROW(A6))), "")} | AG44: =IFERROR(HLOOKUP($AF44,$G$38:$S$39,2,FALSE),"")
B45: Growth Rate 1 | C45: =MIN(RateOfReturn_Max,C47) -> 0.06 | D45: =(1+Growth_Rate_1)^(1/12)-1 -> 0.0048675506 | AF45: {=IFERROR(INDEX($G$44:$S$44, SMALL(IF($G$44:$S$44<>"", COLUMN($G$44:$S$44)-COLUMN($G$44)+1), ROW(A7))), "")} | AG45: =IFERROR(HLOOKUP($AF45,$G$38:$S$39,2,FALSE),"")
...

Sheet Inputs for PointOfIssue Doc
A1: Inputs for Point Of Disclosure Document
C2: Product Version | E2: =LEFT(Product_Code, 1) -> A
K3: Illustration table assuming growth rate 1 | L3: Year | M3: A | N3: B | O3: C | P3: D | Q3: E
C4: Growth Rate 1 (%) | E4: =Growth_Rate_1 -> 0.06 | M4: Total amount of premiums paid into the policy to date | N4: Projected investment growth to date | O4: Projected charges to date | P4: Cumulative gross income to date | Q4: Projected policy value after income
E5: Reduced to: | L5: =IF('ARF Projections'!$G4=0,"", IF('ARF Projections'!$G5=0,Fund_Zero_Year,'ARF Projections'!B5)) -> 1 | M5: =IF('ARF Projections'!$G4=0,"",'ARF Projections'!C5) -> 100000 | N5: =IF('ARF Projections'!$G4=0,"",'ARF Projections'!D5) -> 5853.5778 | O5: =IF('ARF Projections'!$G4=0,"",'ARF Projections'!E5) -> 6385.4821 | P5: =IF('ARF Projections'!$G4=0,"",'ARF Projections'!F5) -> 4023.5435 | Q5: =IF('ARF Projections'!$G4=0,"",'ARF Projections'!G5) -> 95444.552
C6: RIY (reduced from [Growth Rate 1 (%)] to) | E6: ='ARF Projections'!AP65 -> 0.046016978 | L6: =IF('ARF Projections'!$G5=0,"", IF('ARF Projections'!$G6=0,Fund_Zero_Year,'ARF Projections'!B6)) -> 2 | M6: =IF('ARF Projections'!$G5=0,"",'ARF Projections'!C6) -> 100000 | N6: =IF('ARF Projections'!$G5=0,"",'ARF Projections'!D6) -> 11732.878 | O6: =IF('ARF Projections'!$G5=0,"",'ARF Projections'!E6) -> 6765.1612 | P6: =IF('ARF Projections'!$G5=0,"",'ARF Projections'!F6) -> 8127.5579 | Q6: =IF('ARF Projections'!$G5=0,"",'ARF Projections'!G6) -> 96840.159
L7: =IF('ARF Projections'!$G6=0,"", IF('ARF Projections'!$G7=0,Fund_Zero_Year,'ARF Projections'!B7)) -> 3 | M7: =IF('ARF Projections'!$G6=0,"",'ARF Projections'!C7) -> 100000 | N7: =IF('ARF Projections'!$G6=0,"",'ARF Projections'!D7) -> 17634.235 | O7: =IF('ARF Projections'!$G6=0,"",'ARF Projections'!E7) -> 7139.8739 | P7: =IF('ARF Projections'!$G6=0,"",'ARF Projections'!F7) -> 12313.653 | Q7: =IF('ARF Projections'!$G6=0,"",'ARF Projections'!G7) -> 98180.709
C8: Income Description Text | D8: =IF(Income_Type="Monetary Amount (with Escalation)","You have chosen an initial income level of "&TEXT('ARF Projections'!C50,"€#,##0")&" per annum.", IF(Income_Type="Fixed Percent","You have chosen an income level of "& TEXT('ARF Projections'!C51,"0%")& " of the fund value per annum", "You have chosen an income level in line with the Revenue deemed distribution rules in respect of this ARF. These are described below")) -> You have chosen an income level in line with the Revenue deemed distribution rules in respect of this ARF. These are described below | L8: =IF('ARF Projections'!$G7=0,"", IF('ARF Projections'!$G8=0,Fund_Zero_Year,'ARF Projections'!B8)) -> 4 | M8: =IF('ARF Projections'!$G7=0,"",'ARF Projections'!C8) -> 100000 | N8: =IF('ARF Projections'!$G7=0,"",'ARF Projections'!D8) -> 23553.721 | O8: =IF('ARF Projections'!$G7=0,"",'ARF Projections'!E8) -> 7510.5673 | P8: =IF('ARF Projections'!$G7=0,"",'ARF Projections'!F8) -> 16583.469 | Q8: =IF('ARF Projections'!$G7=0,"",'ARF Projections'!G8) -> 99459.684
L9: =IF('ARF Projections'!$G8=0,"", IF('ARF Projections'!$G9=0,Fund_Zero_Year,'ARF Projections'!B9)) -> 5 | M9: =IF('ARF Projections'!$G8=0,"",'ARF Projections'!C9) -> 100000 | N9: =IF('ARF Projections'!$G8=0,"",'ARF Projections'!D9) -> 29487.126 | O9: =IF('ARF Projections'!$G8=0,"",'ARF Projections'!E9) -> 7878.3078 | P9: =IF('ARF Projections'!$G8=0,"",'ARF Projections'!F9) -> 20938.682 | Q9: =IF('ARF Projections'!$G8=0,"",'ARF Projections'!G9) -> 100670.14
L10: =IF('ARF Projections'!$G9=0,"", IF('ARF Projections'!$G10=0,Fund_Zero_Year,'ARF Projections'!B10)) -> 10 | M10: =IF('ARF Projections'!$G9=0,"",'ARF Projections'!C10) -> 100000 | N10: =IF('ARF Projections'!$G9=0,"",'ARF Projections'!D10) -> 58745.716 | O10: =IF('ARF Projections'!$G9=0,"",'ARF Projections'!E10) -> 13669.697 | P10: =IF('ARF Projections'!$G9=0,"",'ARF Projections'!F10) -> 47172.843 | Q10: =IF('ARF Projections'!$G9=0,"",'ARF Projections'!G10) -> 97903.177
L11: =IF('ARF Projections'!$G10=0,"", IF('ARF Projections'!$G11=0,Fund_Zero_Year,'ARF Projections'!B11)) -> 15 | M11: =IF('ARF Projections'!$G10=0,"",'ARF Projections'!C11) -> 100000 | N11: =IF('ARF Projections'!$G10=0,"",'ARF Projections'!D11) -> 86308.355 | O11: =IF('ARF Projections'!$G10=0,"",'ARF Projections'!E11) -> 20083.32 | P11: =IF('ARF Projections'!$G10=0,"",'ARF Projections'!F11) -> 76288.71 | Q11: =IF('ARF Projections'!$G10=0,"",'ARF Projections'!G11) -> 89936.325
L12: =IF('ARF Projections'!$G11=0,"", IF('ARF Projections'!$G12=0,Fund_Zero_Year,'ARF Projections'!B12)) -> 20 | M12: =IF('ARF Projections'!$G11=0,"",'ARF Projections'!C12) -> 100000 | N12: =IF('ARF Projections'!$G11=0,"",'ARF Projections'!D12) -> 110808.23 | O12: =IF('ARF Projections'!$G11=0,"",'ARF Projections'!E12) -> 25784.262 | P12: =IF('ARF Projections'!$G11=0,"",'ARF Projections'!F12) -> 108434.98 | Q12: =IF('ARF Projections'!$G11=0,"",'ARF Projections'!G12) -> 76588.993
L13: =IF('ARF Projections'!$G12=0,"", IF('ARF Projections'!$G13=0,Fund_Zero_Year,'ARF Projections'!B13)) -> 25 | M13: =IF('ARF Projections'!$G12=0,"",'ARF Projections'!C13) -> 100000 | N13: =IF('ARF Projections'!$G12=0,"",'ARF Projections'!D13) -> 130439.75 | O13: =IF('ARF Projections'!$G12=0,"",'ARF Projections'!E13) -> 30352.372 | P13: =IF('ARF Projections'!$G12=0,"",'ARF Projections'!F13) -> 143927.06 | Q13: =IF('ARF Projections'!$G12=0,"",'ARF Projections'!G13) -> 56160.32
L14: =IF('ARF Projections'!$G13=0,"", IF('ARF Projections'!$G14=0,Fund_Zero_Year,'ARF Projections'!B14)) -> 30 | M14: =IF('ARF Projections'!$G13=0,"",'ARF Projections'!C14) -> 100000 | N14: =IF('ARF Projections'!$G13=0,"",'ARF Projections'!D14) -> 142836.67 | O14: =IF('ARF Projections'!$G13=0,"",'ARF Projections'!E14) -> 33237.044 | P14: =IF('ARF Projections'!$G13=0,"",'ARF Projections'!F14) -> 183113.18 | Q14: =IF('ARF Projections'!$G13=0,"",'ARF Projections'!G14) -> 26486.442
C15: Fund Zero Year | D15: =Fund_Zero_Year -> 34 | L15: =IF('ARF Projections'!$G14=0,"", IF('ARF Projections'!$G15=0,Fund_Zero_Year,'ARF Projections'!B15)) -> 34 | M15: =IF('ARF Projections'!$G14=0,"",'ARF Projections'!C15) -> 100000 | N15: =IF('ARF Projections'!$G14=0,"",'ARF Projections'!D15) -> 145597.89 | O15: =IF('ARF Projections'!$G14=0,"",'ARF Projections'!E15) -> 33879.559 | P15: =IF('ARF Projections'!$G14=0,"",'ARF Projections'!F15) -> 211718.33 | Q15: =IF('ARF Projections'!$G14=0,"",'ARF Projections'!G15) -> 0
L16: =IF('ARF Projections'!$G15=0,"", IF('ARF Projections'!$G16=0,Fund_Zero_Year,'ARF Projections'!B16)) | M16: =IF('ARF Projections'!$G15=0,"",'ARF Projections'!C16) | N16: =IF('ARF Projections'!$G15=0,"",'ARF Projections'!D16) | O16: =IF('ARF Projections'!$G15=0,"",'ARF Projections'!E16) | P16: =IF('ARF Projections'!$G15=0,"",'ARF Projections'!F16) | Q16: =IF('ARF Projections'!$G15=0,"",'ARF Projections'!G16)
C17: Surrender Penalty text | D17: {=IF(RIGHT(Product_Code,1)="1","","Please note that the charges shown in Column C for years 1 to "&(_xlfn.XLOOKUP(0, _xlfn.XLOOKUP(Product_Code,Parameters!D7:D25,Parameters!I7:P25), Parameters!I6:P6, 9,0,1)-1)&" assume that policy is fully encashed and an exit charge is incurred. No exit charge applies to partial surrenders. If the policy is not encashed in the first "&(_xlfn.XLOOKUP(0, _xlfn.XLOOKUP(Product_Code,Parameters!D7:D25,Parameters!I7:P25), Parameters!I6:P6, 9,0,1)-1)& " years, no exit charge is payable and the total charges actually deducted from the policy in those years are less than shown." )} -> Please note that the charges shown in Column C for years 1 to 5 assume that policy is fully encashed and an exit charge is incurred. No exit charge applies to partial surrenders. If the policy is not encashed in the first 5 years, no exit charge is payable and the total charges actually deducted from the policy in those years are less than shown.
L18: * charges reflect additional allocation to the policy
K20: Illustration table assuming growth rate 2 | L20: Year | M20: A | N20: B | O20: C | P20: D | Q20: E
M21: Total amount of premiums paid into the policy to date | N21: Projected investment growth to date | O21: Projected charges to date | P21: Cumulative gross income to date | Q21: Projected policy value after income
L22: =IF('ARF Projections'!$G20=0,"", IF('ARF Projections'!$G21=0,Fund_Zero_Year_2,'ARF Projections'!B21)) -> 1 | M22: =IF('ARF Projections'!$G20=0,"",'ARF Projections'!C21) -> 100000 | N22: =IF('ARF Projections'!$G20=0,"",'ARF Projections'!D21) -> 3121.9747 | O22: =IF('ARF Projections'!$G20=0,"",'ARF Projections'!E21) -> 6232.747 | P22: =IF('ARF Projections'!$G20=0,"",'ARF Projections'!F21) -> 4000.499 | Q22: =IF('ARF Projections'!$G20=0,"",'ARF Projections'!G21) -> 92888.729
L23: =IF('ARF Projections'!$G21=0,"", IF('ARF Projections'!$G22=0,Fund_Zero_Year_2,'ARF Projections'!B22)) -> 2 | M23: =IF('ARF Projections'!$G21=0,"",'ARF Projections'!C22) -> 100000 | N23: =IF('ARF Projections'!$G21=0,"",'ARF Projections'!D22) -> 6172.1125 | O23: =IF('ARF Projections'!$G21=0,"",'ARF Projections'!E22) -> 6474.1825 | P23: =IF('ARF Projections'!$G21=0,"",'ARF Projections'!F22) -> 8081.008 | Q23: =IF('ARF Projections'!$G21=0,"",'ARF Projections'!G22) -> 91616.922
C24: Growth Rate 2 (%) | E24: =Growth_Rate_2 -> 0.032 | L24: =IF('ARF Projections'!$G22=0,"", IF('ARF Projections'!$G23=0,Fund_Zero_Year_2,'ARF Projections'!B23)) -> 3 | M24: =IF('ARF Projections'!$G22=0,"",'ARF Projections'!C23) -> 100000 | N24: =IF('ARF Projections'!$G22=0,"",'ARF Projections'!D23) -> 9146.5448 | O24: =IF('ARF Projections'!$G22=0,"",'ARF Projections'!E23) -> 6726.1546 | P24: =IF('ARF Projections'!$G22=0,"",'ARF Projections'!F23) -> 12243.127 | Q24: =IF('ARF Projections'!$G22=0,"",'ARF Projections'!G23) -> 90177.263
E25: Reduced to: | L25: =IF('ARF Projections'!$G23=0,"", IF('ARF Projections'!$G24=0,Fund_Zero_Year_2,'ARF Projections'!B24)) -> 4 | M25: =IF('ARF Projections'!$G23=0,"",'ARF Projections'!C24) -> 100000 | N25: =IF('ARF Projections'!$G23=0,"",'ARF Projections'!D24) -> 12041.281 | O25: =IF('ARF Projections'!$G23=0,"",'ARF Projections'!E24) -> 6990.6095 | P25: =IF('ARF Projections'!$G23=0,"",'ARF Projections'!F24) -> 16488.489 | Q25: =IF('ARF Projections'!$G23=0,"",'ARF Projections'!G24) -> 88562.183
C26: RIY2 (reduced from [Growth Rate 2 (%)] to): | E26: ='ARF Projections'!AP687 -> 0.018235037 | L26: =IF('ARF Projections'!$G24=0,"", IF('ARF Projections'!$G25=0,Fund_Zero_Year_2,'ARF Projections'!B25)) -> 5 | M26: =IF('ARF Projections'!$G24=0,"",'ARF Projections'!C25) -> 100000 | N26: =IF('ARF Projections'!$G24=0,"",'ARF Projections'!D25) -> 14852.207 | O26: =IF('ARF Projections'!$G24=0,"",'ARF Projections'!E25) -> 7269.5949 | P26: =IF('ARF Projections'!$G24=0,"",'ARF Projections'!F25) -> 20818.757 | Q26: =IF('ARF Projections'!$G24=0,"",'ARF Projections'!G25) -> 86763.855
C27: Fund Zero Year2 | D27: =Fund_Zero_Year_2 -> 25 | L27: =IF('ARF Projections'!$G25=0,"", IF('ARF Projections'!$G26=0,Fund_Zero_Year_2,'ARF Projections'!B26)) -> 10 | M27: =IF('ARF Projections'!$G25=0,"",'ARF Projections'!C26) -> 100000 | N27: =IF('ARF Projections'!$G25=0,"",'ARF Projections'!D26) -> 27496.507 | O27: =IF('ARF Projections'!$G25=0,"",'ARF Projections'!E26) -> 11835.982 | P27: =IF('ARF Projections'!$G25=0,"",'ARF Projections'!F26) -> 43804.348 | Q27: =IF('ARF Projections'!$G25=0,"",'ARF Projections'!G26) -> 71856.177
L28: =IF('ARF Projections'!$G26=0,"", IF('ARF Projections'!$G27=0,Fund_Zero_Year_2,'ARF Projections'!B27)) -> 15 | M28: =IF('ARF Projections'!$G26=0,"",'ARF Projections'!C27) -> 100000 | N28: =IF('ARF Projections'!$G26=0,"",'ARF Projections'!D27) -> 37350.62 | O28: =IF('ARF Projections'!$G26=0,"",'ARF Projections'!E27) -> 16077.725 | P28: =IF('ARF Projections'!$G26=0,"",'ARF Projections'!F27) -> 69182.297 | Q28: =IF('ARF Projections'!$G26=0,"",'ARF Projections'!G27) -> 52090.598
C29: Single Contribution Paid | D29: =SinglePrem -> 100000 | L29: =IF('ARF Projections'!$G27=0,"", IF('ARF Projections'!$G28=0,Fund_Zero_Year_2,'ARF Projections'!B28)) -> 20 | M29: =IF('ARF Projections'!$G27=0,"",'ARF Projections'!C28) -> 100000 | N29: =IF('ARF Projections'!$G27=0,"",'ARF Projections'!D28) -> 43738.562 | O29: =IF('ARF Projections'!$G27=0,"",'ARF Projections'!E28) -> 18827.44 | P29: =IF('ARF Projections'!$G27=0,"",'ARF Projections'!F28) -> 97201.603 | Q29: =IF('ARF Projections'!$G27=0,"",'ARF Projections'!G28) -> 27709.519
L30: =IF('ARF Projections'!$G28=0,"", IF('ARF Projections'!$G29=0,Fund_Zero_Year_2,'ARF Projections'!B29)) -> 25 | M30: =IF('ARF Projections'!$G28=0,"",'ARF Projections'!C29) -> 100000 | N30: =IF('ARF Projections'!$G28=0,"",'ARF Projections'!D29) -> 45885.136 | O30: =IF('ARF Projections'!$G28=0,"",'ARF Projections'!E29) -> 19751.442 | P30: =IF('ARF Projections'!$G28=0,"",'ARF Projections'!F29) -> 126133.69 | Q30: =IF('ARF Projections'!$G28=0,"",'ARF Projections'!G29) -> 0
L31: =IF('ARF Projections'!$G29=0,"", IF('ARF Projections'!$G30=0,Fund_Zero_Year_2,'ARF Projections'!B30)) | M31: =IF('ARF Projections'!$G29=0,"",'ARF Projections'!C30) | N31: =IF('ARF Projections'!$G29=0,"",'ARF Projections'!D30) | O31: =IF('ARF Projections'!$G29=0,"",'ARF Projections'!E30) | P31: =IF('ARF Projections'!$G29=0,"",'ARF Projections'!F30) | Q31: =IF('ARF Projections'!$G29=0,"",'ARF Projections'!G30)
C32: Show if [new_allocation_rate] <= 100%: | L32: =IF('ARF Projections'!$G30=0,"", IF('ARF Projections'!$G31=0,Fund_Zero_Year_2,'ARF Projections'!B31)) | M32: =IF('ARF Projections'!$G30=0,"",'ARF Projections'!C31) | N32: =IF('ARF Projections'!$G30=0,"",'ARF Projections'!D31) | O32: =IF('ARF Projections'!$G30=0,"",'ARF Projections'!E31) | P32: =IF('ARF Projections'!$G30=0,"",'ARF Projections'!F31) | Q32: =IF('ARF Projections'!$G30=0,"",'ARF Projections'!G31)
C33: Contribution Charge (%) | D33: =-MIN(new_allocation_rate-1, 0) -> 0 | L33: =IF('ARF Projections'!$G31=0,"", IF('ARF Projections'!$G32=0,Fund_Zero_Year_2,'ARF Projections'!B32)) | M33: =IF('ARF Projections'!$G31=0,"",'ARF Projections'!C32) | N33: =IF('ARF Projections'!$G31=0,"",'ARF Projections'!D32) | O33: =IF('ARF Projections'!$G31=0,"",'ARF Projections'!E32) | P33: =IF('ARF Projections'!$G31=0,"",'ARF Projections'!F32) | Q33: =IF('ARF Projections'!$G31=0,"",'ARF Projections'!G32)
C34: Contribution Charge (€) | D34: =IF('ARF Projections'!J79<0, -'ARF Projections'!J79, 0) -> 0
C35: Invested Amount | D35: =D29-D34 -> 100000
K36: Commission Table | L36: Year | M36: € | N36: € | O36: €
C37: Show if [new_allocation_rate] > 100%: | M37: Contributions payable in that year | N37: Projected total intermediary and sales remuneration payable in that year (6%) | O37: Projected total intermediary and sales remuneration payable in that year (2.65%)
C38: Contribution Rate (%) | D38: =MAX(new_allocation_rate, 0) -> 1 | L38: 1 | M38: ='ARF Projections'!L5 -> 100000 | N38: =IF('ARF Projections'!M5=0,"",'ARF Projections'!M5) -> 4250.8721 | O38: =IF('ARF Projections'!M5=21,"",'ARF Projections'!M21) -> 4247.5134
C39: Additional Contribution (€) | D39: =IF('ARF Projections'!J79 >=0, 'ARF Projections'!J79, 0) -> 0 | L39: 2 | N39: =IF('ARF Projections'!M6=0,"",'ARF Projections'!M6) -> 251.96793 | O39: =IF('ARF Projections'!M6=21,"",'ARF Projections'!M22) -> 241.80018
C40: Invested Amount | D40: =D29+D39 -> 100000 | L40: 3 | N40: =IF('ARF Projections'!M7=0,"",'ARF Projections'!M7) -> 252.90628 | O40: =IF('ARF Projections'!M7=21,"",'ARF Projections'!M23) -> 235.77954
L41: 4 | N41: =IF('ARF Projections'!M8=0,"",'ARF Projections'!M8) -> 253.67577 | O41: =IF('ARF Projections'!M8=21,"",'ARF Projections'!M24) -> 229.44184
...

Sheet Reliances & Limitations
A1: Reliances & Limitations
A3: Allianz Global Life dac
A4: =TODAY() -> 46177
A6: RELIANCES
A7: DATA
A8: In carrying out our work and producing this workbook, we relied on data and other information provided by AGL dac. We have not audited or verified this data and other information. If the underlying data or information is inaccurate or incomplete, the results of our analysis may likewise be inaccurate or incomplete.
A9: We performed a limited review of the data used directly in our analysis for reasonableness and consistency and have not found material defects in the data. If there are material defects in the data, it is possible that they would be uncovered by a detailed, systematic review and comparison of the data to search for data values that are questionable or for relationships that are materially inconsistent. Such a review was beyond the scope of our assignment.
A10: In carrying out our work and producing this workbook, reliance has been placed upon, but not limited to, the following information:
A11: Composition of Funds
A12: Product Parameters including:
A13: - Commission Profile
A14: - Contribution charge
A15: Fund Management Charges
A16: Guarantee Charges
A19: =_xlfn.TEXTJOIN("",TRUE,"This workbook was based on data available to us at, or prior to, ",TEXT(A4,"d mmmm yyyy"), ", and takes no account of developments after that date.") -> This workbook was based on data available to us at, or prior to, 4 Meitheamh 2026, and takes no account of developments after that date.
A20: We supplemented AGL dac's data with insurance industry data where deemed necessary. The use of external data is another source of uncertainty in our estimates.
A22: LIMITATIONS
A23: DISTRIBUTION & USAGE
A24: This workbook has been prepared solely for the internal business use of and is only to be relied upon by the management of AGL dac. No portion of this workbook may be provided to any other party without our prior written consent. In the event such consent is provided, the workbook must be provided in its entirety.
A25: Judgments as to the conclusions contained in this workbook should be made only after studying the workbook in its entirety. Furthermore, conclusions reached by review of a section or sections on an isolated basis may be incorrect.
A26: The workbook is intended to be used by a person with a certain level of expertise in the areas addressed and for the stated purposes only. Any user of this workbook must possess a certain level of expertise in areas relevant to this analysis to appreciate the significance of the assumptions and the impact of these assumptions on the illustrated results. The user should be advised by their own actuaries or other qualified professionals competent in the subject matter of this workbook, so as to properly interpret the material.
A27: This workbook is subject to the terms and limitations, including limitation of liability, set out in our letter of engagement / statement of work / transaction agreement / other relevant agreement.
A29: VARIABILITY OF RESULTS
A30: Differences between our projections and actual amounts depend on the extent to which future experience conforms to the assumptions made for this analysis. The assumptions we have used have, in our view, been made on the basis of reasonable hypotheses. It is certain, however, that actual experience will not conform exactly to the assumptions used in this analysis. Actual amounts will differ from projected amounts to the extent that actual experience deviates from expected experience. Such variations in experience could have a significant effect on the results and conclusions in this workbook. No warranty is given that the assumptions made in this workbook will be reflected in actual future experience.
A32: RECOMMENDED OTHER PROFESSIONAL ADVICE
A33: The consultants who worked on this assignment are insurance actuaries. As such, they are familiar with statutory accounting and GAAP accounting, but are by no means experts in law, taxation, or accounting. Our advice is not, nor is it intended to be, a substitute for qualified legal, tax, or accounting advice.
