Workbook
Name adj_upfront_commission: Projections!$C$64
Name Altered_Initial_Commission_Indicator: Projections!$C$63
Name Commission_Uplift_Factor: Projections!$C$57
Name Contrib_Per_Year: Projections!$C$32
Name Current_Age: Projections!$C$35
Name Custom_Reg_Inc_Perc_annual: Projections!$C$43
Name Exit_Tax_Rate: Projections!$C$50
Name External_Fund_Charge_Monthly: Projections!$D$54
Name Fund_Charge_Monthly: Projections!$D$55
Name Fund_Rates_Table: Parameters!$C$76:$G$89
Name Fund_Zero_Year: Projections!$C$52
Name Government_Levy: Projections!$C$49
Name Growth_Rate_1: Projections!$C$38
Name Growth_Rate_1_Monthly: Projections!$D$38
Name Gtee_Charge_Monthly: Projections!$D$56
Name Gtee_Flag: Projections!$C$39
Name Income_Escalation_Rate_Annual: Projections!$C$45
Name Income_Type: Projections!$C$41
Name Minimum_Fund_Value: Projections!$C$51
Name new_allocation_rate: Projections!$C$67
Name new_upfront_commission: Projections!$C$66
Name Ongoing_Commission_Monthly: Projections!$D$60
Name Policyholder_Type: Projections!$C$25
Name Product_Code: Projections!$C$24
Name Product_Parameters: Parameters!$D$5:$S$47
Name Rate_Of_Return_Monthly: Projections!$D$37
Name RateOfReturn_Max: Projections!$C$36
Name Reg_Contrib: Projections!$C$33
Name Reg_Income_Flag: Projections!$C$40
Name Regular_Income_Amount: Projections!$C$44
Name Regular_Income_Start_Month: Projections!$C$48
Name RP_Allocation_Rate: Projections!$C$68
Name RP_Allowed: Projections!$C$30
Name RP_Escalation_Rate: Projections!$C$34
Name RP_Flag: Projections!$C$29
Name RP_PremFreq: Projections!$C$31
Name RP_special_deal_level: Projections!#REF!
Name RP_upfront_commission: Projections!$C$59
Name SinglePrem: Projections!$C$28
Name special_deal_indicator: Projections!$C$61
Name special_deal_level: Projections!$C$62
Name Start_Date: Projections!$C$26
Name SurrederPenalty_Table: Parameters!$C$48:$E$49
Name Surrender_Penalty_table: Parameters!$C$48:$E$49
Name Tiered_Bonus_Commission_Applies: Projections!$C$65
Name upfront_commission: Projections!$C$58
Name Weighted_Guarantee_Charge: Projections!$T$28
Name Weighted_RateOfReturn_Annual: Projections!$T$25

Sheet Version Control
B2: Version | C2: Date | D2: Change By | E2: Review By | F2: Description
B3: v0.1 | C3: 14/5/26 | D3: George Harding | F3: Investment Bond illustrator spreadsheet created from ARF illustrator
B9: v0.1 | C9: 46220 | D9: Ciaran Murphy | F9: Correction to 'SP Upfront Base' for K1, L1, M1 parameters [i.e. Parameters cell E42]
B10: v0.9 | C10: 46227 | D10: Gearóid Hughes | F10: Change to charges/commission structure
B11: V0.10 | C11: 46261 | D11: Hugh Gannon | F11: Change to cell D19 on Inputs for PointOfIssue Doc to remove surrender penalty wording from
B12: V0.11 | C12: 46262 | D12: Hugh Gannon | F12: Included extra SP allocation for RP charging options where it applies. Changed cell C66 on the Projections tab
B13: V0.12 | C13: 46262 | D13: Hugh Gannon | F13: - Changed formula in cell C52 on the Projections tab for the Year Zero parameter to reference the total policy value rather than just the single premium policy value (no updated required on IMS as already incorporated) - added bonus commission of 0.5% for premiums >=€100k and 1% for premiums >=€500k (added Bonus Commission Applies parameter to cell C65 of Projections, changed formula in cell C67 of Projections, and added a table of Bonus Commission in cells C112 to D114 of Parameters)

Sheet Overview
A1: Overview
A3: Cell Color Key | B3: Cell Color Key | C3: Description
C4: Product and Fund Parameters
C5: Customer specific inputs
C6: Formulas
C7: A flag used where a change in formula occurs during the projection
C8: Regulatory/ ASP inputs
C9: Other Hardcoded Numbers
C10: Summary tables
A14: User Guide | B14: Step | C14: Description
B15: 1 | C15: Update Customer specific inputs on ARF Projection tab
A18: Sheet Description | B18: Sheet Name | C18: Description | D18: HyperLink
B19: Overview | C19: In this tab: (1.) The key information about the EUC is documented. (2.) The user instructions for updating this model is documented. (3.) The purpose of each sheet is also documented. | D19: =A1 -> Overview
B20: Parameters | C20: This tab contains: - Product specific parameters - Fund specific parameters - Regulatory specific inputs. This tab should only be updated if there are changes to any of the above. | D20: =B20 -> Parameters
B21: Projections | C21: This tab projections the ARF over the lifetime of the policy on 2 ASP prescribed growth rates - Customer specifc inputs should be updated here | D21: =B21 -> Projections
B22: Inputs for PointOfIssue Doc | C22: This tab contains inputs for the Point of Issue Disclosure Template | D22: =B22 -> Inputs for PointOfIssue Doc

Sheet Parameters
A1: Parameters
E5: Commission | L5: Surrender Penalty
C6: Product Version | D6: Product Code | E6: SP Upfront Base | F6: SP Upfront Special Deal | G6: RP Upfront Base | H6: RP Upfront Special Deal | I6: RP Allocation Rate | J6: Fund Based Commission | K6: Admin Charge | L6: 1 | M6: 2 | N6: 3 | O6: 4 | P6: 5 | Q6: 6 | R6: 7 | S6: 8
C7: A | D7: A1 | E7: 0 | F7: =E7+IF(special_deal_indicator = "Yes", special_deal_level, 0) -> 0 | G7: 0 | H7: NA | I7: 0 | J7: 0 | K7: 0.0045 | L7: 0 | M7: 0 | N7: 0 | O7: 0 | P7: 0 | Q7: 0 | R7: 0 | S7: 0
C8: B | D8: B1 | E8: 0 | F8: =E8+IF(special_deal_indicator = "Yes", special_deal_level, 0) -> 0 | G8: 0 | H8: NA | I8: 0 | J8: 0.0025 | K8: 0.007 | L8: 0 | M8: 0 | N8: 0 | O8: 0 | P8: 0 | Q8: 0 | R8: 0 | S8: 0
C9: B | D9: B2 | E9: 0.01 | F9: =E9+IF(special_deal_indicator = "Yes", special_deal_level, 0) -> 0.01 | G9: 0 | H9: NA | I9: 0 | J9: 0.00125 | K9: 0.007 | L9: 0.03 | M9: 0.02 | N9: 0.01 | O9: 0 | P9: 0 | Q9: 0 | R9: 0 | S9: 0
C10: B | D10: B3 | E10: 0.02 | F10: =E10+IF(special_deal_indicator = "Yes", special_deal_level, 0) -> 0.02 | G10: 0 | H10: NA | I10: 0 | J10: 0 | K10: 0.007 | L10: 0.03 | M10: 0.02 | N10: 0.01 | O10: 0 | P10: 0 | Q10: 0 | R10: 0 | S10: 0
C11: C | D11: C1 | E11: 0 | F11: =E11+IF(special_deal_indicator = "Yes", special_deal_level, 0) -> 0 | G11: 0 | H11: NA | I11: 0 | J11: 0.005 | K11: 0.0095 | L11: 0 | M11: 0 | N11: 0 | O11: 0 | P11: 0 | Q11: 0 | R11: 0 | S11: 0
C12: C | D12: C2 | E12: 0.01 | F12: =E12+IF(special_deal_indicator = "Yes", special_deal_level, 0) -> 0.01 | G12: 0 | H12: NA | I12: 0 | J12: 0.00375 | K12: 0.0095 | L12: 0.03 | M12: 0.02 | N12: 0.01 | O12: 0 | P12: 0 | Q12: 0 | R12: 0 | S12: 0
C13: C | D13: C3 | E13: 0.02 | F13: =E13+IF(special_deal_indicator = "Yes", special_deal_level, 0) -> 0.02 | G13: 0 | H13: NA | I13: 0 | J13: 0.0025 | K13: 0.0095 | L13: 0.03 | M13: 0.02 | N13: 0.01 | O13: 0 | P13: 0 | Q13: 0 | R13: 0 | S13: 0
C14: C | D14: C4 | E14: 0.03 | F14: =E14+IF(special_deal_indicator = "Yes", special_deal_level, 0) -> 0.03 | G14: 0 | H14: NA | I14: 0 | J14: 0.00125 | K14: 0.0095 | L14: 0.05 | M14: 0.04 | N14: 0.03 | O14: 0.02 | P14: 0.01 | Q14: 0 | R14: 0 | S14: 0
C15: C | D15: C5 | E15: 0.04 | F15: =E15+IF(special_deal_indicator = "Yes", special_deal_level, 0) -> 0.04 | G15: 0 | H15: NA | I15: 0 | J15: 0 | K15: 0.0095 | L15: 0.05 | M15: 0.04 | N15: 0.03 | O15: 0.02 | P15: 0.01 | Q15: 0 | R15: 0 | S15: 0
C16: D | D16: D1 | E16: 0 | F16: =E16+IF(special_deal_indicator = "Yes", special_deal_level, 0) -> 0 | G16: 0 | H16: NA | I16: 0 | J16: 0.0075 | K16: 0.012 | L16: 0 | M16: 0 | N16: 0 | O16: 0 | P16: 0 | Q16: 0 | R16: 0 | S16: 0
C17: D | D17: D2 | E17: 0.01 | F17: =E17+IF(special_deal_indicator = "Yes", special_deal_level, 0) -> 0.01 | G17: 0 | H17: NA | I17: 0 | J17: 0.00625 | K17: 0.012 | L17: 0.03 | M17: 0.02 | N17: 0.01 | O17: 0 | P17: 0 | Q17: 0 | R17: 0 | S17: 0
C18: D | D18: D3 | E18: 0.02 | F18: =E18+IF(special_deal_indicator = "Yes", special_deal_level, 0) -> 0.02 | G18: 0 | H18: NA | I18: 0 | J18: 0.005 | K18: 0.012 | L18: 0.03 | M18: 0.02 | N18: 0.01 | O18: 0 | P18: 0 | Q18: 0 | R18: 0 | S18: 0
... C47: M | D47: M2 | E47: 0.035 | F47: =E47+IF(special_deal_indicator = "Yes", special_deal_level, 0) -> 0.035 | G47: 0.15 | H47: NA | I47: 1 | J47: 0.005 | K47: 0.014 | L47: 0.05 | M47: 0.04 | N47: 0.03 | O47: 0.02 | P47: 0.01 | Q47: 0 | R47: 0 | S47: 0
C50: Growth Assumptions
C51: Equity | D51: 0.072 | E51: ASP-LA8 | F51: ASP LA-8 | G51: Figures effecive from 01/01/2025
C52: Property | D52: 0.072 | E52: ASP-LA8
C53: Fixed Interest | D53: 0.0425 | E53: ASP-LA8
C54: Cash | D54: 0.032 | E54: ASP-LA8
C57: Fund | D57: Equity | E57: Property | F57: Fixed Income | G57: Cash
C58: Growth Assumptions | D58: =D51 -> 0.072 | E58: =D52 -> 0.072 | F58: =D53 -> 0.0425 | G58: =D54 -> 0.032
C59: Strategy Select 30 | D59: 0.3 | E59: 0 | F59: 0.7 | G59: 0 | H59: =1-SUM(D59:G59) -> 0
C60: Strategy Select 50 | D60: 0.5 | E60: 0 | F60: 0.5 | G60: 0 | H60: =1-SUM(D60:G60) -> 0
C61: Strategy Select 75 | D61: 0.75 | E61: 0 | F61: 0.25 | G61: 0 | H61: =1-SUM(D61:G61) -> 0
C62: Allianz Best Styles Global Equity SRI | D62: 1 | E62: 0 | F62: 0 | G62: 0 | H62: =1-SUM(D62:G62) -> 0
C63: Allianz Advanced Fixed Income Short Duration | D63: 0 | E63: 0 | F63: 1 | G63: 0 | H63: =1-SUM(D63:G63) -> 0
C64: Allianz Advanced Fixed Income Euro | D64: 0 | E64: 0 | F64: 1 | G64: 0 | H64: =1-SUM(D64:G64) -> 0
C65: Allianz Dynamic Multi Asset Strategy SRI 75 | D65: 0.75 | E65: 0 | F65: 0.25 | G65: 0 | H65: =1-SUM(D65:G65) -> 0
C66: Allianz Dynamic Multi Asset Strategy SRI 50 | D66: 0.5 | E66: 0 | F66: 0.5 | G66: 0 | H66: =1-SUM(D66:G66) -> 0
C67: Allianz Dynamic Multi Asset Strategy SRI 15 | D67: 0.15 | E67: 0 | F67: 0.85 | G67: 0 | H67: =1-SUM(D67:G67) -> 0
C68: HSBC EURO STOXX 50 UCITS ETF | D68: 1 | E68: 0 | F68: 0 | G68: 0 | H68: =1-SUM(D68:G68) -> 0
C69: HSBC MSCI World UCITS ETF | D69: 1 | E69: 0 | F69: 0 | G69: 0 | H69: =1-SUM(D69:G69) -> 0
C70: HSBC S&P 500 UCITS ETF | D70: 1 | E70: 0 | F70: 0 | G70: 0 | H70: =1-SUM(D70:G70) -> 0
C71: Allianz Euro Cash | D71: 0 | E71: 0 | F71: 0 | G71: 1 | H71: =1-SUM(D71:G71) -> 0
C76: Fund | D76: Guarantee Charge | E76: Growth Rate p.a. | F76: Growth Rate p.m. | G76: External Fund Manager Charge
C77: Strategy Select 30 | D77: 0.0065 | E77: =SUMPRODUCT($D$58:$G$58,D59:G59) -> 0.05135 | F77: =(1+E77)^(1/12)-1 -> 0.0041816398 | G77: 0.0025 | H77: Ext FM charges updated with new fund classes mid 2025
C78: Strategy Select 50 | D78: 0.0075 | E78: =SUMPRODUCT($D$58:$G$58,D60:G60) -> 0.05725 | F78: =(1+E78)^(1/12)-1 -> 0.0046500445 | G78: 0.0025
C79: Strategy Select 75 | D79: 0.0085 | E79: =SUMPRODUCT($D$58:$G$58,D61:G61) -> 0.064625 | F79: =(1+E79)^(1/12)-1 -> 0.0052321924 | G79: 0.0025
...

Sheet Projections
A1: Projections
B3: Year | C3: A | D3: B | E3: C | F3: D | G3: E | H3: F | L3: € | M3: €
C4: Total amount of premiums paid into the policy to date | D4: Projected investment growth to date | E4: Projected expenses and charges to date | F4: Taxation to date | G4: Cumulative income to date after tax | H4: Projected policy value after payment of tax and income | L4: Contributions payable in that year | M4: Projected total intermediary and sales remuneration payable in that year
B5: 1 | C5: =SUMPRODUCT($I$75:$I$674,$AH$75:$AH$674)+SUMPRODUCT($O$75:$O$674,$AH$75:$AH$674) -> 100000 | D5: =SUMPRODUCT($M$75:$M$674,$AH$75:$AH$674)+SUMPRODUCT($S$75:$S$674,$AH$75:$AH$674) -> 5890.9783 | E5: =-SUMPRODUCT($N$75:$N$674,$AH$75:$AH$674)-SUMPRODUCT($T$75:$T$674,$AH$75:$AH$674)+INDEX($AF$75:$AF$674,MATCH($B5*12,$C$75:$C$674,0))-$J$75-SUMPRODUCT($P$75:$P$674,$AH$75:$AH$674) -> 8147.0179 | F5: =-SUMPRODUCT($AC$75:$AC$674,$AH$75:$AH$674)+INDEX($AG$75:$AG$674,MATCH($B5*12,$C$75:$C$674,0)) -> 0 | G5: =-SUMPRODUCT($AD$75:$AD$674,$AH$75:$AH$674) -> 0 | H5: =INDEX($K$75:$K$674,MATCH($B5+1,$B$75:$B$674,0))+INDEX($Q$75:$Q$674,MATCH($B5+1,$B$75:$B$674,0))-INDEX($AF$75:$AF$674,MATCH($B5*12,$C$75:$C$674,0))-INDEX($AG$75:$AG$674,MATCH($B5*12,$C$75:$C$674,0)) -> 97743.96 | L5: =C5 -> 100000 | M5: =-SUMIF($B$75:$B$674,B5,$AE$75:$AE$674) -> 4252.7271 | N5: =M5/H5 -> 0.043508848
B6: 2 | C6: =SUMPRODUCT($I$75:$I$674,$AI$75:$AI$674)+SUMPRODUCT($O$75:$O$674,$AI$75:$AI$674) -> 100000 | D6: =SUMPRODUCT($M$75:$M$674,$AI$75:$AI$674)+SUMPRODUCT($S$75:$S$674,$AI$75:$AI$674) -> 12008.094 | E6: =-SUMPRODUCT($N$75:$N$674,$AI$75:$AI$674)-SUMPRODUCT($T$75:$T$674,$AI$75:$AI$674)+INDEX($AF$75:$AF$674,MATCH($B6*12,$C$75:$C$674,0))-$J$75-SUMPRODUCT($P$75:$P$674,$AI$75:$AI$674) -> 9359.1124 | F6: =-SUMPRODUCT($AC$75:$AC$674,$AI$75:$AI$674)+INDEX($AG$75:$AG$674,MATCH($B6*12,$C$75:$C$674,0)) -> 1006.6129 | G6: =-SUMPRODUCT($AD$75:$AD$674,$AI$75:$AI$674) -> 0 | H6: =INDEX($K$75:$K$674,MATCH($B6+1,$B$75:$B$674,0))+INDEX($Q$75:$Q$674,MATCH($B6+1,$B$75:$B$674,0))-INDEX($AF$75:$AF$674,MATCH($B6*12,$C$75:$C$674,0))-INDEX($AG$75:$AG$674,MATCH($B6*12,$C$75:$C$674,0)) -> 101642.37 | L6: =C6-C5 -> 0 | M6: =-SUMIF($B$75:$B$674,B6,$AE$75:$AE$674) -> 262.53681 | N6: =M6/H6 -> 0.0025829466
B7: 3 | C7: =SUMPRODUCT($I$75:$I$674,$AJ$75:$AJ$674)+SUMPRODUCT($O$75:$O$674,$AJ$75:$AJ$674) -> 100000 | D7: =SUMPRODUCT($M$75:$M$674,$AJ$75:$AJ$674)+SUMPRODUCT($S$75:$S$674,$AJ$75:$AJ$674) -> 18365.263 | E7: =-SUMPRODUCT($N$75:$N$674,$AJ$75:$AJ$674)-SUMPRODUCT($T$75:$T$674,$AJ$75:$AJ$674)+INDEX($AF$75:$AF$674,MATCH($B7*12,$C$75:$C$674,0))-$J$75-SUMPRODUCT($P$75:$P$674,$AJ$75:$AJ$674) -> 10576.812 | F7: =-SUMPRODUCT($AC$75:$AC$674,$AJ$75:$AJ$674)+INDEX($AG$75:$AG$674,MATCH($B7*12,$C$75:$C$674,0)) -> 2959.6111 | G7: =-SUMPRODUCT($AD$75:$AD$674,$AJ$75:$AJ$674) -> 0 | H7: =INDEX($K$75:$K$674,MATCH($B7+1,$B$75:$B$674,0))+INDEX($Q$75:$Q$674,MATCH($B7+1,$B$75:$B$674,0))-INDEX($AF$75:$AF$674,MATCH($B7*12,$C$75:$C$674,0))-INDEX($AG$75:$AG$674,MATCH($B7*12,$C$75:$C$674,0)) -> 104828.84 | L7: =C7-C6 -> 0 | M7: =-SUMIF($B$75:$B$674,B7,$AE$75:$AE$674) -> 272.83952 | N7: =M7/H7 -> 0.0026027144
B8: 4 | C8: =SUMPRODUCT($I$75:$I$674,$AK$75:$AK$674)+SUMPRODUCT($O$75:$O$674,$AK$75:$AK$674) -> 100000 | D8: =SUMPRODUCT($M$75:$M$674,$AK$75:$AK$674)+SUMPRODUCT($S$75:$S$674,$AK$75:$AK$674) -> 24971.905 | E8: =-SUMPRODUCT($N$75:$N$674,$AK$75:$AK$674)-SUMPRODUCT($T$75:$T$674,$AK$75:$AK$674)+INDEX($AF$75:$AF$674,MATCH($B8*12,$C$75:$C$674,0))-$J$75-SUMPRODUCT($P$75:$P$674,$AK$75:$AK$674) -> 11798.691 | F8: =-SUMPRODUCT($AC$75:$AC$674,$AK$75:$AK$674)+INDEX($AG$75:$AG$674,MATCH($B8*12,$C$75:$C$674,0)) -> 5005.8217 | G8: =-SUMPRODUCT($AD$75:$AD$674,$AK$75:$AK$674) -> 0 | H8: =INDEX($K$75:$K$674,MATCH($B8+1,$B$75:$B$674,0))+INDEX($Q$75:$Q$674,MATCH($B8+1,$B$75:$B$674,0))-INDEX($AF$75:$AF$674,MATCH($B8*12,$C$75:$C$674,0))-INDEX($AG$75:$AG$674,MATCH($B8*12,$C$75:$C$674,0)) -> 108167.39 | L8: =C8-C7 -> 0 | M8: =-SUMIF($B$75:$B$674,B8,$AE$75:$AE$674) -> 283.54655 | N8: =M8/H8 -> 0.0026213681
B9: 5 | C9: =SUMPRODUCT($I$75:$I$674,$AL$75:$AL$674)+SUMPRODUCT($O$75:$O$674,$AL$75:$AL$674) -> 100000 | D9: =SUMPRODUCT($M$75:$M$674,$AL$75:$AL$674)+SUMPRODUCT($S$75:$S$674,$AL$75:$AL$674) -> 31837.812 | E9: =-SUMPRODUCT($N$75:$N$674,$AL$75:$AL$674)-SUMPRODUCT($T$75:$T$674,$AL$75:$AL$674)+INDEX($AF$75:$AF$674,MATCH($B9*12,$C$75:$C$674,0))-$J$75-SUMPRODUCT($P$75:$P$674,$AL$75:$AL$674) -> 13023.2 | F9: =-SUMPRODUCT($AC$75:$AC$674,$AL$75:$AL$674)+INDEX($AG$75:$AG$674,MATCH($B9*12,$C$75:$C$674,0)) -> 7149.5527 | G9: =-SUMPRODUCT($AD$75:$AD$674,$AL$75:$AL$674) -> 0 | H9: =INDEX($K$75:$K$674,MATCH($B9+1,$B$75:$B$674,0))+INDEX($Q$75:$Q$674,MATCH($B9+1,$B$75:$B$674,0))-INDEX($AF$75:$AF$674,MATCH($B9*12,$C$75:$C$674,0))-INDEX($AG$75:$AG$674,MATCH($B9*12,$C$75:$C$674,0)) -> 111665.06 | L9: =C9-C8 -> 0 | M9: =-SUMIF($B$75:$B$674,B9,$AE$75:$AE$674) -> 294.67375 | N9: =M9/H9 -> 0.0026389074
B10: 10 | C10: =SUMPRODUCT($I$75:$I$674,$AM$75:$AM$674)+SUMPRODUCT($O$75:$O$674,$AM$75:$AM$674) -> 100000 | D10: =SUMPRODUCT($M$75:$M$674,$AM$75:$AM$674)+SUMPRODUCT($S$75:$S$674,$AM$75:$AM$674) -> 68827.772 | E10: =-SUMPRODUCT($N$75:$N$674,$AM$75:$AM$674)-SUMPRODUCT($T$75:$T$674,$AM$75:$AM$674)-$J$75-SUMPRODUCT($P$75:$P$674,$AM$75:$AM$674) -> 24397.543 | F10: =-SUMPRODUCT($AC$75:$AC$674,$AM$75:$AM$674)+INDEX($AG$75:$AG$674,MATCH($B10*12,$C$75:$C$674,0)) -> 16883.487 | G10: =-SUMPRODUCT($AD$75:$AD$674,$AM$75:$AM$674) -> 0 | H10: =INDEX($K$75:$K$674,MATCH($B10+1,$B$75:$B$674,0))+INDEX($Q$75:$Q$674,MATCH($B10+1,$B$75:$B$674,0))-INDEX($AF$75:$AF$674,MATCH($B10*12,$C$75:$C$674,0))-INDEX($AG$75:$AG$674,MATCH($B10*12,$C$75:$C$674,0)) -> 127546.74 | L10: =C10-C9 -> 0 | M10: =-SUMIF($B$75:$B$674,B10,$AE$75:$AE$674) -> 322.24031 | N10: =M10/H10 -> 0.0025264488
B11: 15 | C11: =SUMPRODUCT($I$75:$I$674,$AN$75:$AN$674)+SUMPRODUCT($O$75:$O$674,$AN$75:$AN$674) -> 100000 | D11: =SUMPRODUCT($M$75:$M$674,$AN$75:$AN$674)+SUMPRODUCT($S$75:$S$674,$AN$75:$AN$674) -> 111026.65 | E11: =-SUMPRODUCT($N$75:$N$674,$AN$75:$AN$674)-SUMPRODUCT($T$75:$T$674,$AN$75:$AN$674)-$J$75-SUMPRODUCT($P$75:$P$674,$AN$75:$AN$674) -> 38742.769 | F11: =-SUMPRODUCT($AC$75:$AC$674,$AN$75:$AN$674)+INDEX($AG$75:$AG$674,MATCH($B11*12,$C$75:$C$674,0)) -> 27467.873 | G11: =-SUMPRODUCT($AD$75:$AD$674,$AN$75:$AN$674) -> 0 | H11: =INDEX($K$75:$K$674,MATCH($B11+1,$B$75:$B$674,0))+INDEX($Q$75:$Q$674,MATCH($B11+1,$B$75:$B$674,0))-INDEX($AF$75:$AF$674,MATCH($B11*12,$C$75:$C$674,0))-INDEX($AG$75:$AG$674,MATCH($B11*12,$C$75:$C$674,0)) -> 144816 | L11: =C11-C10 -> 0 | M11: =-SUMIF($B$75:$B$674,B11,$AE$75:$AE$674) -> 390.62972 | N11: =M11/H11 -> 0.0026974209
B12: 20 | C12: =SUMPRODUCT($I$75:$I$674,$AO$75:$AO$674)+SUMPRODUCT($O$75:$O$674,$AO$75:$AO$674) -> 100000 | D12: =SUMPRODUCT($M$75:$M$674,$AO$75:$AO$674)+SUMPRODUCT($S$75:$S$674,$AO$75:$AO$674) -> 157982.01 | E12: =-SUMPRODUCT($N$75:$N$674,$AO$75:$AO$674)-SUMPRODUCT($T$75:$T$674,$AO$75:$AO$674)-$J$75-SUMPRODUCT($P$75:$P$674,$AO$75:$AO$674) -> 54704.933 | F12: =-SUMPRODUCT($AC$75:$AC$674,$AO$75:$AO$674)+INDEX($AG$75:$AG$674,MATCH($B12*12,$C$75:$C$674,0)) -> 39245.289 | G12: =-SUMPRODUCT($AD$75:$AD$674,$AO$75:$AO$674) -> 0 | H12: =INDEX($K$75:$K$674,MATCH($B12+1,$B$75:$B$674,0))+INDEX($Q$75:$Q$674,MATCH($B12+1,$B$75:$B$674,0))-INDEX($AF$75:$AF$674,MATCH($B12*12,$C$75:$C$674,0))-INDEX($AG$75:$AG$674,MATCH($B12*12,$C$75:$C$674,0)) -> 164031.79 | L12: =C12-C11 -> 0 | M12: =-SUMIF($B$75:$B$674,B12,$AE$75:$AE$674) -> 425.84135 | N12: =M12/H12 -> 0.0025960904
B13: 25 | C13: =SUMPRODUCT($I$75:$I$674,$AP$75:$AP$674)+SUMPRODUCT($O$75:$O$674,$AP$75:$AP$674) -> 100000 | D13: =SUMPRODUCT($M$75:$M$674,$AP$75:$AP$674)+SUMPRODUCT($S$75:$S$674,$AP$75:$AP$674) -> 212536.53 | E13: =-SUMPRODUCT($N$75:$N$674,$AP$75:$AP$674)-SUMPRODUCT($T$75:$T$674,$AP$75:$AP$674)-$J$75-SUMPRODUCT($P$75:$P$674,$AP$75:$AP$674) -> 73250.379 | F13: =-SUMPRODUCT($AC$75:$AC$674,$AP$75:$AP$674)+INDEX($AG$75:$AG$674,MATCH($B13*12,$C$75:$C$674,0)) -> 52928.737 | G13: =-SUMPRODUCT($AD$75:$AD$674,$AP$75:$AP$674) -> 0 | H13: =INDEX($K$75:$K$674,MATCH($B13+1,$B$75:$B$674,0))+INDEX($Q$75:$Q$674,MATCH($B13+1,$B$75:$B$674,0))-INDEX($AF$75:$AF$674,MATCH($B13*12,$C$75:$C$674,0))-INDEX($AG$75:$AG$674,MATCH($B13*12,$C$75:$C$674,0)) -> 186357.41 | L13: =C13-C12 -> 0 | M13: =-SUMIF($B$75:$B$674,B13,$AE$75:$AE$674) -> 464.22699 | N13: =M13/H13 -> 0.0024910573
B14: 30 | C14: =SUMPRODUCT($I$75:$I$674,$AQ$75:$AQ$674)+SUMPRODUCT($O$75:$O$674,$AQ$75:$AQ$674) -> 100000 | D14: =SUMPRODUCT($M$75:$M$674,$AQ$75:$AQ$674)+SUMPRODUCT($S$75:$S$674,$AQ$75:$AQ$674) -> 273329.22 | E14: =-SUMPRODUCT($N$75:$N$674,$AQ$75:$AQ$674)-SUMPRODUCT($T$75:$T$674,$AQ$75:$AQ$674)-$J$75-SUMPRODUCT($P$75:$P$674,$AQ$75:$AQ$674) -> 93916.451 | F14: =-SUMPRODUCT($AC$75:$AC$674,$AQ$75:$AQ$674)+INDEX($AG$75:$AG$674,MATCH($B14*12,$C$75:$C$674,0)) -> 68176.853 | G14: =-SUMPRODUCT($AD$75:$AD$674,$AQ$75:$AQ$674) -> 0 | H14: =INDEX($K$75:$K$674,MATCH($B14+1,$B$75:$B$674,0))+INDEX($Q$75:$Q$674,MATCH($B14+1,$B$75:$B$674,0))-INDEX($AF$75:$AF$674,MATCH($B14*12,$C$75:$C$674,0))-INDEX($AG$75:$AG$674,MATCH($B14*12,$C$75:$C$674,0)) -> 211235.92 | L14: =C14-C13 -> 0 | M14: =-SUMIF($B$75:$B$674,B14,$AE$75:$AE$674) -> 562.75039 | N14: =M14/H14 -> 0.0026640848
B15: 35 | C15: =SUMPRODUCT($I$75:$I$674,$AR$75:$AR$674)+SUMPRODUCT($O$75:$O$674,$AR$75:$AR$674) -> 100000 | D15: =SUMPRODUCT($M$75:$M$674,$AR$75:$AR$674)+SUMPRODUCT($S$75:$S$674,$AR$75:$AR$674) -> 342400.5 | E15: =-SUMPRODUCT($N$75:$N$674,$AR$75:$AR$674)-SUMPRODUCT($T$75:$T$674,$AR$75:$AR$674)-$J$75-SUMPRODUCT($P$75:$P$674,$AR$75:$AR$674) -> 117396.77 | F15: =-SUMPRODUCT($AC$75:$AC$674,$AR$75:$AR$674)+INDEX($AG$75:$AG$674,MATCH($B15*12,$C$75:$C$674,0)) -> 85501.416 | G15: =-SUMPRODUCT($AD$75:$AD$674,$AR$75:$AR$674) -> 0 | H15: =INDEX($K$75:$K$674,MATCH($B15+1,$B$75:$B$674,0))+INDEX($Q$75:$Q$674,MATCH($B15+1,$B$75:$B$674,0))-INDEX($AF$75:$AF$674,MATCH($B15*12,$C$75:$C$674,0))-INDEX($AG$75:$AG$674,MATCH($B15*12,$C$75:$C$674,0)) -> 239502.31 | L15: =C15-C14 -> 0 | M15: =-SUMIF($B$75:$B$674,B15,$AE$75:$AE$674) -> 613.47711 | N15: =M15/H15 -> 0.0025614663
B16: 40 | C16: =SUMPRODUCT($I$75:$I$674,$AS$75:$AS$674)+SUMPRODUCT($O$75:$O$674,$AS$75:$AS$674) -> 100000 | D16: =SUMPRODUCT($M$75:$M$674,$AS$75:$AS$674)+SUMPRODUCT($S$75:$S$674,$AS$75:$AS$674) -> 422738.19 | E16: =-SUMPRODUCT($N$75:$N$674,$AS$75:$AS$674)-SUMPRODUCT($T$75:$T$674,$AS$75:$AS$674)-$J$75-SUMPRODUCT($P$75:$P$674,$AS$75:$AS$674) -> 144707.04 | F16: =-SUMPRODUCT($AC$75:$AC$674,$AS$75:$AS$674)+INDEX($AG$75:$AG$674,MATCH($B16*12,$C$75:$C$674,0)) -> 105651.84 | G16: =-SUMPRODUCT($AD$75:$AD$674,$AS$75:$AS$674) -> 0 | H16: =INDEX($K$75:$K$674,MATCH($B16+1,$B$75:$B$674,0))+INDEX($Q$75:$Q$674,MATCH($B16+1,$B$75:$B$674,0))-INDEX($AF$75:$AF$674,MATCH($B16*12,$C$75:$C$674,0))-INDEX($AG$75:$AG$674,MATCH($B16*12,$C$75:$C$674,0)) -> 272379.32 | L16: =C16-C15 -> 0 | M16: =-SUMIF($B$75:$B$674,B16,$AE$75:$AE$674) -> 743.67602 | N16: =M16/H16 -> 0.0027302955
G20: =IF(T24<>1,"Percentage Invested is not equal to 100%","")
B23: Inputs: | F23: Investment Stategy | G23: Strategy Select 30 | H23: Strategy Select 50 | I23: Strategy Select 75 | J23: Allianz Best Styles Global Equity SRI | K23: Allianz Advanced Fixed Income Short Duration | L23: Allianz Advanced Fixed Income Euro | M23: Allianz Dynamic Multi Asset Strategy SRI 75 | N23: Allianz Dynamic Multi Asset Strategy SRI 50 | O23: Allianz Dynamic Multi Asset Strategy SRI 15 | P23: HSBC EURO STOXX 50 UCITS ETF | Q23: HSBC MSCI World UCITS ETF | R23: HSBC S&P 500 UCITS ETF | S23: Allianz Euro Cash | T23: Annual Rate | U23: Monthly Rate
B24: Product Code | C24: D5 | F24: % invested | G24: 0 | H24: 0.75 | I24: 0 | J24: 0 | K24: 0 | L24: 0 | M24: 0 | N24: 0 | O24: 0 | P24: 0 | Q24: 0 | R24: 0.25 | S24: 0 | T24: =SUM(G24:S24) -> 1
B25: Policyholder Type | C25: Individual | F25: Rate of Return | G25: =VLOOKUP(G$23,Fund_Rates_Table,3,FALSE) -> 0.05135 | H25: =VLOOKUP(H$23,Fund_Rates_Table,3,FALSE) -> 0.05725 | I25: =VLOOKUP(I$23,Fund_Rates_Table,3,FALSE) -> 0.064625 | J25: =VLOOKUP(J$23,Fund_Rates_Table,3,FALSE) -> 0.072 | K25: =VLOOKUP(K$23,Fund_Rates_Table,3,FALSE) -> 0.0425 | L25: =VLOOKUP(L$23,Fund_Rates_Table,3,FALSE) -> 0.0425 | M25: =VLOOKUP(M$23,Fund_Rates_Table,3,FALSE) -> 0.064625 | N25: =VLOOKUP(N$23,Fund_Rates_Table,3,FALSE) -> 0.05725 | ... S25: =VLOOKUP(S$23,Fund_Rates_Table,3,FALSE) -> 0.032 | T25: =MIN(SUMPRODUCT($G$24:$S$24,G25:S25)) -> 0.0609375 | U25: =(1+T25)^(1/12)-1 -> 0.0049415821
B26: Commencement Date | C26: 45917 | F26: External Fund Charge | G26: =VLOOKUP(G$23,Fund_Rates_Table,5,FALSE) -> 0.0025 | H26: =VLOOKUP(H$23,Fund_Rates_Table,5,FALSE) -> 0.0025 | I26: =VLOOKUP(I$23,Fund_Rates_Table,5,FALSE) -> 0.0025 | J26: =VLOOKUP(J$23,Fund_Rates_Table,5,FALSE) -> 0.0045 | K26: =VLOOKUP(K$23,Fund_Rates_Table,5,FALSE) -> 0.0022 | L26: =VLOOKUP(L$23,Fund_Rates_Table,5,FALSE) -> 0.0027 | M26: =VLOOKUP(M$23,Fund_Rates_Table,5,FALSE) -> 0.0065 | N26: =VLOOKUP(N$23,Fund_Rates_Table,5,FALSE) -> 0.0059 | ... S26: =VLOOKUP(S$23,Fund_Rates_Table,5,FALSE) -> 0.0016 | T26: =SUMPRODUCT($G$24:$S$24,G26:S26) -> 0.0021
B27: Date of Birth | C27: 23251 | D27: =DATEDIF(C27, Start_Date, "y") -> 62 | F27: If Guarantee | G27: No | H27: Yes | I27: No
B28: Single Contribution | C28: 100000 | F28: Guarantee Charge | G28: =IF(G27="yes",VLOOKUP(G$23,Fund_Rates_Table,2,FALSE),0) -> 0 | H28: =IF(H27="yes",VLOOKUP(H$23,Fund_Rates_Table,2,FALSE),0) -> 0.0075 | I28: =IF(I27="yes",VLOOKUP(I$23,Fund_Rates_Table,2,FALSE),0) -> 0 | T28: =SUMPRODUCT($G$24:$S$24,G28:S28) -> 0.005625 | U28: =1-(1-T28)^(1/12) -> 0.00046996286
B29: Regular Premium Contribution | C29: No | F29: Invested Funds | G29: =IF(G24="","",G23) -> Strategy Select 30 | H29: =IF(H24="","",H23) -> Strategy Select 50 | I29: =IF(I24="","",I23) -> Strategy Select 75 | J29: =IF(J24="","",J23) -> Allianz Best Styles Global Equity SRI | K29: =IF(K24="","",K23) -> Allianz Advanced Fixed Income Short Duration | L29: =IF(L24="","",L23) -> Allianz Advanced Fixed Income Euro | M29: =IF(M24="","",M23) -> Allianz Dynamic Multi Asset Strategy SRI 75 | N29: =IF(N24="","",N23) -> Allianz Dynamic Multi Asset Strategy SRI 50 | ... S29: =IF(S24="","",S23) -> Allianz Euro Cash
B30: Regular Premium Allowed | C30: =IF(Reg_Income_Flag="Yes","No","Yes") -> Yes
B31: Premium Frequency | C31: Monthly | D31: Assumption in model that if regular income is being taken from outset, regular contributions are not being made | J31: Fund | K31: Investment %
B32: Contribution Per Year | C32: {=_xlfn.IFS(RP_PremFreq = "Monthly", 12, RP_PremFreq = "Quarterly", 4, RP_PremFreq = "Half-Yearly", 2, RP_PremFreq = "Annual", 1, TRUE, 0)} -> 12 | J32: {=IFERROR(INDEX($G$29:$S$29, SMALL(IF($G$29:$S$29<>"", COLUMN($G$29:$S$29)-COLUMN($G$29)+1), ROW(A1))), "")} -> Strategy Select 30 | K32: =IFERROR(HLOOKUP($J32,$G$23:$S$24,2,FALSE),"") -> 0
B33: Regular Contribution Per Annum | C33: 6000 | J33: {=IFERROR(INDEX($G$29:$S$29, SMALL(IF($G$29:$S$29<>"", COLUMN($G$29:$S$29)-COLUMN($G$29)+1), ROW(A2))), "")} -> Strategy Select 50 | K33: =IFERROR(HLOOKUP($J33,$G$23:$S$24,2,FALSE),"") -> 0.75
B34: Contribution Escalation | C34: 0 | D34: Can we either 0% or 3% | J34: {=IFERROR(INDEX($G$29:$S$29, SMALL(IF($G$29:$S$29<>"", COLUMN($G$29:$S$29)-COLUMN($G$29)+1), ROW(A3))), "")} -> Strategy Select 75 | K34: =IFERROR(HLOOKUP($J34,$G$23:$S$24,2,FALSE),"") -> 0
B35: Current Age | C35: =(C26-C27)/365.25 -> 62.056126 | J35: {=IFERROR(INDEX($G$29:$S$29, SMALL(IF($G$29:$S$29<>"", COLUMN($G$29:$S$29)-COLUMN($G$29)+1), ROW(A4))), "")} -> Allianz Best Styles Global Equity SRI | K35: =IFERROR(HLOOKUP($J35,$G$23:$S$24,2,FALSE),"") -> 0
B36: Max Rate of return | C36: 0.06 | D36: ASP LA-8 | J36: {=IFERROR(INDEX($G$29:$S$29, SMALL(IF($G$29:$S$29<>"", COLUMN($G$29:$S$29)-COLUMN($G$29)+1), ROW(A5))), "")} -> Allianz Advanced Fixed Income Short Duration | K36: =IFERROR(HLOOKUP($J36,$G$23:$S$24,2,FALSE),"") -> 0
B37: Expected Rate of Return | C37: =Weighted_RateOfReturn_Annual -> 0.0609375 | D37: =(1+C37)^(1/12)-1 -> 0.0049415821 | J37: {=IFERROR(INDEX($G$29:$S$29, SMALL(IF($G$29:$S$29<>"", COLUMN($G$29:$S$29)-COLUMN($G$29)+1), ROW(A6))), "")} -> Allianz Advanced Fixed Income Euro | K37: =IFERROR(HLOOKUP($J37,$G$23:$S$24,2,FALSE),"") -> 0
B38: Growth Rate (Used in Model) | C38: =MIN(RateOfReturn_Max,C37) -> 0.06 | D38: =(1+Growth_Rate_1)^(1/12)-1 -> 0.0048675506 | J38: {=IFERROR(INDEX($G$29:$S$29, SMALL(IF($G$29:$S$29<>"", COLUMN($G$29:$S$29)-COLUMN($G$29)+1), ROW(A7))), "")} -> Allianz Dynamic Multi Asset Strategy SRI 75 | K38: =IFERROR(HLOOKUP($J38,$G$23:$S$24,2,FALSE),"") -> 0
B39: Guarantee on/off | C39: =IF(OR(G27="Yes",H27="Yes",I27="Yes"),"On","Off") -> On | J39: {=IFERROR(INDEX($G$29:$S$29, SMALL(IF($G$29:$S$29<>"", COLUMN($G$29:$S$29)-COLUMN($G$29)+1), ROW(A8))), "")} -> Allianz Dynamic Multi Asset Strategy SRI 50 | K39: =IFERROR(HLOOKUP($J39,$G$23:$S$24,2,FALSE),"") -> 0
B40: Regular Income Flag | C40: No | E40: =IF(AND(Reg_Income_Flag="Yes",RP_Flag="Yes"),"Regular premium contributions switched off as Regular Income Flag is turned on","") | J40: {=IFERROR(INDEX($G$29:$S$29, SMALL(IF($G$29:$S$29<>"", COLUMN($G$29:$S$29)-COLUMN($G$29)+1), ROW(A9))), "")} -> Allianz Dynamic Multi Asset Strategy SRI 15 | K40: =IFERROR(HLOOKUP($J40,$G$23:$S$24,2,FALSE),"") -> 0
B41: Regular Income Type | C41: Monetary Amount (with Escalation) | E41: =IF(AND(Income_Type="Fixed Percent",Custom_Reg_Inc_Perc_annual=0),"Must input Customer Regular Income % if Regular Income Type = Fixed Percent","") | J41: {=IFERROR(INDEX($G$29:$S$29, SMALL(IF($G$29:$S$29<>"", COLUMN($G$29:$S$29)-COLUMN($G$29)+1), ROW(A10))), "")} -> HSBC EURO STOXX 50 UCITS ETF | K41: =IFERROR(HLOOKUP($J41,$G$23:$S$24,2,FALSE),"") -> 0
B42: Monetary Amount Choosen (annual) | C42: 100000 | J42: {=IFERROR(INDEX($G$29:$S$29, SMALL(IF($G$29:$S$29<>"", COLUMN($G$29:$S$29)-COLUMN($G$29)+1), ROW(A11))), "")} -> HSBC MSCI World UCITS ETF | K42: =IFERROR(HLOOKUP($J42,$G$23:$S$24,2,FALSE),"") -> 0
B43: Custom Regular Income % | C43: 0.05 | J43: {=IFERROR(INDEX($G$29:$S$29, SMALL(IF($G$29:$S$29<>"", COLUMN($G$29:$S$29)-COLUMN($G$29)+1), ROW(A12))), "")} -> HSBC S&P 500 UCITS ETF | K43: =IFERROR(HLOOKUP($J43,$G$23:$S$24,2,FALSE),"") -> 0.25
B44: Start Regular Income Amount | C44: =IF(Income_Type="Fixed Percent",Custom_Reg_Inc_Perc_annual*SinglePrem, IF(Income_Type="Monetary Amount (with Escalation)",$C$42,"error")) -> 100000 | J44: {=IFERROR(INDEX($G$29:$S$29, SMALL(IF($G$29:$S$29<>"", COLUMN($G$29:$S$29)-COLUMN($G$29)+1), ROW(A13))), "")} -> Allianz Euro Cash | K44: =IFERROR(HLOOKUP($J44,$G$23:$S$24,2,FALSE),"") -> 0
B45: Income Escalation % | C45: 0 | D45: Fixed at 0%
B46: Regular Income Start Month (calendar month) | C46: 10 | D46: Note on RP Start Date:
...

Sheet Inputs for PointOfIssue Doc
A1: Inputs for Point Of Disclosure Document
C2: Product Version | E2: =LEFT(Product_Code, 1) -> D
K3: Illustration table assuming growth rate 1 - Regular Income | L3: Year | M3: A | N3: B | O3: C | P3: D | Q3: E | R3: F
C4: Growth Rate 1 (%) | E4: =Growth_Rate_1 -> 0.06 | M4: Total amount of premiums paid into the policy to date | N4: Projected investment growth to date | O4: Projected charges to date | P4: Taxation to date | Q4: Cumulative income to date after tax | R4: Projected policy value after payment of tax and income
E5: Reduced to: | L5: =IF(Reg_Income_Flag="No","",IF(Projections!$H4=0,"", IF(Projections!$H5=0,Fund_Zero_Year,Projections!B5))) | M5: =IF(Reg_Income_Flag="No","",IF(OR(AND($L5>Projections!$C$53,Fund_Zero_Year=""),Projections!$H4=0),"",Projections!C5)) | N5: =IF(Reg_Income_Flag="No","",IF(OR(AND($L5>Projections!$C$53,Fund_Zero_Year=""),Projections!$H4=0),"",Projections!D5)) | O5: =IF(Reg_Income_Flag="No","",IF(OR(AND($L5>Projections!$C$53,Fund_Zero_Year=""),Projections!$H4=0),"",Projections!E5)) | P5: =IF(Reg_Income_Flag="No","",IF(OR(AND($L5>Projections!$C$53,Fund_Zero_Year=""),Projections!$H4=0),"",Projections!F5)) | Q5: =IF(Reg_Income_Flag="No","",IF(OR(AND($L5>Projections!$C$53,Fund_Zero_Year=""),Projections!$H4=0),"",Projections!G5)) | R5: =IF(Reg_Income_Flag="No","",IF(OR(AND($L5>Projections!$C$53,Fund_Zero_Year=""),Projections!$H4=0),"",Projections!H5))
C6: RIY (reduced from [Growth Rate 1 (%)] to) | E6: =Projections!AZ71 -> 0.038720339 | L6: =IF(Reg_Income_Flag="No","",IF(Projections!$H5=0,"", IF(Projections!$H6=0,Fund_Zero_Year,Projections!B6))) | M6: =IF(Reg_Income_Flag="No","",IF(OR(AND($L6>Projections!$C$53,Fund_Zero_Year=""),Projections!$H5=0),"",Projections!C6)) | N6: =IF(Reg_Income_Flag="No","",IF(OR(AND($L6>Projections!$C$53,Fund_Zero_Year=""),Projections!$H5=0),"",Projections!D6)) | O6: =IF(Reg_Income_Flag="No","",IF(OR(AND($L6>Projections!$C$53,Fund_Zero_Year=""),Projections!$H5=0),"",Projections!E6)) | P6: =IF(Reg_Income_Flag="No","",IF(OR(AND($L6>Projections!$C$53,Fund_Zero_Year=""),Projections!$H5=0),"",Projections!F6)) | Q6: =IF(Reg_Income_Flag="No","",IF(OR(AND($L6>Projections!$C$53,Fund_Zero_Year=""),Projections!$H5=0),"",Projections!G6)) | R6: =IF(Reg_Income_Flag="No","",IF(OR(AND($L6>Projections!$C$53,Fund_Zero_Year=""),Projections!$H5=0),"",Projections!H6))
L7: =IF(Reg_Income_Flag="No","",IF(Projections!$H6=0,"", IF(Projections!$H7=0,Fund_Zero_Year,Projections!B7))) | M7: =IF(Reg_Income_Flag="No","",IF(OR(AND($L7>Projections!$C$53,Fund_Zero_Year=""),Projections!$H6=0),"",Projections!C7)) | N7: =IF(Reg_Income_Flag="No","",IF(OR(AND($L7>Projections!$C$53,Fund_Zero_Year=""),Projections!$H6=0),"",Projections!D7)) | O7: =IF(Reg_Income_Flag="No","",IF(OR(AND($L7>Projections!$C$53,Fund_Zero_Year=""),Projections!$H6=0),"",Projections!E7)) | P7: =IF(Reg_Income_Flag="No","",IF(OR(AND($L7>Projections!$C$53,Fund_Zero_Year=""),Projections!$H6=0),"",Projections!F7)) | Q7: =IF(Reg_Income_Flag="No","",IF(OR(AND($L7>Projections!$C$53,Fund_Zero_Year=""),Projections!$H6=0),"",Projections!G7)) | R7: =IF(Reg_Income_Flag="No","",IF(OR(AND($L7>Projections!$C$53,Fund_Zero_Year=""),Projections!$H6=0),"",Projections!H7))
C8: Exit Tax Rate (%) | E8: =Exit_Tax_Rate -> 0.38 | L8: =IF(Reg_Income_Flag="No","",IF(Projections!$H7=0,"", IF(Projections!$H8=0,Fund_Zero_Year,Projections!B8))) | M8: =IF(Reg_Income_Flag="No","",IF(OR(AND($L8>Projections!$C$53,Fund_Zero_Year=""),Projections!$H7=0),"",Projections!C8)) | N8: =IF(Reg_Income_Flag="No","",IF(OR(AND($L8>Projections!$C$53,Fund_Zero_Year=""),Projections!$H7=0),"",Projections!D8)) | O8: =IF(Reg_Income_Flag="No","",IF(OR(AND($L8>Projections!$C$53,Fund_Zero_Year=""),Projections!$H7=0),"",Projections!E8)) | P8: =IF(Reg_Income_Flag="No","",IF(OR(AND($L8>Projections!$C$53,Fund_Zero_Year=""),Projections!$H7=0),"",Projections!F8)) | Q8: =IF(Reg_Income_Flag="No","",IF(OR(AND($L8>Projections!$C$53,Fund_Zero_Year=""),Projections!$H7=0),"",Projections!G8)) | R8: =IF(Reg_Income_Flag="No","",IF(OR(AND($L8>Projections!$C$53,Fund_Zero_Year=""),Projections!$H7=0),"",Projections!H8))
L9: =IF(Reg_Income_Flag="No","",IF(Projections!$H8=0,"", IF(Projections!$H9=0,Fund_Zero_Year,Projections!B9))) | M9: =IF(Reg_Income_Flag="No","",IF(OR(AND($L9>Projections!$C$53,Fund_Zero_Year=""),Projections!$H8=0),"",Projections!C9)) | N9: =IF(Reg_Income_Flag="No","",IF(OR(AND($L9>Projections!$C$53,Fund_Zero_Year=""),Projections!$H8=0),"",Projections!D9)) | O9: =IF(Reg_Income_Flag="No","",IF(OR(AND($L9>Projections!$C$53,Fund_Zero_Year=""),Projections!$H8=0),"",Projections!E9)) | P9: =IF(Reg_Income_Flag="No","",IF(OR(AND($L9>Projections!$C$53,Fund_Zero_Year=""),Projections!$H8=0),"",Projections!F9)) | Q9: =IF(Reg_Income_Flag="No","",IF(OR(AND($L9>Projections!$C$53,Fund_Zero_Year=""),Projections!$H8=0),"",Projections!G9)) | R9: =IF(Reg_Income_Flag="No","",IF(OR(AND($L9>Projections!$C$53,Fund_Zero_Year=""),Projections!$H8=0),"",Projections!H9))
C10: Income Description Text | D10: =IF(Reg_Income_Flag="No","", IF(Income_Type="Monetary Amount (with Escalation)","You have chosen an initial income level of "&TEXT(Projections!C42,"€#,##0")&" per annum.", "You have chosen an income level of "& TEXT(Projections!C43,"0%")& " of the fund value per annum")& "The income to date values in Column E of the table are shown after the payment of tax.") | L10: =IF(Reg_Income_Flag="No","",IF(Projections!$H9=0,"", IF(Projections!$H10=0,Fund_Zero_Year,Projections!B10))) | M10: =IF(Reg_Income_Flag="No","",IF(OR(AND($L10>Projections!$C$53,Fund_Zero_Year=""),Projections!$H9=0),"",Projections!C10)) | N10: =IF(Reg_Income_Flag="No","",IF(OR(AND($L10>Projections!$C$53,Fund_Zero_Year=""),Projections!$H9=0),"",Projections!D10)) | O10: =IF(Reg_Income_Flag="No","",IF(OR(AND($L10>Projections!$C$53,Fund_Zero_Year=""),Projections!$H9=0),"",Projections!E10)) | P10: =IF(Reg_Income_Flag="No","",IF(OR(AND($L10>Projections!$C$53,Fund_Zero_Year=""),Projections!$H9=0),"",Projections!F10)) | Q10: =IF(Reg_Income_Flag="No","",IF(OR(AND($L10>Projections!$C$53,Fund_Zero_Year=""),Projections!$H9=0),"",Projections!G10)) | R10: =IF(Reg_Income_Flag="No","",IF(OR(AND($L10>Projections!$C$53,Fund_Zero_Year=""),Projections!$H9=0),"",Projections!H10))
L11: =IF(Reg_Income_Flag="No","",IF(Projections!$H10=0,"", IF(Projections!$H11=0,Fund_Zero_Year,Projections!B11))) | M11: =IF(Reg_Income_Flag="No","",IF(OR(AND($L11>Projections!$C$53,Fund_Zero_Year=""),Projections!$H10=0),"",Projections!C11)) | N11: =IF(Reg_Income_Flag="No","",IF(OR(AND($L11>Projections!$C$53,Fund_Zero_Year=""),Projections!$H10=0),"",Projections!D11)) | O11: =IF(Reg_Income_Flag="No","",IF(OR(AND($L11>Projections!$C$53,Fund_Zero_Year=""),Projections!$H10=0),"",Projections!E11)) | P11: =IF(Reg_Income_Flag="No","",IF(OR(AND($L11>Projections!$C$53,Fund_Zero_Year=""),Projections!$H10=0),"",Projections!F11)) | Q11: =IF(Reg_Income_Flag="No","",IF(OR(AND($L11>Projections!$C$53,Fund_Zero_Year=""),Projections!$H10=0),"",Projections!G11)) | R11: =IF(Reg_Income_Flag="No","",IF(OR(AND($L11>Projections!$C$53,Fund_Zero_Year=""),Projections!$H10=0),"",Projections!H11))
L12: =IF(Reg_Income_Flag="No","",IF(Projections!$H11=0,"", IF(Projections!$H12=0,Fund_Zero_Year,Projections!B12))) | M12: =IF(Reg_Income_Flag="No","",IF(OR(AND($L12>Projections!$C$53,Fund_Zero_Year=""),Projections!$H11=0),"",Projections!C12)) | N12: =IF(Reg_Income_Flag="No","",IF(OR(AND($L12>Projections!$C$53,Fund_Zero_Year=""),Projections!$H11=0),"",Projections!D12)) | O12: =IF(Reg_Income_Flag="No","",IF(OR(AND($L12>Projections!$C$53,Fund_Zero_Year=""),Projections!$H11=0),"",Projections!E12)) | P12: =IF(Reg_Income_Flag="No","",IF(OR(AND($L12>Projections!$C$53,Fund_Zero_Year=""),Projections!$H11=0),"",Projections!F12)) | Q12: =IF(Reg_Income_Flag="No","",IF(OR(AND($L12>Projections!$C$53,Fund_Zero_Year=""),Projections!$H11=0),"",Projections!G12)) | R12: =IF(Reg_Income_Flag="No","",IF(OR(AND($L12>Projections!$C$53,Fund_Zero_Year=""),Projections!$H11=0),"",Projections!H12))
L13: =IF(Reg_Income_Flag="No","",IF(Projections!$H12=0,"", IF(Projections!$H13=0,Fund_Zero_Year,Projections!B13))) | M13: =IF(Reg_Income_Flag="No","",IF(OR(AND($L13>Projections!$C$53,Fund_Zero_Year=""),Projections!$H12=0),"",Projections!C13)) | N13: =IF(Reg_Income_Flag="No","",IF(OR(AND($L13>Projections!$C$53,Fund_Zero_Year=""),Projections!$H12=0),"",Projections!D13)) | O13: =IF(Reg_Income_Flag="No","",IF(OR(AND($L13>Projections!$C$53,Fund_Zero_Year=""),Projections!$H12=0),"",Projections!E13)) | P13: =IF(Reg_Income_Flag="No","",IF(OR(AND($L13>Projections!$C$53,Fund_Zero_Year=""),Projections!$H12=0),"",Projections!F13)) | Q13: =IF(Reg_Income_Flag="No","",IF(OR(AND($L13>Projections!$C$53,Fund_Zero_Year=""),Projections!$H12=0),"",Projections!G13)) | R13: =IF(Reg_Income_Flag="No","",IF(OR(AND($L13>Projections!$C$53,Fund_Zero_Year=""),Projections!$H12=0),"",Projections!H13))
L14: =IF(Reg_Income_Flag="No","",IF(Projections!$H13=0,"", IF(Projections!$H14=0,Fund_Zero_Year,Projections!B14))) | M14: =IF(Reg_Income_Flag="No","",IF(OR(AND($L14>Projections!$C$53,Fund_Zero_Year=""),Projections!$H13=0),"",Projections!C14)) | N14: =IF(Reg_Income_Flag="No","",IF(OR(AND($L14>Projections!$C$53,Fund_Zero_Year=""),Projections!$H13=0),"",Projections!D14)) | O14: =IF(Reg_Income_Flag="No","",IF(OR(AND($L14>Projections!$C$53,Fund_Zero_Year=""),Projections!$H13=0),"",Projections!E14)) | P14: =IF(Reg_Income_Flag="No","",IF(OR(AND($L14>Projections!$C$53,Fund_Zero_Year=""),Projections!$H13=0),"",Projections!F14)) | Q14: =IF(Reg_Income_Flag="No","",IF(OR(AND($L14>Projections!$C$53,Fund_Zero_Year=""),Projections!$H13=0),"",Projections!G14)) | R14: =IF(Reg_Income_Flag="No","",IF(OR(AND($L14>Projections!$C$53,Fund_Zero_Year=""),Projections!$H13=0),"",Projections!H14))
L15: =IF(Reg_Income_Flag="No","",IF(Projections!$H14=0,"", IF(Projections!$H15=0,Fund_Zero_Year,Projections!B15))) | M15: =IF(Reg_Income_Flag="No","",IF(OR(AND($L15>Projections!$C$53,Fund_Zero_Year=""),Projections!$H14=0),"",Projections!C15)) | N15: =IF(Reg_Income_Flag="No","",IF(OR(AND($L15>Projections!$C$53,Fund_Zero_Year=""),Projections!$H14=0),"",Projections!D15)) | O15: =IF(Reg_Income_Flag="No","",IF(OR(AND($L15>Projections!$C$53,Fund_Zero_Year=""),Projections!$H14=0),"",Projections!E15)) | P15: =IF(Reg_Income_Flag="No","",IF(OR(AND($L15>Projections!$C$53,Fund_Zero_Year=""),Projections!$H14=0),"",Projections!F15)) | Q15: =IF(Reg_Income_Flag="No","",IF(OR(AND($L15>Projections!$C$53,Fund_Zero_Year=""),Projections!$H14=0),"",Projections!G15)) | R15: =IF(Reg_Income_Flag="No","",IF(OR(AND($L15>Projections!$C$53,Fund_Zero_Year=""),Projections!$H14=0),"",Projections!H15))
L16: =IF(Reg_Income_Flag="No","",IF(Projections!$H15=0,"", IF(Projections!$H16=0,Fund_Zero_Year,Projections!B16))) | M16: =IF(Reg_Income_Flag="No","",IF(OR(AND($L16>Projections!$C$53,Fund_Zero_Year=""),Projections!$H15=0),"",Projections!C16)) | N16: =IF(Reg_Income_Flag="No","",IF(OR(AND($L16>Projections!$C$53,Fund_Zero_Year=""),Projections!$H15=0),"",Projections!D16)) | O16: =IF(Reg_Income_Flag="No","",IF(OR(AND($L16>Projections!$C$53,Fund_Zero_Year=""),Projections!$H15=0),"",Projections!E16)) | P16: =IF(Reg_Income_Flag="No","",IF(OR(AND($L16>Projections!$C$53,Fund_Zero_Year=""),Projections!$H15=0),"",Projections!F16)) | Q16: =IF(Reg_Income_Flag="No","",IF(OR(AND($L16>Projections!$C$53,Fund_Zero_Year=""),Projections!$H15=0),"",Projections!G16)) | R16: =IF(Reg_Income_Flag="No","",IF(OR(AND($L16>Projections!$C$53,Fund_Zero_Year=""),Projections!$H15=0),"",Projections!H16))
C17: Fund Zero Year | D17: =Fund_Zero_Year
L18: * charges reflect additional allocation to the policy
C19: Surrender Penalty text | D19: {=IF(_xlfn.XLOOKUP(Product_Code,Parameters!D7:D47,Parameters!L7:L47) = 0,"","Please note that the charges shown in Column C for years 1 to "&(_xlfn.XLOOKUP(0, _xlfn.XLOOKUP(Product_Code,Parameters!D7:D47,Parameters!L7:S47), Parameters!L6:S6, 9,0,1)-1)&" assume that policy is fully encashed and an exit charge is incurred. No exit charge applies to regular withdrawals. If the policy is not encashed in the first "&(_xlfn.XLOOKUP(0, _xlfn.XLOOKUP(Product_Code,Parameters!D7:D47,Parameters!L7:S47), Parameters!L6:S6, 9,0,1)-1)& " years, no exit charge is payable and the total charges actually deducted from the policy in those years are less than shown." )} -> Please note that the charges shown in Column C for years 1 to 5 assume that policy is fully encashed and an exit charge is incurred. No exit charge applies to regular withdrawals. If the policy is not encashed in the first 5 years, no exit charge is payable and the total charges actually deducted from the policy in those years are less than shown.
K20: Illustration table assuming growth rate 1 - No Regular Income | L20: Year | M20: A | N20: B | O20: C | P20: D | Q20: F
K21: {=IF(_xlfn.XLOOKUP(Product_Code,Parameters!D7:D47,Parameters!L7:L47) = 0,"","Please note that the charges shown in Column C for years 1 to "&(_xlfn.XLOOKUP(0, _xlfn.XLOOKUP(Product_Code,Parameters!D7:D47,Parameters!L7:S47), Parameters!L6:S6, 9,0,1)-1)&" assume that policy is fully encashed and an exit charge is incurred. No exit charge applies to regular withdrawals. If the policy is not encashed in the first "&(_xlfn.XLOOKUP(0, _xlfn.XLOOKUP(Product_Code,Parameters!D7:D47,Parameters!L7:S47), Parameters!L6:S6, 9,0,1)-1)& " years, no exit charge is payable and the total charges actually deducted from the policy in those years are less than shown." )} -> Please note that the charges shown in Column C for years 1 to 5 assume that policy is fully encashed and an exit charge is incurred. No exit charge applies to regular withdrawals. If the policy is not encashed in the first 5 years, no exit charge is payable and the total charges actually deducted from the policy in those years are less than shown. | M21: Total amount of premiums paid into the policy to date | N21: Projected investment growth to date | O21: Projected charges to date | P21: Taxation to date | Q21: Projected policy value after payment of tax
K22: =_xlfn.XLOOKUP(Product_Code,Parameters!D7:D47,Parameters!L7:L47) -> 0.05 | L22: =IF(Reg_Income_Flag="Yes","",IF(Projections!$H4=0,"", IF(Projections!$H5=0,Fund_Zero_Year,Projections!B5))) -> 1 | M22: =IF(Reg_Income_Flag="Yes","",IF(Projections!$H4=0,"",Projections!C5)) -> 100000 | N22: =IF(Reg_Income_Flag="Yes","",IF(Projections!$H4=0,"",Projections!D5)) -> 5890.9783 | O22: =IF(Reg_Income_Flag="Yes","",IF(Projections!$H4=0,"",Projections!E5)) -> 8147.0179 | P22: =IF(Reg_Income_Flag="Yes","",IF(Projections!$H4=0,"",Projections!F5)) -> 0 | Q22: =IF(Reg_Income_Flag="Yes","",IF(Projections!$H4=0,"",Projections!H5)) -> 97743.96
L23: =IF(Reg_Income_Flag="Yes","",IF(Projections!$H5=0,"", IF(Projections!$H6=0,Fund_Zero_Year,Projections!B6))) -> 2 | M23: =IF(Reg_Income_Flag="Yes","",IF(Projections!$H5=0,"",Projections!C6)) -> 100000 | N23: =IF(Reg_Income_Flag="Yes","",IF(Projections!$H5=0,"",Projections!D6)) -> 12008.094 | O23: =IF(Reg_Income_Flag="Yes","",IF(Projections!$H5=0,"",Projections!E6)) -> 9359.1124 | P23: =IF(Reg_Income_Flag="Yes","",IF(Projections!$H5=0,"",Projections!F6)) -> 1006.6129 | Q23: =IF(Reg_Income_Flag="Yes","",IF(Projections!$H5=0,"",Projections!H6)) -> 101642.37
L24: =IF(Reg_Income_Flag="Yes","",IF(Projections!$H6=0,"", IF(Projections!$H7=0,Fund_Zero_Year,Projections!B7))) -> 3 | M24: =IF(Reg_Income_Flag="Yes","",IF(Projections!$H6=0,"",Projections!C7)) -> 100000 | N24: =IF(Reg_Income_Flag="Yes","",IF(Projections!$H6=0,"",Projections!D7)) -> 18365.263 | O24: =IF(Reg_Income_Flag="Yes","",IF(Projections!$H6=0,"",Projections!E7)) -> 10576.812 | P24: =IF(Reg_Income_Flag="Yes","",IF(Projections!$H6=0,"",Projections!F7)) -> 2959.6111 | Q24: =IF(Reg_Income_Flag="Yes","",IF(Projections!$H6=0,"",Projections!H7)) -> 104828.84
L25: =IF(Reg_Income_Flag="Yes","",IF(Projections!$H7=0,"", IF(Projections!$H8=0,Fund_Zero_Year,Projections!B8))) -> 4 | M25: =IF(Reg_Income_Flag="Yes","",IF(Projections!$H7=0,"",Projections!C8)) -> 100000 | N25: =IF(Reg_Income_Flag="Yes","",IF(Projections!$H7=0,"",Projections!D8)) -> 24971.905 | O25: =IF(Reg_Income_Flag="Yes","",IF(Projections!$H7=0,"",Projections!E8)) -> 11798.691 | P25: =IF(Reg_Income_Flag="Yes","",IF(Projections!$H7=0,"",Projections!F8)) -> 5005.8217 | Q25: =IF(Reg_Income_Flag="Yes","",IF(Projections!$H7=0,"",Projections!H8)) -> 108167.39
C26: Single Contribution Paid | D26: =SinglePrem -> 100000 | L26: =IF(Reg_Income_Flag="Yes","",IF(Projections!$H8=0,"", IF(Projections!$H9=0,Fund_Zero_Year,Projections!B9))) -> 5 | M26: =IF(Reg_Income_Flag="Yes","",IF(Projections!$H8=0,"",Projections!C9)) -> 100000 | N26: =IF(Reg_Income_Flag="Yes","",IF(Projections!$H8=0,"",Projections!D9)) -> 31837.812 | O26: =IF(Reg_Income_Flag="Yes","",IF(Projections!$H8=0,"",Projections!E9)) -> 13023.2 | P26: =IF(Reg_Income_Flag="Yes","",IF(Projections!$H8=0,"",Projections!F9)) -> 7149.5527 | Q26: =IF(Reg_Income_Flag="Yes","",IF(Projections!$H8=0,"",Projections!H9)) -> 111665.06
L27: =IF(Reg_Income_Flag="Yes","",IF(Projections!$H9=0,"", IF(Projections!$H10=0,Fund_Zero_Year,Projections!B10))) -> 10 | M27: =IF(Reg_Income_Flag="Yes","",IF(Projections!$H9=0,"",Projections!C10)) -> 100000 | N27: =IF(Reg_Income_Flag="Yes","",IF(Projections!$H9=0,"",Projections!D10)) -> 68827.772 | O27: =IF(Reg_Income_Flag="Yes","",IF(Projections!$H9=0,"",Projections!E10)) -> 24397.543 | P27: =IF(Reg_Income_Flag="Yes","",IF(Projections!$H9=0,"",Projections!F10)) -> 16883.487 | Q27: =IF(Reg_Income_Flag="Yes","",IF(Projections!$H9=0,"",Projections!H10)) -> 127546.74
C28: Regular Contibutions per frequency | D28: =Reg_Contrib/Contrib_Per_Year -> 500 | L28: =IF(Reg_Income_Flag="Yes","",IF(Projections!$H10=0,"", IF(Projections!$H11=0,Fund_Zero_Year,Projections!B11))) -> 15 | M28: =IF(Reg_Income_Flag="Yes","",IF(Projections!$H10=0,"",Projections!C11)) -> 100000 | N28: =IF(Reg_Income_Flag="Yes","",IF(Projections!$H10=0,"",Projections!D11)) -> 111026.65 | O28: =IF(Reg_Income_Flag="Yes","",IF(Projections!$H10=0,"",Projections!E11)) -> 38742.769 | P28: =IF(Reg_Income_Flag="Yes","",IF(Projections!$H10=0,"",Projections!F11)) -> 27467.873 | Q28: =IF(Reg_Income_Flag="Yes","",IF(Projections!$H10=0,"",Projections!H11)) -> 144816
C29: Contribution Frequency | D29: =RP_PremFreq -> Monthly | L29: =IF(Reg_Income_Flag="Yes","",IF(Projections!$H11=0,"", IF(Projections!$H12=0,Fund_Zero_Year,Projections!B12))) -> 20 | M29: =IF(Reg_Income_Flag="Yes","",IF(Projections!$H11=0,"",Projections!C12)) -> 100000 | N29: =IF(Reg_Income_Flag="Yes","",IF(Projections!$H11=0,"",Projections!D12)) -> 157982.01 | O29: =IF(Reg_Income_Flag="Yes","",IF(Projections!$H11=0,"",Projections!E12)) -> 54704.933 | P29: =IF(Reg_Income_Flag="Yes","",IF(Projections!$H11=0,"",Projections!F12)) -> 39245.289 | Q29: =IF(Reg_Income_Flag="Yes","",IF(Projections!$H11=0,"",Projections!H12)) -> 164031.79
C31: Show if Single Premium [new_allocation_rate] <= 100%:
C32: Contribution Charge (%) | D32: =-MIN(new_allocation_rate-1, 0) -> 0
C33: Contribution Charge (€) | D33: =IF(Projections!J75<0, -Projections!J75, 0) -> 0
C34: Invested Amount | D34: =D26-D33-D52 -> 99000
C36: Show if Single Premium [new_allocation_rate] > 100%: | K36: remuneration table | L36: Year | M36: € | N36: €
C37: Contribution Rate (%) | D37: =MAX(new_allocation_rate, 0) -> 1 | M37: Contributions payable in that year | N37: Projected total intermediary and sales remuneration payable in that year
C38: Additional Contribution (€) | D38: =IF(Projections!J75 >=0, Projections!J75, 0) -> 0 | L38: 1 | M38: =Projections!L5 -> 100000 | N38: =IF(Projections!M5=0,"",Projections!M5) -> 4252.7271
C39: Invested Amount | D39: =D26+D38-D52 -> 99000 | L39: 2 | M39: =IF(Projections!L6=0,"",Projections!L6) | N39: =IF(Projections!M6=0,"",Projections!M6) -> 262.53681
L40: 3 | M40: =IF(Projections!L7=0,"",Projections!L7) | N40: =IF(Projections!M7=0,"",Projections!M7) -> 272.83952
C41: Show if Regular Premium [new_allocation_rate] <= 100%: | L41: 4 | M41: =IF(Projections!L8=0,"",Projections!L8) | N41: =IF(Projections!M8=0,"",Projections!M8) -> 283.54655
C42: Contribution Charge (%) | D42: =-MIN(RP_Allocation_Rate-1, 0) -> 1 | L42: 5 | M42: =IF(Projections!L9=0,"",Projections!L9) | N42: =IF(Projections!M9=0,"",Projections!M9) -> 294.67375
...

Sheet Documentation
B2: Modelling Assumptions
A3: - | B3: It is assumed that a policyholder paying a regular premium contribution from the outset cannot at the same time receive a regular income from the model
A4: - | B4: All regular income is assumed to be paid monthly. This is a simplification that does not allow for actual income payment timings. See email from Kevin Manning and Hugh Gannon on 25th April 2025 confirming this approach is compliant
A5: - | B5: The investment return used in the calculation of reduction in yield is on a gross of tax basis.

Sheet Reliances & Limitations
A1: Reliances & Limitations
A3: Allianz Global Life dac
A4: =TODAY() -> 46282
A6: RELIANCES
A7: DATA
A8: In carrying out our work and producing this workbook, we relied on data and other information provided by AGL dac. We have not audited or verified this data and other information. If the underlying data or information is inaccurate or incomplete, the results of our analysis may likewise be inaccurate or incomplete.
A9: We performed a limited review of the data used directly in our analysis for reasonableness and consistency and have not found material defects in the data. If there are material defects in the data, it is possible that they would be uncovered by a detailed, systematic review and comparison of the data to search for data values that are questionable or for relationships that are materially inconsistent. Such a review was beyond the scope of our assignment.
A10: In carrying out our work and producing this workbook, reliance has been placed upon, but not limited to, the following information:
A11: Composition of Funds
A12: Product Parameters including:
A13: - Commission Profile
A14: - Contribution charge
A15: Fund Management Charges
A16: Guarantee Charges
A19: =_xlfn.TEXTJOIN("",TRUE,"This workbook was based on data available to us at, or prior to, ",TEXT(A4,"d mmmm yyyy"), ", and takes no account of developments after that date.") -> This workbook was based on data available to us at, or prior to, 17 September 2026, and takes no account of developments after that date.
A20: We supplemented AGL dac's data with insurance industry data where deemed necessary. The use of external data is another source of uncertainty in our estimates.
A22: LIMITATIONS
A23: DISTRIBUTION & USAGE
A24: This workbook has been prepared solely for the internal business use of and is only to be relied upon by the management of AGL dac. No portion of this workbook may be provided to any other party without our prior written consent. In the event such consent is provided, the workbook must be provided in its entirety.
A25: Judgments as to the conclusions contained in this workbook should be made only after studying the workbook in its entirety. Furthermore, conclusions reached by review of a section or sections on an isolated basis may be incorrect.
A26: The workbook is intended to be used by a person with a certain level of expertise in the areas addressed and for the stated purposes only. Any user of this workbook must possess a certain level of expertise in areas relevant to this analysis to appreciate the significance of the assumptions and the impact of these assumptions on the illustrated results. The user should be advised by their own actuaries or other qualified professionals competent in the subject matter of this workbook, so as to properly interpret the material.
A27: This workbook is subject to the terms and limitations, including limitation of liability, set out in our letter of engagement / statement of work / transaction agreement / other relevant agreement.
A29: VARIABILITY OF RESULTS
A30: Differences between our projections and actual amounts depend on the extent to which future experience conforms to the assumptions made for this analysis. The assumptions we have used have, in our view, been made on the basis of reasonable hypotheses. It is certain, however, that actual experience will not conform exactly to the assumptions used in this analysis. Actual amounts will differ from projected amounts to the extent that actual experience deviates from expected experience. Such variations in experience could have a significant effect on the results and conclusions in this workbook. No warranty is given that the assumptions made in this workbook will be reflected in actual future experience.
A32: RECOMMENDED OTHER PROFESSIONAL ADVICE
A33: The consultants who worked on this assignment are insurance actuaries. As such, they are familiar with statutory accounting and GAAP accounting, but are by no means experts in law, taxation, or accounting. Our advice is not, nor is it intended to be, a substitute for qualified legal, tax, or accounting advice.
