Workbook
Name avc_indicator: SRP!$C$3
Name Commission_Uplift_Factor: [1]SRP!$D$65
Name Commission_Uplift_Factor: SRP!$D$65
Name Contributions_per_year: [1]SRP!$G$61
Name Contributions_per_year: SRP!$G$61
Name DIY_Chrge_Table: 'Investment Strategy Funds'!$T$4:$W$17
Name DIY_ExtManChrge_CurrentFunds: [1]SRP!$Q$6
Name DIY_ExtManChrge_CurrentFunds: SRP!$T$6
Name DIY_ExtManChrge_FuturePremiums: [1]SRP!$Q$15
Name DIY_ExtManChrge_FuturePremiums: SRP!$T$15
Name DIY_ExtManChrge_SP: [1]SRP!$Q$11
Name DIY_ExtManChrge_SP: SRP!$T$11
Name DIY_GteeChrge_CurrentFunds: [1]SRP!$Q$8
Name DIY_GteeChrge_CurrentFunds: SRP!$T$8
Name DIY_GteeChrge_FuturePremiums: [1]SRP!$Q$16
Name DIY_GteeChrge_FuturePremiums: SRP!$T$16
Name DIY_GteeChrge_SP: [1]SRP!$Q$12
Name DIY_GteeChrge_SP: SRP!$T$12
Name DIY_RateOfReturn_CurrentFunds: [1]SRP!$Q$5
Name DIY_RateOfReturn_CurrentFunds: SRP!$T$5
Name DIY_RateOfReturn_FuturePremiums: [1]SRP!$Q$14
Name DIY_RateOfReturn_FuturePremiums: SRP!$T$14
Name DIY_RateofReturn_SP: [1]SRP!$Q$10
Name DIY_RateofReturn_SP: SRP!$T$10
Name External_Man_Chrge: [1]Parameters!$C$38:$I$48
Name External_Man_Chrge: Parameters!$C$47:$I$60
Name Gtee_Chrge: [1]Parameters!$C$31:$D$34
Name Gtee_Chrge: Parameters!$C$40:$D$43
Name Investment_Strategy: [1]SRP!$C$6
Name Investment_Strategy: SRP!$C$6
Name Investment_Strategy_Sub1: [1]SRP!$C$7
Name Investment_Strategy_Sub1: SRP!$C$7
Name Investment_Strategy_Sub2: [1]SRP!$C$8
Name Investment_Strategy_Sub2: SRP!$C$8
Name Max_Contrib_Escalation: [1]SRP!$G$62
Name Max_Contrib_Escalation: SRP!$G$62
Name Max_InvReturn: [1]SRP!$D$78
Name Max_InvReturn: SRP!$D$78
Name NS_AP_Bal: 'Investment Strategy Funds'!$D$21:$G$24
Name NS_AP_Dyn: 'Investment Strategy Funds'!$D$26:$G$28
Name NS_AP_Opp: 'Investment Strategy Funds'!$D$30:$G$32
Name NS_DIS: 'Investment Strategy Funds'!$D$34:$G$40
Name NS_LC_Bal: 'Investment Strategy Funds'!$D$4:$G$7
Name NS_LC_Dyn: 'Investment Strategy Funds'!$D$9:$G$13
Name NS_LC_Opp: 'Investment Strategy Funds'!$D$15:$G$19
Name Opening_Fund_Value: [1]SRP!$D$58
Name Opening_Fund_Value: SRP!$D$58
Name Premium_Month1_Flag: [1]SRP!$I$60
Name Premium_Month1_Flag: SRP!$I$60
Name Product_Type: [1]SRP!$C$5
Name Product_Type: SRP!$C$5
Name Product_Version: [1]SRP!$C$4
Name Product_Version: SRP!$C$4
Name Rates_of_Return: [1]Parameters!$K$38:$L$48
Name Rates_of_Return: Parameters!$K$47:$L$60
Name S_DIS: 'Investment Strategy Funds'!$L$21:$O$23
Name S_LC_Bal: 'Investment Strategy Funds'!$L$4:$O$7
Name S_LC_Dyn: 'Investment Strategy Funds'!$L$9:$O$11
Name S_LC_Opp: 'Investment Strategy Funds'!$L$15:$O$17
Name Single_Equivalence_Charge: [1]SRP!$BE$86

Sheet Version Control
C3: Date | D3: Version | E3: Change | F3: By | G3: Reviewed By
C4: 45806 | D4: V1.0 | E4: Fund Charges Update | F4: Gearóid Hughes | G4: Hugh Gannon
C5: 45814 | D5: V1.1 | E5: Back to old fund charges | F5: Hugh Gannon
C6: 45819 | D6: V2.0 | E6: Fund Charges Update | F6: Gearóid Hughes | G6: Hugh Gannon
C7: 46000 | D7: V3.0 | E7: AVC PRSA Update | F7: Gearóid Hughes | G7: Hugh Gannon
C8: 46080 | D8: V3.1 | E8: Updated to add the new HSBC funds, detailed change notes in email | F8: Gearóid Hughes
C9: 46080 | D9: V3.2 | E9: Updated parameters for AMC and Contribution charge | F9: Gearóid Hughes
C10: 46080 | D10: V3.3 | E10: Updated the Commission Structure | F10: Gearóid Hughes
C11: 46080 | D11: V4 | E11: Sign-off on V3 Changes | F11: Gearóid Hughes | G11: Hugh Gannon
C12: 46141 | D12: V5 | E12: Updated prescribed assumptions | F12: Gearóid Hughes

Sheet Overview
A1: Overview
A3: Cell Color Key | B3: Cell Color Key | C3: Description
C4: Product and Fund Parameters
C5: Customer specific inputs
C6: Formulas
C7: A flag used where a change in formula occurs during the projection
C8: Regulatory/ ASP inputs
C9: Other hardcoded Numbers
C10: Summary tables
A14: User Guide | B14: Step | C14: Description
B15: 1 | C15: Update Customer specific inputs on SRP tab
A18: Sheet Description | B18: Sheet Name | C18: Description | D18: HyperLink
B19: Overview | C19: In this tab: (1.) The key information about the EUC is documented. (2.) The user instructions for updating this model is documented. (3.) The purpose of each sheet is also documented. | D19: =B19 -> Overview
B20: Parameters | C20: This tab contains: - Product specific parameters - Fund specific parameters - Regulatory specific inputs. This tab should only be updated if there are changes to any of the above. | D20: =B20 -> Parameters
B21: Mortality Table | C21: This tab contains the mortality tables that are used to determine the qx used in calculating the annuity rates | D21: =B21 -> Mortality Table
B22: Irish Life Quote | C22: This tab provides the annuity rate to use if term to maturity is less than 5 years | D22: =B22 -> Irish Life Quote
B23: Investment Strategies | C23: This tab contains: - The Fund Glidepaths - Rate of Return -Charges for all defined investment stategies | D23: =B23 -> Investment Strategies
B24: SRP | C24: This tab projection the PRSA over the lifetime of the policy. - Customer specifc inputs should be updated here | D24: =B24 -> SRP
B25: Investment Strategy Funds | C25: This tab contains fund based and guarantee charges for all funds within each investment strategy | D25: =B25 -> Investment Strategy Funds
B26: Fund Based Charges Text | C26: This tab contains the prescribed text to use for each investment strategy which is subsequently used in the 2 following tabs | D26: =B26 -> Fund Based Charges Text
B27: Initial SRP doc Inputs | C27: This tab contains the inputs for the initial SRP document | D27: =B27 -> Initial SRP doc Inputs
B28: InForce SRP doc Inputs | C28: This tab contains the inputs for the existing SRP document | D28: =B28 -> InForce SRP doc Inputs

Sheet Parameters
F5: Commission
C6: Product Version | D6: Type | F6: SP Upfront | G6: RP Upfront | H6: Ongoing | I6: Admin Charge | J6: Total AMC
C7: A | D7: 1. Non-Standard | E7: =C7&"_"&D7 -> A_1. Non-Standard | F7: 0 | G7: N/A | H7: 0.0075 | I7: 0.0115 | J7: 1.30% - 2.25%
C8: A | D8: 2. Non-Standard | E8: =C8&"_"&D8 -> A_2. Non-Standard | F8: 0.01 | G8: 0.4% * Term, max 5% | H8: 0.006 | I8: 0.0115 | J8: 1.30% - 2.25%
C9: A | D9: 3. Non-Standard | E9: =C9&"_"&D9 -> A_3. Non-Standard | F9: 0.02 | G9: 0.8% * Term, max 10% | H9: 0.005 | I9: 0.0115 | J9: 1.30% - 2.25%
C10: A | D10: 4. Non-Standard | E10: =C10&"_"&D10 -> A_4. Non-Standard | F10: 0.03 | G10: 1% * Term, max 15% | H10: 0.0035 | I10: 0.0115 | J10: 1.30% - 2.25%
C11: A | D11: 5. Non-Standard | E11: =C11&"_"&D11 -> A_5. Non-Standard | F11: 0.04 | G11: 1.3% * Term, max 20% | H11: 0.0025 | I11: 0.0115 | J11: 1.30% - 2.25%
C12: B | D12: 1. Non-Standard | E12: =C12&"_"&D12 -> B_1. Non-Standard | F12: 0 | G12: 0 | H12: 0.005 | I12: 0.009 | J12: 1.05% - 2.00%
C13: B | D13: 2. Non-Standard | E13: =C13&"_"&D13 -> B_2. Non-Standard | F13: 0.01 | G13: 0.4% * Term, max 5% | H13: 0.0035 | I13: 0.009 | J13: 1.05% - 2.00%
C14: B | D14: 3. Non-Standard | E14: =C14&"_"&D14 -> B_3. Non-Standard | F14: 0.035 | G14: 0.8% * Term, max 10% | H14: 0.0025 | I14: 0.009 | J14: 1.05% - 2.00%
C15: B | D15: 4. Non-Standard | E15: =C15&"_"&D15 -> B_4. Non-Standard | F15: 0.03 | G15: 1% * Term, max 15% | H15: 0.001 | I15: 0.009 | J15: 1.30% - 2.25%
C16: B | D16: 5. Non-Standard | E16: =C16&"_"&D16 -> B_5. Non-Standard | F16: 0.04 | G16: 1.3% * Term, max 20% | H16: 0 | I16: 0.009 | J16: 1.30% - 2.25%
C17: C | D17: 1. Non-Standard | E17: =C17&"_"&D17 -> C_1. Non-Standard | F17: 0 | G17: 0 | H17: 0.0025 | I17: 0.0065 | J17: 0.85% - 1.80%
C18: C | D18: 2. Non-Standard | E18: =C18&"_"&D18 -> C_2. Non-Standard | F18: 0.01 | G18: 0.4% * Term, max 5% | H18: 0.0012 | I18: 0.0065 | J18: 0.85% - 1.80%
C19: C | D19: 3. Non-Standard | E19: =C19&"_"&D19 -> C_3. Non-Standard | F19: 0.02 | G19: 0.8% * Term, max 10% | H19: 0 | I19: 0.0065 | J19: 0.85% - 1.80%
C20: D | D20: 1. Non-Standard | E20: =C20&"_"&D20 -> D_1. Non-Standard | F20: 0 | G20: 0 | H20: 0 | I20: 0.004 | J20: 0.55% - 1.50%
C21: E | D21: 1. Standard | E21: =C21&"_"&D21 -> E_1. Standard | F21: 0 | G21: 0 | H21: 0.0025 | I21: 0.007
C22: E | D22: 2. Standard | E22: =C22&"_"&D22 -> E_2. Standard | F22: 0.01 | G22: 0.4% * Term, max 5% | H22: 0.0012 | I22: 0.007
C23: E | D23: 3. Standard | E23: =C23&"_"&D23 -> E_3. Standard | F23: 0.02 | G23: 0.8% * Term, max 10% | H23: 0 | I23: 0.007
C24: F | D24: 1. Non-Standard | E24: =C24&"_"&D24 -> F_1. Non-Standard | F24: 0 | G24: N/A | H24: 0.01 | I24: 0.014
C25: F | D25: 2. Non-Standard | E25: =C25&"_"&D25 -> F_2. Non-Standard | F25: 0.01 | G25: 0.4% * Term, max 5% | H25: 0.0085 | I25: 0.014
C26: F | D26: 3. Non-Standard | E26: =C26&"_"&D26 -> F_3. Non-Standard | F26: 0.02 | G26: 0.8% * Term, max 10% | H26: 0.0075 | I26: 0.014
C27: F | D27: 4. Non-Standard | E27: =C27&"_"&D27 -> F_4. Non-Standard | F27: 0.03 | G27: 1% * Term, max 15% | H27: 0.006 | I27: 0.014
C28: F | D28: 5. Non-Standard | E28: =C28&"_"&D28 -> F_5. Non-Standard | F28: 0.04 | G28: 1.3% * Term, max 20% | H28: 0.005 | I28: 0.014
C31: Single Premium Size | D31: Allocation Charge | G31: Regular Premium Size | H31: Allocation Charge
C32: Up €10,000 | D32: 0.02 | G32: Up to €100 per month | H32: 0.02
C33: €10,000 and over | D33: 0 | G33: €100 and over p.m. | H33: 0
C39: Guarnatee Charge
C40: Chosen Fund(s) | D40: GMAB Charge p.a. | G40: Assumed Rates of Return
C41: Allianz Strategy Select 30 | D41: 0.0065 | G41: Equities | H41: 0.072 | I41: =H41*0.75+H42*0.25 -> 0.064625 | J41: 2025 Growth Rates from:
C42: Allianz Strategy Select 50 | D42: 0.0075 | G42: Fixed Income | H42: 0.0425 | J42: ASP PRSA-2 V1.14 final.pdf
C43: Allianz Strategy Select 75 | D43: 0.0085 | G43: Cash | H43: 0.032
E45: Fund Charge Values from:
C46: External Fund Charge | E46: AGL historic TERs and Calc or TER Ranges.xlsx | K46: Rates of Return
C47: Fund Name | D47: ISIN | E47: Fund Manager Charge | F47: Bounded Charge | G47: Lower Bound | H47: Upper Bound | I47: Charge Value 2025 | K47: Fund Name | L47: Rate of return
C48: Allianz Strategy Select 30 | D48: LU1901058732 | E48: 0.0025 | F48: No | G48: N/A | H48: N/A | I48: 0.0025 | K48: Allianz Strategy Select 30 | L48: =0.3*H41+0.7*H42 -> 0.05135
C49: Allianz Strategy Select 50 | D49: LU1462180164 | E49: 0.0025 | F49: No | G49: N/A | H49: N/A | I49: 0.0025 | K49: Allianz Strategy Select 50 | L49: =0.5*H41+0.5*H42 -> 0.05725
C50: Allianz Strategy Select 75 | D50: LU1462191526 | E50: 0.0025 | F50: No | G50: N/A | H50: N/A | I50: 0.0025 | K50: Allianz Strategy Select 75 | L50: =0.75*H41+0.25*H42 -> 0.064625
C51: Allianz Best Styles Global Equity SRI | D51: LU2437558831 | E51: =H51 -> 0.005 | F51: Yes | G51: 0.0043 | H51: 0.005 | I51: 0.0045 | K51: Allianz Best Styles Global Equity SRI | L51: =H41 -> 0.072
C52: Allianz Advanced Fixed Income Short Duration | D52: LU1328247389 | E52: =H52 -> 0.0024 | F52: Yes | G52: 0.0022 | H52: 0.0024 | I52: 0.0022 | K52: Allianz Advanced Fixed Income Short Duration | L52: =$H$42 -> 0.0425
...

Sheet Mortality Table
D2: =SRP_Male_qx_adj -> 0.42 | E2: =SRP_Female_qx_adj -> 0.5
A4: AgeExact | B4: ILT15 (Males)_base | C4: ILT15 (Females)_base | D4: ILT15 (Males)_adjusted | E4: ILT15 (Females)_adjusted
A5: 0 | B5: 0 | C5: 0 | D5: =B5*D$2 -> 0 | E5: =C5*E$2 -> 0
A6: 16 | B6: 0 | C6: 0 | D6: =B6*D$2 -> 0 | E6: =C6*E$2 -> 0
A7: 17 | B7: 0 | C7: 0 | D7: =B7*D$2 -> 0 | E7: =C7*E$2 -> 0
A8: 18 | B8: 0 | C8: 0 | D8: =B8*D$2 -> 0 | E8: =C8*E$2 -> 0
A9: 19 | B9: 0 | C9: 0 | D9: =B9*D$2 -> 0 | E9: =C9*E$2 -> 0
A10: 20 | B10: 0.00103 | C10: 0.00033 | D10: =B10*D$2 -> 0.0004326 | E10: =C10*E$2 -> 0.000165
A11: 21 | B11: 0.00109 | C11: 0.00031 | D11: =B11*D$2 -> 0.0004578 | E11: =C11*E$2 -> 0.000155
A12: 22 | B12: 0.00113 | C12: 0.0003 | D12: =B12*D$2 -> 0.0004746 | E12: =C12*E$2 -> 0.00015
A13: 23 | B13: 0.00112 | C13: 0.0003 | D13: =B13*D$2 -> 0.0004704 | E13: =C13*E$2 -> 0.00015
A14: 24 | B14: 0.00107 | C14: 0.00031 | D14: =B14*D$2 -> 0.0004494 | E14: =C14*E$2 -> 0.000155
A15: 25 | B15: 0.00101 | C15: 0.00031 | D15: =B15*D$2 -> 0.0004242 | E15: =C15*E$2 -> 0.000155
A16: 26 | B16: 0.00095 | C16: 0.00032 | D16: =B16*D$2 -> 0.000399 | E16: =C16*E$2 -> 0.00016
... A109: 119 | B109: 0.51026 | C109: 0.45654 | D109: =B109*D$2 -> 0.2143092 | E109: =C109*E$2 -> 0.22827
A110: 120 | B110: 1 | C110: 1 | D110: 1 | E110: 1
A111: =A110+1 -> 121 | B111: 1 | C111: 1 | D111: 1 | E111: 1
A112: =A111+1 -> 122 | B112: 1 | C112: 1 | D112: 1 | E112: 1
A113: =A112+1 -> 123 | B113: 1 | C113: 1 | D113: 1 | E113: 1
A114: =A113+1 -> 124 | B114: 1 | C114: 1 | D114: 1 | E114: 1
A115: =A114+1 -> 125 | B115: 1 | C115: 1 | D115: 1 | E115: 1
A116: =A115+1 -> 126 | B116: 1 | C116: 1 | D116: 1 | E116: 1
A117: =A116+1 -> 127 | B117: 1 | C117: 1 | D117: 1 | E117: 1
A118: =A117+1 -> 128 | B118: 1 | C118: 1 | D118: 1 | E118: 1
A119: =A118+1 -> 129 | B119: 1 | C119: 1 | D119: 1 | E119: 1
A120: =A119+1 -> 130 | B120: 1 | C120: 1 | D120: 1 | E120: 1
A121: =A120+1 -> 131 | B121: 1 | C121: 1 | D121: 1 | E121: 1
A122: =A121+1 -> 132 | B122: 1 | C122: 1 | D122: 1 | E122: 1
... A153: =A152+1 -> 163 | B153: 1 | C153: 1 | D153: 1 | E153: 1

Sheet Irish Life Quote
B1: https://www.pensionplanetinteractive.ie/ppi/public/pensionChoicePersonalDetails.action
S8: Rate | T8: 0.05129
S9: Factor per month | T9: =12/T8 -> 233.96374

Sheet Investment Strategies
D1: Rate of Return | E1: =VLOOKUP(E$4,Rates_of_Return,2,FALSE) -> 0.0425 | F1: =VLOOKUP(F$4,Rates_of_Return,2,FALSE) -> 0.046925 | G1: =VLOOKUP(G$4,Rates_of_Return,2,FALSE) -> 0.064625 | H1: =VLOOKUP(H$4,Rates_of_Return,2,FALSE) -> 0.072 | U1: Rate of Return | V1: =VLOOKUP(V$4,Rates_of_Return,2,FALSE) -> 0.064625 | W1: =VLOOKUP(W$4,Rates_of_Return,2,FALSE) -> 0.05135 | X1: =VLOOKUP(X$4,Rates_of_Return,2,FALSE) -> 0.0425 | AK1: Rate of Return | AL1: =VLOOKUP(AL$4,Rates_of_Return,2,FALSE) -> 0.064625 | AM1: =VLOOKUP(AM$4,Rates_of_Return,2,FALSE) -> 0.05135 | AN1: =VLOOKUP(AN$4,Rates_of_Return,2,FALSE) -> 0.0425 | BA1: Rate of Return | BB1: =VLOOKUP(BB$4,Rates_of_Return,2,FALSE) -> 0.0425 | BC1: =VLOOKUP(BC$4,Rates_of_Return,2,FALSE) -> 0.046925 | BD1: =VLOOKUP(BD$4,Rates_of_Return,2,FALSE) -> 0.064625 | BE1: =VLOOKUP(BE$4,Rates_of_Return,2,FALSE) -> 0.072 | BF1: =VLOOKUP(BF$4,Rates_of_Return,2,FALSE) -> 0.064625 | BG1: =VLOOKUP(BG$4,Rates_of_Return,2,FALSE) -> 0.05725 | BH1: =VLOOKUP(BH$4,Rates_of_Return,2,FALSE) -> 0.05135
D2: External Management Charge | E2: =VLOOKUP(E$4,External_Man_Chrge,3,FALSE) -> 0.0024 | F2: =VLOOKUP(F$4,External_Man_Chrge,3,FALSE) -> 0.0059 | G2: =VLOOKUP(G$4,External_Man_Chrge,3,FALSE) -> 0.0072 | H2: =VLOOKUP(H$4,External_Man_Chrge,3,FALSE) -> 0.005 | U2: External Management Charge | V2: =VLOOKUP(V$4,External_Man_Chrge,3,FALSE) -> 0.0025 | W2: =VLOOKUP(W$4,External_Man_Chrge,3,FALSE) -> 0.0025 | X2: =VLOOKUP(X$4,External_Man_Chrge,3,FALSE) -> 0.0024 | AK2: External Management Charge | AL2: =VLOOKUP(AL$4,External_Man_Chrge,3,FALSE) -> 0.0025 | AM2: =VLOOKUP(AM$4,External_Man_Chrge,3,FALSE) -> 0.0025 | AN2: =VLOOKUP(AN$4,External_Man_Chrge,3,FALSE) -> 0.0024 | BA2: External Management Charge | BB2: =VLOOKUP(BB$4,External_Man_Chrge,3,FALSE) -> 0.0024 | BC2: =VLOOKUP(BC$4,External_Man_Chrge,3,FALSE) -> 0.0059 | BD2: =VLOOKUP(BD$4,External_Man_Chrge,3,FALSE) -> 0.0072 | BE2: =VLOOKUP(BE$4,External_Man_Chrge,3,FALSE) -> 0.005 | BF2: =VLOOKUP(BF$4,External_Man_Chrge,3,FALSE) -> 0.0025 | BG2: =VLOOKUP(BG$4,External_Man_Chrge,3,FALSE) -> 0.0025 | BH2: =VLOOKUP(BH$4,External_Man_Chrge,3,FALSE) -> 0.0025
A3: Non-Standard | D3: Guarantee Charge | E3: =IFERROR(VLOOKUP(E$4,Gtee_Chrge,2,FALSE),) -> 0 | F3: =IFERROR(VLOOKUP(F$4,Gtee_Chrge,2,FALSE),) -> 0 | G3: =IFERROR(VLOOKUP(G$4,Gtee_Chrge,2,FALSE),) -> 0 | H3: =IFERROR(VLOOKUP(H$4,Gtee_Chrge,2,FALSE),) -> 0 | U3: Guarantee Charge | V3: =IFERROR(VLOOKUP(V$4,Gtee_Chrge,2,FALSE),) -> 0.0085 | W3: =IFERROR(VLOOKUP(W$4,Gtee_Chrge,2,FALSE),) -> 0.0065 | X3: =IFERROR(VLOOKUP(X$4,Gtee_Chrge,2,FALSE),) -> 0 | AH3: Standard | AK3: Guarantee Charge | AL3: =IFERROR(VLOOKUP(AL$4,Gtee_Chrge,2,FALSE),) -> 0.0085 | AM3: =IFERROR(VLOOKUP(AM$4,Gtee_Chrge,2,FALSE),) -> 0.0065 | AN3: =IFERROR(VLOOKUP(AN$4,Gtee_Chrge,2,FALSE),) -> 0 | BA3: Guarantee Charge | BB3: =IFERROR(VLOOKUP(BB$4,Gtee_Chrge,2,FALSE),) -> 0 | BC3: =IFERROR(VLOOKUP(BC$4,Gtee_Chrge,2,FALSE),) -> 0 | BD3: =IFERROR(VLOOKUP(BD$4,Gtee_Chrge,2,FALSE),) -> 0 | BE3: =IFERROR(VLOOKUP(BE$4,Gtee_Chrge,2,FALSE),) -> 0 | BF3: =IFERROR(VLOOKUP(BF$4,Gtee_Chrge,2,FALSE),) -> 0.0085 | BG3: =IFERROR(VLOOKUP(BG$4,Gtee_Chrge,2,FALSE),) -> 0.0075 | BH3: =IFERROR(VLOOKUP(BH$4,Gtee_Chrge,2,FALSE),) -> 0.0065
A4: Strategy | B4: Sub Category | D4: Months to retirement | E4: Allianz Advanced Fixed Income Short Duration | F4: Allianz Dynamic Multi Asset Strategy SRI 15 | G4: Allianz Dynamic Multi Asset Strategy SRI 75 | H4: Allianz Best Styles Global Equity SRI | J4: Average Rate of Return | K4: Monthly rate of Return | L4: Guarantee Status | M4: Average Guarantee Charge | N4: Monthly Guarantee charge | O4: Average External AMC | P4: Monthly External AMC | R4: Stragegy | S4: Sub Category | U4: Months to retirement | V4: ='[2]AP Balanced'!R$1 -> Allianz Strategy Select 75 | W4: ='[2]AP Balanced'!S$1 -> Allianz Strategy Select 30 | X4: ='[2]AP Balanced'!T$1 -> Allianz Advanced Fixed Income Short Duration | Z4: Average Rate of Return | AA4: Monthly rate of Return | AB4: Guarantee Status | AC4: Average Guarantee Charge | AD4: Monthly Guarantee charge | AE4: Average External AMC | AF4: Monthly External AMC | AH4: Stragegy | AI4: Sub Category | AK4: Months to retirement | AL4: =[2]Standard_Balanced!R$1 -> Allianz Strategy Select 75 | AM4: =[2]Standard_Balanced!S$1 -> Allianz Strategy Select 30 | AN4: =[2]Standard_Balanced!T$1 -> Allianz Advanced Fixed Income Short Duration | AP4: Average Rate of Return | AQ4: Monthly rate of Return | AR4: Guarantee Status | AS4: Average Guarantee Charge | AT4: Monthly Guarantee charge | AU4: Average External AMC | AV4: Monthly External AMC | AX4: Stragegy | AY4: Sub Category | BA4: Month | BB4: ='[2]NonStandard DIS'!R$1 -> Allianz Advanced Fixed Income Short Duration | BC4: ='[2]NonStandard DIS'!S$1 -> Allianz Dynamic Multi Asset Strategy SRI 15 | BD4: ='[2]NonStandard DIS'!T$1 -> Allianz Dynamic Multi Asset Strategy SRI 75 | BE4: ='[2]NonStandard DIS'!U$1 -> Allianz Best Styles Global Equity SRI | BF4: ='[2]NonStandard DIS'!V$1 -> Allianz Strategy Select 75 | BG4: ='[2]NonStandard DIS'!W$1 -> Allianz Strategy Select 50 | BH4: ='[2]NonStandard DIS'!X$1 -> Allianz Strategy Select 30 | BJ4: Average Rate of Return | BK4: Monthly rate of Return | BL4: Guarantee Status | BM4: Average Guarantee Charge | BN4: Monthly Guarantee charge | BO4: Average External AMC | BP4: Monthly External AMC
A5: Lifecycle | B5: Balanced | C5: =A5&"_"&B5&"_"&D5 -> Lifecycle_Balanced_540 | D5: 540 | E5: =VLOOKUP($D5,'[2]LC Balanced'!$Q$2:$U$542,2,FALSE) -> 0 | F5: =VLOOKUP($D5,'[2]LC Balanced'!$Q$2:$U$542,3,FALSE) -> 0.149 | G5: =VLOOKUP($D5,'[2]LC Balanced'!$Q$2:$U$542,4,FALSE) -> 0.851 | H5: =VLOOKUP($D5,'[2]LC Balanced'!$Q$2:$U$542,5,FALSE) -> 0 | I5: =SUM(E5:H5) -> 1 | J5: =SUMPRODUCT($E$1:$H$1,E5:H5) -> 0.0619877 | K5: =(1+J5)^(1/12)-1 -> 0.0050244421 | L5: 0 | M5: =IF($L5=0,0,SUMPRODUCT($E$3:$H$3,E5:H5)) -> 0 | N5: =1-(1-M5)^(1/12) -> 0 | O5: =SUMPRODUCT($E$2:$H$2,E5:H5) -> 0.0070063 | P5: =1-(1-O5)^(1/12) -> 0.00058574167 | R5: Autopilot | S5: Balanced | T5: =R5&"_"&S5&"_"&U5 -> Autopilot_Balanced_540 | U5: 540 | V5: =VLOOKUP($U5,'[2]AP Balanced'!$Q$1:$T$542,2,FALSE) -> 0.77777778 | W5: =VLOOKUP($U5,'[2]AP Balanced'!$Q$1:$T$542,3,FALSE) -> 0.22222222 | X5: =VLOOKUP($U5,'[2]AP Balanced'!$Q$1:$T$542,4,FALSE) -> 0 | Y5: =SUM(V5:X5) -> 1 | Z5: =SUMPRODUCT($V$1:$X$1,V5:X5) -> 0.061675 | AA5: =(1+Z5)^(1/12)-1 -> 0.0049997782 | AB5: 1 | AC5: =IF($AB5=0,0,SUMPRODUCT($V$3:$X$3,V5:X5)) -> 0.0080555556 | AD5: =1-(1-AC5)^(1/12) -> 0.00067378764 | AE5: =SUMPRODUCT($V$2:$X$2,V5:X5) -> 0.0025 | AF5: =1-(1-AE5)^(1/12) -> 0.00020857243 | AH5: Lifecycle | AI5: Balanced | AJ5: =AH5&"_"&AI5&"_"&AK5 -> Lifecycle_Balanced_540 | AK5: 540 | AL5: =VLOOKUP($U5,[2]Standard_Balanced!$Q$1:$T$542,2,FALSE) -> 0.77777778 | AM5: =VLOOKUP($U5,[2]Standard_Balanced!$Q$1:$T$542,3,FALSE) -> 0.22222222 | AN5: =VLOOKUP($U5,[2]Standard_Balanced!$Q$1:$T$542,4,FALSE) -> 0 | AO5: =SUM(AL5:AN5) -> 1 | AP5: =SUMPRODUCT($AL$1:$AN$1,AL5:AN5) -> 0.061675 | AQ5: =(1+AP5)^(1/12)-1 -> 0.0049997782 | AR5: 0 | AS5: =IF(AR5=0,0,SUMPRODUCT($AL$3:$AN$3,AL5:AN5)) -> 0 | AT5: =1-(1-AS5)^(1/12) -> 0 | AU5: =SUMPRODUCT($AL$2:$AN$2,AL5:AN5) -> 0.0025 | AV5: =1-(1-AU5)^(1/12) -> 0.00020857243 | AX5: DIS | AY5: Non-Standard | AZ5: =AX5&"_"&AY5&"_"&BA5 -> DIS_Non-Standard_540 | BA5: 540 | BB5: =VLOOKUP($BA5,'[2]NonStandard DIS'!$Q$1:$X$542,2,FALSE) -> 0 | BC5: =VLOOKUP($BA5,'[2]NonStandard DIS'!$Q$1:$X$542,3,FALSE) -> 0 | BD5: =VLOOKUP($BA5,'[2]NonStandard DIS'!$Q$1:$X$542,4,FALSE) -> 0.308 | BE5: =VLOOKUP($BA5,'[2]NonStandard DIS'!$Q$1:$X$542,5,FALSE) -> 0.692 | BF5: =VLOOKUP($BA5,'[2]NonStandard DIS'!$Q$1:$X$542,6,FALSE) -> 0 | BG5: =VLOOKUP($BA5,'[2]NonStandard DIS'!$Q$1:$X$542,7,FALSE) -> 0 | BH5: =VLOOKUP($BA5,'[2]NonStandard DIS'!$Q$1:$X$542,8,FALSE) -> 0 | BI5: =SUM(BB5:BH5) -> 1 | BJ5: =SUMPRODUCT($BB$1:$BH$1,BB5:BH5) -> 0.0697285 | BK5: =(1+BJ5)^(1/12)-1 -> 0.0056328785 | BL5: 0 | BM5: =IF(BL5=0,0,SUMPRODUCT($BB$3:$BH$3,BB5:BH5)) -> 0 | BN5: =(1+BM5)^(1/12)-1 -> 0 | BO5: =SUMPRODUCT($BB$2:$BH$2,BB5:BH5) -> 0.0056776 | BP5: =(1+BO5)^(1/12)-1 -> 0.00047190658
A6: Lifecycle | B6: Balanced | C6: =A6&"_"&B6&"_"&D6 -> Lifecycle_Balanced_539 | D6: 539 | E6: =VLOOKUP($D6,'[2]LC Balanced'!$Q$2:$U$542,2,FALSE) -> 0 | F6: =VLOOKUP($D6,'[2]LC Balanced'!$Q$2:$U$542,3,FALSE) -> 0.149 | G6: =VLOOKUP($D6,'[2]LC Balanced'!$Q$2:$U$542,4,FALSE) -> 0.851 | H6: =VLOOKUP($D6,'[2]LC Balanced'!$Q$2:$U$542,5,FALSE) -> 0 | I6: =SUM(E6:H6) -> 1 | J6: =SUMPRODUCT($E$1:$H$1,E6:H6) -> 0.0619877 | K6: =(1+J6)^(1/12)-1 -> 0.0050244421 | L6: 0 | M6: =IF($L6=0,0,SUMPRODUCT($E$3:$H$3,E6:H6)) -> 0 | N6: =1-(1-M6)^(1/12) -> 0 | O6: =SUMPRODUCT($E$2:$H$2,E6:H6) -> 0.0070063 | P6: =1-(1-O6)^(1/12) -> 0.00058574167 | R6: Autopilot | S6: Balanced | T6: =R6&"_"&S6&"_"&U6 -> Autopilot_Balanced_539 | U6: 539 | V6: =VLOOKUP($U6,'[2]AP Balanced'!$Q$1:$T$542,2,FALSE) -> 0.77777778 | W6: =VLOOKUP($U6,'[2]AP Balanced'!$Q$1:$T$542,3,FALSE) -> 0.22222222 | X6: =VLOOKUP($U6,'[2]AP Balanced'!$Q$1:$T$542,4,FALSE) -> 0 | Y6: =SUM(V6:X6) -> 1 | Z6: =SUMPRODUCT($V$1:$X$1,V6:X6) -> 0.061675 | AA6: =(1+Z6)^(1/12)-1 -> 0.0049997782 | AB6: 1 | AC6: =IF($AB6=0,0,SUMPRODUCT($V$3:$X$3,V6:X6)) -> 0.0080555556 | AD6: =1-(1-AC6)^(1/12) -> 0.00067378764 | AE6: =SUMPRODUCT($V$2:$X$2,V6:X6) -> 0.0025 | AF6: =1-(1-AE6)^(1/12) -> 0.00020857243 | AH6: Lifecycle | AI6: Balanced | AJ6: =AH6&"_"&AI6&"_"&AK6 -> Lifecycle_Balanced_539 | AK6: 539 | AL6: =VLOOKUP($U6,[2]Standard_Balanced!$Q$1:$T$542,2,FALSE) -> 0.77777778 | AM6: =VLOOKUP($U6,[2]Standard_Balanced!$Q$1:$T$542,3,FALSE) -> 0.22222222 | AN6: =VLOOKUP($U6,[2]Standard_Balanced!$Q$1:$T$542,4,FALSE) -> 0 | AO6: =SUM(AL6:AN6) -> 1 | AP6: =SUMPRODUCT($AL$1:$AN$1,AL6:AN6) -> 0.061675 | AQ6: =(1+AP6)^(1/12)-1 -> 0.0049997782 | AR6: 0 | AS6: =IF(AR6=0,0,SUMPRODUCT($AL$3:$AN$3,AL6:AN6)) -> 0 | AT6: =1-(1-AS6)^(1/12) -> 0 | AU6: =SUMPRODUCT($AL$2:$AN$2,AL6:AN6) -> 0.0025 | AV6: =1-(1-AU6)^(1/12) -> 0.00020857243 | AX6: DIS | AY6: Non-Standard | AZ6: =AX6&"_"&AY6&"_"&BA6 -> DIS_Non-Standard_539 | BA6: 539 | BB6: =VLOOKUP($BA6,'[2]NonStandard DIS'!$Q$1:$X$542,2,FALSE) -> 0 | BC6: =VLOOKUP($BA6,'[2]NonStandard DIS'!$Q$1:$X$542,3,FALSE) -> 0 | BD6: =VLOOKUP($BA6,'[2]NonStandard DIS'!$Q$1:$X$542,4,FALSE) -> 0.308 | BE6: =VLOOKUP($BA6,'[2]NonStandard DIS'!$Q$1:$X$542,5,FALSE) -> 0.692 | BF6: =VLOOKUP($BA6,'[2]NonStandard DIS'!$Q$1:$X$542,6,FALSE) -> 0 | BG6: =VLOOKUP($BA6,'[2]NonStandard DIS'!$Q$1:$X$542,7,FALSE) -> 0 | BH6: =VLOOKUP($BA6,'[2]NonStandard DIS'!$Q$1:$X$542,8,FALSE) -> 0 | BI6: =SUM(BB6:BH6) -> 1 | BJ6: =SUMPRODUCT($BB$1:$BH$1,BB6:BH6) -> 0.0697285 | BK6: =(1+BJ6)^(1/12)-1 -> 0.0056328785 | BL6: 0 | BM6: =IF(BL6=0,0,SUMPRODUCT($BB$3:$BH$3,BB6:BH6)) -> 0 | BN6: =(1+BM6)^(1/12)-1 -> 0 | BO6: =SUMPRODUCT($BB$2:$BH$2,BB6:BH6) -> 0.0056776 | BP6: =(1+BO6)^(1/12)-1 -> 0.00047190658
A7: Lifecycle | B7: Balanced | C7: =A7&"_"&B7&"_"&D7 -> Lifecycle_Balanced_538 | D7: 538 | E7: =VLOOKUP($D7,'[2]LC Balanced'!$Q$2:$U$542,2,FALSE) -> 0 | F7: =VLOOKUP($D7,'[2]LC Balanced'!$Q$2:$U$542,3,FALSE) -> 0.149 | G7: =VLOOKUP($D7,'[2]LC Balanced'!$Q$2:$U$542,4,FALSE) -> 0.851 | H7: =VLOOKUP($D7,'[2]LC Balanced'!$Q$2:$U$542,5,FALSE) -> 0 | I7: =SUM(E7:H7) -> 1 | J7: =SUMPRODUCT($E$1:$H$1,E7:H7) -> 0.0619877 | K7: =(1+J7)^(1/12)-1 -> 0.0050244421 | L7: 0 | M7: =IF($L7=0,0,SUMPRODUCT($E$3:$H$3,E7:H7)) -> 0 | N7: =1-(1-M7)^(1/12) -> 0 | O7: =SUMPRODUCT($E$2:$H$2,E7:H7) -> 0.0070063 | P7: =1-(1-O7)^(1/12) -> 0.00058574167 | R7: Autopilot | S7: Balanced | T7: =R7&"_"&S7&"_"&U7 -> Autopilot_Balanced_538 | U7: 538 | V7: =VLOOKUP($U7,'[2]AP Balanced'!$Q$1:$T$542,2,FALSE) -> 0.77777778 | W7: =VLOOKUP($U7,'[2]AP Balanced'!$Q$1:$T$542,3,FALSE) -> 0.22222222 | X7: =VLOOKUP($U7,'[2]AP Balanced'!$Q$1:$T$542,4,FALSE) -> 0 | Y7: =SUM(V7:X7) -> 1 | Z7: =SUMPRODUCT($V$1:$X$1,V7:X7) -> 0.061675 | AA7: =(1+Z7)^(1/12)-1 -> 0.0049997782 | AB7: 1 | AC7: =IF($AB7=0,0,SUMPRODUCT($V$3:$X$3,V7:X7)) -> 0.0080555556 | AD7: =1-(1-AC7)^(1/12) -> 0.00067378764 | AE7: =SUMPRODUCT($V$2:$X$2,V7:X7) -> 0.0025 | AF7: =1-(1-AE7)^(1/12) -> 0.00020857243 | AH7: Lifecycle | AI7: Balanced | AJ7: =AH7&"_"&AI7&"_"&AK7 -> Lifecycle_Balanced_538 | AK7: 538 | AL7: =VLOOKUP($U7,[2]Standard_Balanced!$Q$1:$T$542,2,FALSE) -> 0.77777778 | AM7: =VLOOKUP($U7,[2]Standard_Balanced!$Q$1:$T$542,3,FALSE) -> 0.22222222 | AN7: =VLOOKUP($U7,[2]Standard_Balanced!$Q$1:$T$542,4,FALSE) -> 0 | AO7: =SUM(AL7:AN7) -> 1 | AP7: =SUMPRODUCT($AL$1:$AN$1,AL7:AN7) -> 0.061675 | AQ7: =(1+AP7)^(1/12)-1 -> 0.0049997782 | AR7: 0 | AS7: =IF(AR7=0,0,SUMPRODUCT($AL$3:$AN$3,AL7:AN7)) -> 0 | AT7: =1-(1-AS7)^(1/12) -> 0 | AU7: =SUMPRODUCT($AL$2:$AN$2,AL7:AN7) -> 0.0025 | AV7: =1-(1-AU7)^(1/12) -> 0.00020857243 | AX7: DIS | AY7: Non-Standard | AZ7: =AX7&"_"&AY7&"_"&BA7 -> DIS_Non-Standard_538 | BA7: 538 | BB7: =VLOOKUP($BA7,'[2]NonStandard DIS'!$Q$1:$X$542,2,FALSE) -> 0 | BC7: =VLOOKUP($BA7,'[2]NonStandard DIS'!$Q$1:$X$542,3,FALSE) -> 0 | BD7: =VLOOKUP($BA7,'[2]NonStandard DIS'!$Q$1:$X$542,4,FALSE) -> 0.308 | BE7: =VLOOKUP($BA7,'[2]NonStandard DIS'!$Q$1:$X$542,5,FALSE) -> 0.692 | BF7: =VLOOKUP($BA7,'[2]NonStandard DIS'!$Q$1:$X$542,6,FALSE) -> 0 | BG7: =VLOOKUP($BA7,'[2]NonStandard DIS'!$Q$1:$X$542,7,FALSE) -> 0 | BH7: =VLOOKUP($BA7,'[2]NonStandard DIS'!$Q$1:$X$542,8,FALSE) -> 0 | BI7: =SUM(BB7:BH7) -> 1 | BJ7: =SUMPRODUCT($BB$1:$BH$1,BB7:BH7) -> 0.0697285 | BK7: =(1+BJ7)^(1/12)-1 -> 0.0056328785 | BL7: 0 | BM7: =IF(BL7=0,0,SUMPRODUCT($BB$3:$BH$3,BB7:BH7)) -> 0 | BN7: =(1+BM7)^(1/12)-1 -> 0 | BO7: =SUMPRODUCT($BB$2:$BH$2,BB7:BH7) -> 0.0056776 | BP7: =(1+BO7)^(1/12)-1 -> 0.00047190658
A8: Lifecycle | B8: Balanced | C8: =A8&"_"&B8&"_"&D8 -> Lifecycle_Balanced_537 | D8: 537 | E8: =VLOOKUP($D8,'[2]LC Balanced'!$Q$2:$U$542,2,FALSE) -> 0 | F8: =VLOOKUP($D8,'[2]LC Balanced'!$Q$2:$U$542,3,FALSE) -> 0.149 | G8: =VLOOKUP($D8,'[2]LC Balanced'!$Q$2:$U$542,4,FALSE) -> 0.851 | H8: =VLOOKUP($D8,'[2]LC Balanced'!$Q$2:$U$542,5,FALSE) -> 0 | I8: =SUM(E8:H8) -> 1 | J8: =SUMPRODUCT($E$1:$H$1,E8:H8) -> 0.0619877 | K8: =(1+J8)^(1/12)-1 -> 0.0050244421 | L8: 0 | M8: =IF($L8=0,0,SUMPRODUCT($E$3:$H$3,E8:H8)) -> 0 | N8: =1-(1-M8)^(1/12) -> 0 | O8: =SUMPRODUCT($E$2:$H$2,E8:H8) -> 0.0070063 | P8: =1-(1-O8)^(1/12) -> 0.00058574167 | R8: Autopilot | S8: Balanced | T8: =R8&"_"&S8&"_"&U8 -> Autopilot_Balanced_537 | U8: 537 | V8: =VLOOKUP($U8,'[2]AP Balanced'!$Q$1:$T$542,2,FALSE) -> 0.77777778 | W8: =VLOOKUP($U8,'[2]AP Balanced'!$Q$1:$T$542,3,FALSE) -> 0.22222222 | X8: =VLOOKUP($U8,'[2]AP Balanced'!$Q$1:$T$542,4,FALSE) -> 0 | Y8: =SUM(V8:X8) -> 1 | Z8: =SUMPRODUCT($V$1:$X$1,V8:X8) -> 0.061675 | AA8: =(1+Z8)^(1/12)-1 -> 0.0049997782 | AB8: 1 | AC8: =IF($AB8=0,0,SUMPRODUCT($V$3:$X$3,V8:X8)) -> 0.0080555556 | AD8: =1-(1-AC8)^(1/12) -> 0.00067378764 | AE8: =SUMPRODUCT($V$2:$X$2,V8:X8) -> 0.0025 | AF8: =1-(1-AE8)^(1/12) -> 0.00020857243 | AH8: Lifecycle | AI8: Balanced | AJ8: =AH8&"_"&AI8&"_"&AK8 -> Lifecycle_Balanced_537 | AK8: 537 | AL8: =VLOOKUP($U8,[2]Standard_Balanced!$Q$1:$T$542,2,FALSE) -> 0.77777778 | AM8: =VLOOKUP($U8,[2]Standard_Balanced!$Q$1:$T$542,3,FALSE) -> 0.22222222 | AN8: =VLOOKUP($U8,[2]Standard_Balanced!$Q$1:$T$542,4,FALSE) -> 0 | AO8: =SUM(AL8:AN8) -> 1 | AP8: =SUMPRODUCT($AL$1:$AN$1,AL8:AN8) -> 0.061675 | AQ8: =(1+AP8)^(1/12)-1 -> 0.0049997782 | AR8: 0 | AS8: =IF(AR8=0,0,SUMPRODUCT($AL$3:$AN$3,AL8:AN8)) -> 0 | AT8: =1-(1-AS8)^(1/12) -> 0 | AU8: =SUMPRODUCT($AL$2:$AN$2,AL8:AN8) -> 0.0025 | AV8: =1-(1-AU8)^(1/12) -> 0.00020857243 | AX8: DIS | AY8: Non-Standard | AZ8: =AX8&"_"&AY8&"_"&BA8 -> DIS_Non-Standard_537 | BA8: 537 | BB8: =VLOOKUP($BA8,'[2]NonStandard DIS'!$Q$1:$X$542,2,FALSE) -> 0 | BC8: =VLOOKUP($BA8,'[2]NonStandard DIS'!$Q$1:$X$542,3,FALSE) -> 0 | BD8: =VLOOKUP($BA8,'[2]NonStandard DIS'!$Q$1:$X$542,4,FALSE) -> 0.308 | BE8: =VLOOKUP($BA8,'[2]NonStandard DIS'!$Q$1:$X$542,5,FALSE) -> 0.692 | BF8: =VLOOKUP($BA8,'[2]NonStandard DIS'!$Q$1:$X$542,6,FALSE) -> 0 | BG8: =VLOOKUP($BA8,'[2]NonStandard DIS'!$Q$1:$X$542,7,FALSE) -> 0 | BH8: =VLOOKUP($BA8,'[2]NonStandard DIS'!$Q$1:$X$542,8,FALSE) -> 0 | BI8: =SUM(BB8:BH8) -> 1 | BJ8: =SUMPRODUCT($BB$1:$BH$1,BB8:BH8) -> 0.0697285 | BK8: =(1+BJ8)^(1/12)-1 -> 0.0056328785 | BL8: 0 | BM8: =IF(BL8=0,0,SUMPRODUCT($BB$3:$BH$3,BB8:BH8)) -> 0 | BN8: =(1+BM8)^(1/12)-1 -> 0 | BO8: =SUMPRODUCT($BB$2:$BH$2,BB8:BH8) -> 0.0056776 | BP8: =(1+BO8)^(1/12)-1 -> 0.00047190658
A9: Lifecycle | B9: Balanced | C9: =A9&"_"&B9&"_"&D9 -> Lifecycle_Balanced_536 | D9: 536 | E9: =VLOOKUP($D9,'[2]LC Balanced'!$Q$2:$U$542,2,FALSE) -> 0 | F9: =VLOOKUP($D9,'[2]LC Balanced'!$Q$2:$U$542,3,FALSE) -> 0.149 | G9: =VLOOKUP($D9,'[2]LC Balanced'!$Q$2:$U$542,4,FALSE) -> 0.851 | H9: =VLOOKUP($D9,'[2]LC Balanced'!$Q$2:$U$542,5,FALSE) -> 0 | I9: =SUM(E9:H9) -> 1 | J9: =SUMPRODUCT($E$1:$H$1,E9:H9) -> 0.0619877 | K9: =(1+J9)^(1/12)-1 -> 0.0050244421 | L9: 0 | M9: =IF($L9=0,0,SUMPRODUCT($E$3:$H$3,E9:H9)) -> 0 | N9: =1-(1-M9)^(1/12) -> 0 | O9: =SUMPRODUCT($E$2:$H$2,E9:H9) -> 0.0070063 | P9: =1-(1-O9)^(1/12) -> 0.00058574167 | R9: Autopilot | S9: Balanced | T9: =R9&"_"&S9&"_"&U9 -> Autopilot_Balanced_536 | U9: 536 | V9: =VLOOKUP($U9,'[2]AP Balanced'!$Q$1:$T$542,2,FALSE) -> 0.77777778 | W9: =VLOOKUP($U9,'[2]AP Balanced'!$Q$1:$T$542,3,FALSE) -> 0.22222222 | X9: =VLOOKUP($U9,'[2]AP Balanced'!$Q$1:$T$542,4,FALSE) -> 0 | Y9: =SUM(V9:X9) -> 1 | Z9: =SUMPRODUCT($V$1:$X$1,V9:X9) -> 0.061675 | AA9: =(1+Z9)^(1/12)-1 -> 0.0049997782 | AB9: 1 | AC9: =IF($AB9=0,0,SUMPRODUCT($V$3:$X$3,V9:X9)) -> 0.0080555556 | AD9: =1-(1-AC9)^(1/12) -> 0.00067378764 | AE9: =SUMPRODUCT($V$2:$X$2,V9:X9) -> 0.0025 | AF9: =1-(1-AE9)^(1/12) -> 0.00020857243 | AH9: Lifecycle | AI9: Balanced | AJ9: =AH9&"_"&AI9&"_"&AK9 -> Lifecycle_Balanced_536 | AK9: 536 | AL9: =VLOOKUP($U9,[2]Standard_Balanced!$Q$1:$T$542,2,FALSE) -> 0.77777778 | AM9: =VLOOKUP($U9,[2]Standard_Balanced!$Q$1:$T$542,3,FALSE) -> 0.22222222 | AN9: =VLOOKUP($U9,[2]Standard_Balanced!$Q$1:$T$542,4,FALSE) -> 0 | AO9: =SUM(AL9:AN9) -> 1 | AP9: =SUMPRODUCT($AL$1:$AN$1,AL9:AN9) -> 0.061675 | AQ9: =(1+AP9)^(1/12)-1 -> 0.0049997782 | AR9: 0 | AS9: =IF(AR9=0,0,SUMPRODUCT($AL$3:$AN$3,AL9:AN9)) -> 0 | AT9: =1-(1-AS9)^(1/12) -> 0 | AU9: =SUMPRODUCT($AL$2:$AN$2,AL9:AN9) -> 0.0025 | AV9: =1-(1-AU9)^(1/12) -> 0.00020857243 | AX9: DIS | AY9: Non-Standard | AZ9: =AX9&"_"&AY9&"_"&BA9 -> DIS_Non-Standard_536 | BA9: 536 | BB9: =VLOOKUP($BA9,'[2]NonStandard DIS'!$Q$1:$X$542,2,FALSE) -> 0 | BC9: =VLOOKUP($BA9,'[2]NonStandard DIS'!$Q$1:$X$542,3,FALSE) -> 0 | BD9: =VLOOKUP($BA9,'[2]NonStandard DIS'!$Q$1:$X$542,4,FALSE) -> 0.308 | BE9: =VLOOKUP($BA9,'[2]NonStandard DIS'!$Q$1:$X$542,5,FALSE) -> 0.692 | BF9: =VLOOKUP($BA9,'[2]NonStandard DIS'!$Q$1:$X$542,6,FALSE) -> 0 | BG9: =VLOOKUP($BA9,'[2]NonStandard DIS'!$Q$1:$X$542,7,FALSE) -> 0 | BH9: =VLOOKUP($BA9,'[2]NonStandard DIS'!$Q$1:$X$542,8,FALSE) -> 0 | BI9: =SUM(BB9:BH9) -> 1 | BJ9: =SUMPRODUCT($BB$1:$BH$1,BB9:BH9) -> 0.0697285 | BK9: =(1+BJ9)^(1/12)-1 -> 0.0056328785 | BL9: 0 | BM9: =IF(BL9=0,0,SUMPRODUCT($BB$3:$BH$3,BB9:BH9)) -> 0 | BN9: =(1+BM9)^(1/12)-1 -> 0 | BO9: =SUMPRODUCT($BB$2:$BH$2,BB9:BH9) -> 0.0056776 | BP9: =(1+BO9)^(1/12)-1 -> 0.00047190658
A10: Lifecycle | B10: Balanced | C10: =A10&"_"&B10&"_"&D10 -> Lifecycle_Balanced_535 | D10: 535 | E10: =VLOOKUP($D10,'[2]LC Balanced'!$Q$2:$U$542,2,FALSE) -> 0 | F10: =VLOOKUP($D10,'[2]LC Balanced'!$Q$2:$U$542,3,FALSE) -> 0.149 | G10: =VLOOKUP($D10,'[2]LC Balanced'!$Q$2:$U$542,4,FALSE) -> 0.851 | H10: =VLOOKUP($D10,'[2]LC Balanced'!$Q$2:$U$542,5,FALSE) -> 0 | I10: =SUM(E10:H10) -> 1 | J10: =SUMPRODUCT($E$1:$H$1,E10:H10) -> 0.0619877 | K10: =(1+J10)^(1/12)-1 -> 0.0050244421 | L10: 0 | M10: =IF($L10=0,0,SUMPRODUCT($E$3:$H$3,E10:H10)) -> 0 | N10: =1-(1-M10)^(1/12) -> 0 | O10: =SUMPRODUCT($E$2:$H$2,E10:H10) -> 0.0070063 | P10: =1-(1-O10)^(1/12) -> 0.00058574167 | R10: Autopilot | S10: Balanced | T10: =R10&"_"&S10&"_"&U10 -> Autopilot_Balanced_535 | U10: 535 | V10: =VLOOKUP($U10,'[2]AP Balanced'!$Q$1:$T$542,2,FALSE) -> 0.77777778 | W10: =VLOOKUP($U10,'[2]AP Balanced'!$Q$1:$T$542,3,FALSE) -> 0.22222222 | X10: =VLOOKUP($U10,'[2]AP Balanced'!$Q$1:$T$542,4,FALSE) -> 0 | Y10: =SUM(V10:X10) -> 1 | Z10: =SUMPRODUCT($V$1:$X$1,V10:X10) -> 0.061675 | AA10: =(1+Z10)^(1/12)-1 -> 0.0049997782 | AB10: 1 | AC10: =IF($AB10=0,0,SUMPRODUCT($V$3:$X$3,V10:X10)) -> 0.0080555556 | AD10: =1-(1-AC10)^(1/12) -> 0.00067378764 | AE10: =SUMPRODUCT($V$2:$X$2,V10:X10) -> 0.0025 | AF10: =1-(1-AE10)^(1/12) -> 0.00020857243 | AH10: Lifecycle | AI10: Balanced | AJ10: =AH10&"_"&AI10&"_"&AK10 -> Lifecycle_Balanced_535 | AK10: 535 | AL10: =VLOOKUP($U10,[2]Standard_Balanced!$Q$1:$T$542,2,FALSE) -> 0.77777778 | AM10: =VLOOKUP($U10,[2]Standard_Balanced!$Q$1:$T$542,3,FALSE) -> 0.22222222 | AN10: =VLOOKUP($U10,[2]Standard_Balanced!$Q$1:$T$542,4,FALSE) -> 0 | AO10: =SUM(AL10:AN10) -> 1 | AP10: =SUMPRODUCT($AL$1:$AN$1,AL10:AN10) -> 0.061675 | AQ10: =(1+AP10)^(1/12)-1 -> 0.0049997782 | AR10: 0 | AS10: =IF(AR10=0,0,SUMPRODUCT($AL$3:$AN$3,AL10:AN10)) -> 0 | AT10: =1-(1-AS10)^(1/12) -> 0 | AU10: =SUMPRODUCT($AL$2:$AN$2,AL10:AN10) -> 0.0025 | AV10: =1-(1-AU10)^(1/12) -> 0.00020857243 | AX10: DIS | AY10: Non-Standard | AZ10: =AX10&"_"&AY10&"_"&BA10 -> DIS_Non-Standard_535 | BA10: 535 | BB10: =VLOOKUP($BA10,'[2]NonStandard DIS'!$Q$1:$X$542,2,FALSE) -> 0 | BC10: =VLOOKUP($BA10,'[2]NonStandard DIS'!$Q$1:$X$542,3,FALSE) -> 0 | BD10: =VLOOKUP($BA10,'[2]NonStandard DIS'!$Q$1:$X$542,4,FALSE) -> 0.308 | BE10: =VLOOKUP($BA10,'[2]NonStandard DIS'!$Q$1:$X$542,5,FALSE) -> 0.692 | BF10: =VLOOKUP($BA10,'[2]NonStandard DIS'!$Q$1:$X$542,6,FALSE) -> 0 | BG10: =VLOOKUP($BA10,'[2]NonStandard DIS'!$Q$1:$X$542,7,FALSE) -> 0 | BH10: =VLOOKUP($BA10,'[2]NonStandard DIS'!$Q$1:$X$542,8,FALSE) -> 0 | BI10: =SUM(BB10:BH10) -> 1 | BJ10: =SUMPRODUCT($BB$1:$BH$1,BB10:BH10) -> 0.0697285 | BK10: =(1+BJ10)^(1/12)-1 -> 0.0056328785 | BL10: 0 | BM10: =IF(BL10=0,0,SUMPRODUCT($BB$3:$BH$3,BB10:BH10)) -> 0 | BN10: =(1+BM10)^(1/12)-1 -> 0 | BO10: =SUMPRODUCT($BB$2:$BH$2,BB10:BH10) -> 0.0056776 | BP10: =(1+BO10)^(1/12)-1 -> 0.00047190658
A11: Lifecycle | B11: Balanced | C11: =A11&"_"&B11&"_"&D11 -> Lifecycle_Balanced_534 | D11: 534 | E11: =VLOOKUP($D11,'[2]LC Balanced'!$Q$2:$U$542,2,FALSE) -> 0 | F11: =VLOOKUP($D11,'[2]LC Balanced'!$Q$2:$U$542,3,FALSE) -> 0.149 | G11: =VLOOKUP($D11,'[2]LC Balanced'!$Q$2:$U$542,4,FALSE) -> 0.851 | H11: =VLOOKUP($D11,'[2]LC Balanced'!$Q$2:$U$542,5,FALSE) -> 0 | I11: =SUM(E11:H11) -> 1 | J11: =SUMPRODUCT($E$1:$H$1,E11:H11) -> 0.0619877 | K11: =(1+J11)^(1/12)-1 -> 0.0050244421 | L11: 0 | M11: =IF($L11=0,0,SUMPRODUCT($E$3:$H$3,E11:H11)) -> 0 | N11: =1-(1-M11)^(1/12) -> 0 | O11: =SUMPRODUCT($E$2:$H$2,E11:H11) -> 0.0070063 | P11: =1-(1-O11)^(1/12) -> 0.00058574167 | R11: Autopilot | S11: Balanced | T11: =R11&"_"&S11&"_"&U11 -> Autopilot_Balanced_534 | U11: 534 | V11: =VLOOKUP($U11,'[2]AP Balanced'!$Q$1:$T$542,2,FALSE) -> 0.77777778 | W11: =VLOOKUP($U11,'[2]AP Balanced'!$Q$1:$T$542,3,FALSE) -> 0.22222222 | X11: =VLOOKUP($U11,'[2]AP Balanced'!$Q$1:$T$542,4,FALSE) -> 0 | Y11: =SUM(V11:X11) -> 1 | Z11: =SUMPRODUCT($V$1:$X$1,V11:X11) -> 0.061675 | AA11: =(1+Z11)^(1/12)-1 -> 0.0049997782 | AB11: 1 | AC11: =IF($AB11=0,0,SUMPRODUCT($V$3:$X$3,V11:X11)) -> 0.0080555556 | AD11: =1-(1-AC11)^(1/12) -> 0.00067378764 | AE11: =SUMPRODUCT($V$2:$X$2,V11:X11) -> 0.0025 | AF11: =1-(1-AE11)^(1/12) -> 0.00020857243 | AH11: Lifecycle | AI11: Balanced | AJ11: =AH11&"_"&AI11&"_"&AK11 -> Lifecycle_Balanced_534 | AK11: 534 | AL11: =VLOOKUP($U11,[2]Standard_Balanced!$Q$1:$T$542,2,FALSE) -> 0.77777778 | AM11: =VLOOKUP($U11,[2]Standard_Balanced!$Q$1:$T$542,3,FALSE) -> 0.22222222 | AN11: =VLOOKUP($U11,[2]Standard_Balanced!$Q$1:$T$542,4,FALSE) -> 0 | AO11: =SUM(AL11:AN11) -> 1 | AP11: =SUMPRODUCT($AL$1:$AN$1,AL11:AN11) -> 0.061675 | AQ11: =(1+AP11)^(1/12)-1 -> 0.0049997782 | AR11: 0 | AS11: =IF(AR11=0,0,SUMPRODUCT($AL$3:$AN$3,AL11:AN11)) -> 0 | AT11: =1-(1-AS11)^(1/12) -> 0 | AU11: =SUMPRODUCT($AL$2:$AN$2,AL11:AN11) -> 0.0025 | AV11: =1-(1-AU11)^(1/12) -> 0.00020857243 | AX11: DIS | AY11: Non-Standard | AZ11: =AX11&"_"&AY11&"_"&BA11 -> DIS_Non-Standard_534 | BA11: 534 | BB11: =VLOOKUP($BA11,'[2]NonStandard DIS'!$Q$1:$X$542,2,FALSE) -> 0 | BC11: =VLOOKUP($BA11,'[2]NonStandard DIS'!$Q$1:$X$542,3,FALSE) -> 0 | BD11: =VLOOKUP($BA11,'[2]NonStandard DIS'!$Q$1:$X$542,4,FALSE) -> 0.308 | BE11: =VLOOKUP($BA11,'[2]NonStandard DIS'!$Q$1:$X$542,5,FALSE) -> 0.692 | BF11: =VLOOKUP($BA11,'[2]NonStandard DIS'!$Q$1:$X$542,6,FALSE) -> 0 | BG11: =VLOOKUP($BA11,'[2]NonStandard DIS'!$Q$1:$X$542,7,FALSE) -> 0 | BH11: =VLOOKUP($BA11,'[2]NonStandard DIS'!$Q$1:$X$542,8,FALSE) -> 0 | BI11: =SUM(BB11:BH11) -> 1 | BJ11: =SUMPRODUCT($BB$1:$BH$1,BB11:BH11) -> 0.0697285 | BK11: =(1+BJ11)^(1/12)-1 -> 0.0056328785 | BL11: 0 | BM11: =IF(BL11=0,0,SUMPRODUCT($BB$3:$BH$3,BB11:BH11)) -> 0 | BN11: =(1+BM11)^(1/12)-1 -> 0 | BO11: =SUMPRODUCT($BB$2:$BH$2,BB11:BH11) -> 0.0056776 | BP11: =(1+BO11)^(1/12)-1 -> 0.00047190658
A12: Lifecycle | B12: Balanced | C12: =A12&"_"&B12&"_"&D12 -> Lifecycle_Balanced_533 | D12: 533 | E12: =VLOOKUP($D12,'[2]LC Balanced'!$Q$2:$U$542,2,FALSE) -> 0 | F12: =VLOOKUP($D12,'[2]LC Balanced'!$Q$2:$U$542,3,FALSE) -> 0.149 | G12: =VLOOKUP($D12,'[2]LC Balanced'!$Q$2:$U$542,4,FALSE) -> 0.851 | H12: =VLOOKUP($D12,'[2]LC Balanced'!$Q$2:$U$542,5,FALSE) -> 0 | I12: =SUM(E12:H12) -> 1 | J12: =SUMPRODUCT($E$1:$H$1,E12:H12) -> 0.0619877 | K12: =(1+J12)^(1/12)-1 -> 0.0050244421 | L12: 0 | M12: =IF($L12=0,0,SUMPRODUCT($E$3:$H$3,E12:H12)) -> 0 | N12: =1-(1-M12)^(1/12) -> 0 | O12: =SUMPRODUCT($E$2:$H$2,E12:H12) -> 0.0070063 | P12: =1-(1-O12)^(1/12) -> 0.00058574167 | R12: Autopilot | S12: Balanced | T12: =R12&"_"&S12&"_"&U12 -> Autopilot_Balanced_533 | U12: 533 | V12: =VLOOKUP($U12,'[2]AP Balanced'!$Q$1:$T$542,2,FALSE) -> 0.77777778 | W12: =VLOOKUP($U12,'[2]AP Balanced'!$Q$1:$T$542,3,FALSE) -> 0.22222222 | X12: =VLOOKUP($U12,'[2]AP Balanced'!$Q$1:$T$542,4,FALSE) -> 0 | Y12: =SUM(V12:X12) -> 1 | Z12: =SUMPRODUCT($V$1:$X$1,V12:X12) -> 0.061675 | AA12: =(1+Z12)^(1/12)-1 -> 0.0049997782 | AB12: 1 | AC12: =IF($AB12=0,0,SUMPRODUCT($V$3:$X$3,V12:X12)) -> 0.0080555556 | AD12: =1-(1-AC12)^(1/12) -> 0.00067378764 | AE12: =SUMPRODUCT($V$2:$X$2,V12:X12) -> 0.0025 | AF12: =1-(1-AE12)^(1/12) -> 0.00020857243 | AH12: Lifecycle | AI12: Balanced | AJ12: =AH12&"_"&AI12&"_"&AK12 -> Lifecycle_Balanced_533 | AK12: 533 | AL12: =VLOOKUP($U12,[2]Standard_Balanced!$Q$1:$T$542,2,FALSE) -> 0.77777778 | AM12: =VLOOKUP($U12,[2]Standard_Balanced!$Q$1:$T$542,3,FALSE) -> 0.22222222 | AN12: =VLOOKUP($U12,[2]Standard_Balanced!$Q$1:$T$542,4,FALSE) -> 0 | AO12: =SUM(AL12:AN12) -> 1 | AP12: =SUMPRODUCT($AL$1:$AN$1,AL12:AN12) -> 0.061675 | AQ12: =(1+AP12)^(1/12)-1 -> 0.0049997782 | AR12: 0 | AS12: =IF(AR12=0,0,SUMPRODUCT($AL$3:$AN$3,AL12:AN12)) -> 0 | AT12: =1-(1-AS12)^(1/12) -> 0 | AU12: =SUMPRODUCT($AL$2:$AN$2,AL12:AN12) -> 0.0025 | AV12: =1-(1-AU12)^(1/12) -> 0.00020857243 | AX12: DIS | AY12: Non-Standard | AZ12: =AX12&"_"&AY12&"_"&BA12 -> DIS_Non-Standard_533 | BA12: 533 | BB12: =VLOOKUP($BA12,'[2]NonStandard DIS'!$Q$1:$X$542,2,FALSE) -> 0 | BC12: =VLOOKUP($BA12,'[2]NonStandard DIS'!$Q$1:$X$542,3,FALSE) -> 0 | BD12: =VLOOKUP($BA12,'[2]NonStandard DIS'!$Q$1:$X$542,4,FALSE) -> 0.308 | BE12: =VLOOKUP($BA12,'[2]NonStandard DIS'!$Q$1:$X$542,5,FALSE) -> 0.692 | BF12: =VLOOKUP($BA12,'[2]NonStandard DIS'!$Q$1:$X$542,6,FALSE) -> 0 | BG12: =VLOOKUP($BA12,'[2]NonStandard DIS'!$Q$1:$X$542,7,FALSE) -> 0 | BH12: =VLOOKUP($BA12,'[2]NonStandard DIS'!$Q$1:$X$542,8,FALSE) -> 0 | BI12: =SUM(BB12:BH12) -> 1 | BJ12: =SUMPRODUCT($BB$1:$BH$1,BB12:BH12) -> 0.0697285 | BK12: =(1+BJ12)^(1/12)-1 -> 0.0056328785 | BL12: 0 | BM12: =IF(BL12=0,0,SUMPRODUCT($BB$3:$BH$3,BB12:BH12)) -> 0 | BN12: =(1+BM12)^(1/12)-1 -> 0 | BO12: =SUMPRODUCT($BB$2:$BH$2,BB12:BH12) -> 0.0056776 | BP12: =(1+BO12)^(1/12)-1 -> 0.00047190658
A13: Lifecycle | B13: Balanced | C13: =A13&"_"&B13&"_"&D13 -> Lifecycle_Balanced_532 | D13: 532 | E13: =VLOOKUP($D13,'[2]LC Balanced'!$Q$2:$U$542,2,FALSE) -> 0 | F13: =VLOOKUP($D13,'[2]LC Balanced'!$Q$2:$U$542,3,FALSE) -> 0.149 | G13: =VLOOKUP($D13,'[2]LC Balanced'!$Q$2:$U$542,4,FALSE) -> 0.851 | H13: =VLOOKUP($D13,'[2]LC Balanced'!$Q$2:$U$542,5,FALSE) -> 0 | I13: =SUM(E13:H13) -> 1 | J13: =SUMPRODUCT($E$1:$H$1,E13:H13) -> 0.0619877 | K13: =(1+J13)^(1/12)-1 -> 0.0050244421 | L13: 0 | M13: =IF($L13=0,0,SUMPRODUCT($E$3:$H$3,E13:H13)) -> 0 | N13: =1-(1-M13)^(1/12) -> 0 | O13: =SUMPRODUCT($E$2:$H$2,E13:H13) -> 0.0070063 | P13: =1-(1-O13)^(1/12) -> 0.00058574167 | R13: Autopilot | S13: Balanced | T13: =R13&"_"&S13&"_"&U13 -> Autopilot_Balanced_532 | U13: 532 | V13: =VLOOKUP($U13,'[2]AP Balanced'!$Q$1:$T$542,2,FALSE) -> 0.77777778 | W13: =VLOOKUP($U13,'[2]AP Balanced'!$Q$1:$T$542,3,FALSE) -> 0.22222222 | X13: =VLOOKUP($U13,'[2]AP Balanced'!$Q$1:$T$542,4,FALSE) -> 0 | Y13: =SUM(V13:X13) -> 1 | Z13: =SUMPRODUCT($V$1:$X$1,V13:X13) -> 0.061675 | AA13: =(1+Z13)^(1/12)-1 -> 0.0049997782 | AB13: 1 | AC13: =IF($AB13=0,0,SUMPRODUCT($V$3:$X$3,V13:X13)) -> 0.0080555556 | AD13: =1-(1-AC13)^(1/12) -> 0.00067378764 | AE13: =SUMPRODUCT($V$2:$X$2,V13:X13) -> 0.0025 | AF13: =1-(1-AE13)^(1/12) -> 0.00020857243 | AH13: Lifecycle | AI13: Balanced | AJ13: =AH13&"_"&AI13&"_"&AK13 -> Lifecycle_Balanced_532 | AK13: 532 | AL13: =VLOOKUP($U13,[2]Standard_Balanced!$Q$1:$T$542,2,FALSE) -> 0.77777778 | AM13: =VLOOKUP($U13,[2]Standard_Balanced!$Q$1:$T$542,3,FALSE) -> 0.22222222 | AN13: =VLOOKUP($U13,[2]Standard_Balanced!$Q$1:$T$542,4,FALSE) -> 0 | AO13: =SUM(AL13:AN13) -> 1 | AP13: =SUMPRODUCT($AL$1:$AN$1,AL13:AN13) -> 0.061675 | AQ13: =(1+AP13)^(1/12)-1 -> 0.0049997782 | AR13: 0 | AS13: =IF(AR13=0,0,SUMPRODUCT($AL$3:$AN$3,AL13:AN13)) -> 0 | AT13: =1-(1-AS13)^(1/12) -> 0 | AU13: =SUMPRODUCT($AL$2:$AN$2,AL13:AN13) -> 0.0025 | AV13: =1-(1-AU13)^(1/12) -> 0.00020857243 | AX13: DIS | AY13: Non-Standard | AZ13: =AX13&"_"&AY13&"_"&BA13 -> DIS_Non-Standard_532 | BA13: 532 | BB13: =VLOOKUP($BA13,'[2]NonStandard DIS'!$Q$1:$X$542,2,FALSE) -> 0 | BC13: =VLOOKUP($BA13,'[2]NonStandard DIS'!$Q$1:$X$542,3,FALSE) -> 0 | BD13: =VLOOKUP($BA13,'[2]NonStandard DIS'!$Q$1:$X$542,4,FALSE) -> 0.308 | BE13: =VLOOKUP($BA13,'[2]NonStandard DIS'!$Q$1:$X$542,5,FALSE) -> 0.692 | BF13: =VLOOKUP($BA13,'[2]NonStandard DIS'!$Q$1:$X$542,6,FALSE) -> 0 | BG13: =VLOOKUP($BA13,'[2]NonStandard DIS'!$Q$1:$X$542,7,FALSE) -> 0 | BH13: =VLOOKUP($BA13,'[2]NonStandard DIS'!$Q$1:$X$542,8,FALSE) -> 0 | BI13: =SUM(BB13:BH13) -> 1 | BJ13: =SUMPRODUCT($BB$1:$BH$1,BB13:BH13) -> 0.0697285 | BK13: =(1+BJ13)^(1/12)-1 -> 0.0056328785 | BL13: 0 | BM13: =IF(BL13=0,0,SUMPRODUCT($BB$3:$BH$3,BB13:BH13)) -> 0 | BN13: =(1+BM13)^(1/12)-1 -> 0 | BO13: =SUMPRODUCT($BB$2:$BH$2,BB13:BH13) -> 0.0056776 | BP13: =(1+BO13)^(1/12)-1 -> 0.00047190658
A14: Lifecycle | B14: Balanced | C14: =A14&"_"&B14&"_"&D14 -> Lifecycle_Balanced_531 | D14: 531 | E14: =VLOOKUP($D14,'[2]LC Balanced'!$Q$2:$U$542,2,FALSE) -> 0 | F14: =VLOOKUP($D14,'[2]LC Balanced'!$Q$2:$U$542,3,FALSE) -> 0.149 | G14: =VLOOKUP($D14,'[2]LC Balanced'!$Q$2:$U$542,4,FALSE) -> 0.851 | H14: =VLOOKUP($D14,'[2]LC Balanced'!$Q$2:$U$542,5,FALSE) -> 0 | I14: =SUM(E14:H14) -> 1 | J14: =SUMPRODUCT($E$1:$H$1,E14:H14) -> 0.0619877 | K14: =(1+J14)^(1/12)-1 -> 0.0050244421 | L14: 0 | M14: =IF($L14=0,0,SUMPRODUCT($E$3:$H$3,E14:H14)) -> 0 | N14: =1-(1-M14)^(1/12) -> 0 | O14: =SUMPRODUCT($E$2:$H$2,E14:H14) -> 0.0070063 | P14: =1-(1-O14)^(1/12) -> 0.00058574167 | R14: Autopilot | S14: Balanced | T14: =R14&"_"&S14&"_"&U14 -> Autopilot_Balanced_531 | U14: 531 | V14: =VLOOKUP($U14,'[2]AP Balanced'!$Q$1:$T$542,2,FALSE) -> 0.77777778 | W14: =VLOOKUP($U14,'[2]AP Balanced'!$Q$1:$T$542,3,FALSE) -> 0.22222222 | X14: =VLOOKUP($U14,'[2]AP Balanced'!$Q$1:$T$542,4,FALSE) -> 0 | Y14: =SUM(V14:X14) -> 1 | Z14: =SUMPRODUCT($V$1:$X$1,V14:X14) -> 0.061675 | AA14: =(1+Z14)^(1/12)-1 -> 0.0049997782 | AB14: 1 | AC14: =IF($AB14=0,0,SUMPRODUCT($V$3:$X$3,V14:X14)) -> 0.0080555556 | AD14: =1-(1-AC14)^(1/12) -> 0.00067378764 | AE14: =SUMPRODUCT($V$2:$X$2,V14:X14) -> 0.0025 | AF14: =1-(1-AE14)^(1/12) -> 0.00020857243 | AH14: Lifecycle | AI14: Balanced | AJ14: =AH14&"_"&AI14&"_"&AK14 -> Lifecycle_Balanced_531 | AK14: 531 | AL14: =VLOOKUP($U14,[2]Standard_Balanced!$Q$1:$T$542,2,FALSE) -> 0.77777778 | AM14: =VLOOKUP($U14,[2]Standard_Balanced!$Q$1:$T$542,3,FALSE) -> 0.22222222 | AN14: =VLOOKUP($U14,[2]Standard_Balanced!$Q$1:$T$542,4,FALSE) -> 0 | AO14: =SUM(AL14:AN14) -> 1 | AP14: =SUMPRODUCT($AL$1:$AN$1,AL14:AN14) -> 0.061675 | AQ14: =(1+AP14)^(1/12)-1 -> 0.0049997782 | AR14: 0 | AS14: =IF(AR14=0,0,SUMPRODUCT($AL$3:$AN$3,AL14:AN14)) -> 0 | AT14: =1-(1-AS14)^(1/12) -> 0 | AU14: =SUMPRODUCT($AL$2:$AN$2,AL14:AN14) -> 0.0025 | AV14: =1-(1-AU14)^(1/12) -> 0.00020857243 | AX14: DIS | AY14: Non-Standard | AZ14: =AX14&"_"&AY14&"_"&BA14 -> DIS_Non-Standard_531 | BA14: 531 | BB14: =VLOOKUP($BA14,'[2]NonStandard DIS'!$Q$1:$X$542,2,FALSE) -> 0 | BC14: =VLOOKUP($BA14,'[2]NonStandard DIS'!$Q$1:$X$542,3,FALSE) -> 0 | BD14: =VLOOKUP($BA14,'[2]NonStandard DIS'!$Q$1:$X$542,4,FALSE) -> 0.308 | BE14: =VLOOKUP($BA14,'[2]NonStandard DIS'!$Q$1:$X$542,5,FALSE) -> 0.692 | BF14: =VLOOKUP($BA14,'[2]NonStandard DIS'!$Q$1:$X$542,6,FALSE) -> 0 | BG14: =VLOOKUP($BA14,'[2]NonStandard DIS'!$Q$1:$X$542,7,FALSE) -> 0 | BH14: =VLOOKUP($BA14,'[2]NonStandard DIS'!$Q$1:$X$542,8,FALSE) -> 0 | BI14: =SUM(BB14:BH14) -> 1 | BJ14: =SUMPRODUCT($BB$1:$BH$1,BB14:BH14) -> 0.0697285 | BK14: =(1+BJ14)^(1/12)-1 -> 0.0056328785 | BL14: 0 | BM14: =IF(BL14=0,0,SUMPRODUCT($BB$3:$BH$3,BB14:BH14)) -> 0 | BN14: =(1+BM14)^(1/12)-1 -> 0 | BO14: =SUMPRODUCT($BB$2:$BH$2,BB14:BH14) -> 0.0056776 | BP14: =(1+BO14)^(1/12)-1 -> 0.00047190658
A15: Lifecycle | B15: Balanced | C15: =A15&"_"&B15&"_"&D15 -> Lifecycle_Balanced_530 | D15: 530 | E15: =VLOOKUP($D15,'[2]LC Balanced'!$Q$2:$U$542,2,FALSE) -> 0 | F15: =VLOOKUP($D15,'[2]LC Balanced'!$Q$2:$U$542,3,FALSE) -> 0.149 | G15: =VLOOKUP($D15,'[2]LC Balanced'!$Q$2:$U$542,4,FALSE) -> 0.851 | H15: =VLOOKUP($D15,'[2]LC Balanced'!$Q$2:$U$542,5,FALSE) -> 0 | I15: =SUM(E15:H15) -> 1 | J15: =SUMPRODUCT($E$1:$H$1,E15:H15) -> 0.0619877 | K15: =(1+J15)^(1/12)-1 -> 0.0050244421 | L15: 0 | M15: =IF($L15=0,0,SUMPRODUCT($E$3:$H$3,E15:H15)) -> 0 | N15: =1-(1-M15)^(1/12) -> 0 | O15: =SUMPRODUCT($E$2:$H$2,E15:H15) -> 0.0070063 | P15: =1-(1-O15)^(1/12) -> 0.00058574167 | R15: Autopilot | S15: Balanced | T15: =R15&"_"&S15&"_"&U15 -> Autopilot_Balanced_530 | U15: 530 | V15: =VLOOKUP($U15,'[2]AP Balanced'!$Q$1:$T$542,2,FALSE) -> 0.77777778 | W15: =VLOOKUP($U15,'[2]AP Balanced'!$Q$1:$T$542,3,FALSE) -> 0.22222222 | X15: =VLOOKUP($U15,'[2]AP Balanced'!$Q$1:$T$542,4,FALSE) -> 0 | Y15: =SUM(V15:X15) -> 1 | Z15: =SUMPRODUCT($V$1:$X$1,V15:X15) -> 0.061675 | AA15: =(1+Z15)^(1/12)-1 -> 0.0049997782 | AB15: 1 | AC15: =IF($AB15=0,0,SUMPRODUCT($V$3:$X$3,V15:X15)) -> 0.0080555556 | AD15: =1-(1-AC15)^(1/12) -> 0.00067378764 | AE15: =SUMPRODUCT($V$2:$X$2,V15:X15) -> 0.0025 | AF15: =1-(1-AE15)^(1/12) -> 0.00020857243 | AH15: Lifecycle | AI15: Balanced | AJ15: =AH15&"_"&AI15&"_"&AK15 -> Lifecycle_Balanced_530 | AK15: 530 | AL15: =VLOOKUP($U15,[2]Standard_Balanced!$Q$1:$T$542,2,FALSE) -> 0.77777778 | AM15: =VLOOKUP($U15,[2]Standard_Balanced!$Q$1:$T$542,3,FALSE) -> 0.22222222 | AN15: =VLOOKUP($U15,[2]Standard_Balanced!$Q$1:$T$542,4,FALSE) -> 0 | AO15: =SUM(AL15:AN15) -> 1 | AP15: =SUMPRODUCT($AL$1:$AN$1,AL15:AN15) -> 0.061675 | AQ15: =(1+AP15)^(1/12)-1 -> 0.0049997782 | AR15: 0 | AS15: =IF(AR15=0,0,SUMPRODUCT($AL$3:$AN$3,AL15:AN15)) -> 0 | AT15: =1-(1-AS15)^(1/12) -> 0 | AU15: =SUMPRODUCT($AL$2:$AN$2,AL15:AN15) -> 0.0025 | AV15: =1-(1-AU15)^(1/12) -> 0.00020857243 | AX15: DIS | AY15: Non-Standard | AZ15: =AX15&"_"&AY15&"_"&BA15 -> DIS_Non-Standard_530 | BA15: 530 | BB15: =VLOOKUP($BA15,'[2]NonStandard DIS'!$Q$1:$X$542,2,FALSE) -> 0 | BC15: =VLOOKUP($BA15,'[2]NonStandard DIS'!$Q$1:$X$542,3,FALSE) -> 0 | BD15: =VLOOKUP($BA15,'[2]NonStandard DIS'!$Q$1:$X$542,4,FALSE) -> 0.308 | BE15: =VLOOKUP($BA15,'[2]NonStandard DIS'!$Q$1:$X$542,5,FALSE) -> 0.692 | BF15: =VLOOKUP($BA15,'[2]NonStandard DIS'!$Q$1:$X$542,6,FALSE) -> 0 | BG15: =VLOOKUP($BA15,'[2]NonStandard DIS'!$Q$1:$X$542,7,FALSE) -> 0 | BH15: =VLOOKUP($BA15,'[2]NonStandard DIS'!$Q$1:$X$542,8,FALSE) -> 0 | BI15: =SUM(BB15:BH15) -> 1 | BJ15: =SUMPRODUCT($BB$1:$BH$1,BB15:BH15) -> 0.0697285 | BK15: =(1+BJ15)^(1/12)-1 -> 0.0056328785 | BL15: 0 | BM15: =IF(BL15=0,0,SUMPRODUCT($BB$3:$BH$3,BB15:BH15)) -> 0 | BN15: =(1+BM15)^(1/12)-1 -> 0 | BO15: =SUMPRODUCT($BB$2:$BH$2,BB15:BH15) -> 0.0056776 | BP15: =(1+BO15)^(1/12)-1 -> 0.00047190658
A16: Lifecycle | B16: Balanced | C16: =A16&"_"&B16&"_"&D16 -> Lifecycle_Balanced_529 | D16: 529 | E16: =VLOOKUP($D16,'[2]LC Balanced'!$Q$2:$U$542,2,FALSE) -> 0 | F16: =VLOOKUP($D16,'[2]LC Balanced'!$Q$2:$U$542,3,FALSE) -> 0.149 | G16: =VLOOKUP($D16,'[2]LC Balanced'!$Q$2:$U$542,4,FALSE) -> 0.851 | H16: =VLOOKUP($D16,'[2]LC Balanced'!$Q$2:$U$542,5,FALSE) -> 0 | I16: =SUM(E16:H16) -> 1 | J16: =SUMPRODUCT($E$1:$H$1,E16:H16) -> 0.0619877 | K16: =(1+J16)^(1/12)-1 -> 0.0050244421 | L16: 0 | M16: =IF($L16=0,0,SUMPRODUCT($E$3:$H$3,E16:H16)) -> 0 | N16: =1-(1-M16)^(1/12) -> 0 | O16: =SUMPRODUCT($E$2:$H$2,E16:H16) -> 0.0070063 | P16: =1-(1-O16)^(1/12) -> 0.00058574167 | R16: Autopilot | S16: Balanced | T16: =R16&"_"&S16&"_"&U16 -> Autopilot_Balanced_529 | U16: 529 | V16: =VLOOKUP($U16,'[2]AP Balanced'!$Q$1:$T$542,2,FALSE) -> 0.77777778 | W16: =VLOOKUP($U16,'[2]AP Balanced'!$Q$1:$T$542,3,FALSE) -> 0.22222222 | X16: =VLOOKUP($U16,'[2]AP Balanced'!$Q$1:$T$542,4,FALSE) -> 0 | Y16: =SUM(V16:X16) -> 1 | Z16: =SUMPRODUCT($V$1:$X$1,V16:X16) -> 0.061675 | AA16: =(1+Z16)^(1/12)-1 -> 0.0049997782 | AB16: 1 | AC16: =IF($AB16=0,0,SUMPRODUCT($V$3:$X$3,V16:X16)) -> 0.0080555556 | AD16: =1-(1-AC16)^(1/12) -> 0.00067378764 | AE16: =SUMPRODUCT($V$2:$X$2,V16:X16) -> 0.0025 | AF16: =1-(1-AE16)^(1/12) -> 0.00020857243 | AH16: Lifecycle | AI16: Balanced | AJ16: =AH16&"_"&AI16&"_"&AK16 -> Lifecycle_Balanced_529 | AK16: 529 | AL16: =VLOOKUP($U16,[2]Standard_Balanced!$Q$1:$T$542,2,FALSE) -> 0.77777778 | AM16: =VLOOKUP($U16,[2]Standard_Balanced!$Q$1:$T$542,3,FALSE) -> 0.22222222 | AN16: =VLOOKUP($U16,[2]Standard_Balanced!$Q$1:$T$542,4,FALSE) -> 0 | AO16: =SUM(AL16:AN16) -> 1 | AP16: =SUMPRODUCT($AL$1:$AN$1,AL16:AN16) -> 0.061675 | AQ16: =(1+AP16)^(1/12)-1 -> 0.0049997782 | AR16: 0 | AS16: =IF(AR16=0,0,SUMPRODUCT($AL$3:$AN$3,AL16:AN16)) -> 0 | AT16: =1-(1-AS16)^(1/12) -> 0 | AU16: =SUMPRODUCT($AL$2:$AN$2,AL16:AN16) -> 0.0025 | AV16: =1-(1-AU16)^(1/12) -> 0.00020857243 | AX16: DIS | AY16: Non-Standard | AZ16: =AX16&"_"&AY16&"_"&BA16 -> DIS_Non-Standard_529 | BA16: 529 | BB16: =VLOOKUP($BA16,'[2]NonStandard DIS'!$Q$1:$X$542,2,FALSE) -> 0 | BC16: =VLOOKUP($BA16,'[2]NonStandard DIS'!$Q$1:$X$542,3,FALSE) -> 0 | BD16: =VLOOKUP($BA16,'[2]NonStandard DIS'!$Q$1:$X$542,4,FALSE) -> 0.308 | BE16: =VLOOKUP($BA16,'[2]NonStandard DIS'!$Q$1:$X$542,5,FALSE) -> 0.692 | BF16: =VLOOKUP($BA16,'[2]NonStandard DIS'!$Q$1:$X$542,6,FALSE) -> 0 | BG16: =VLOOKUP($BA16,'[2]NonStandard DIS'!$Q$1:$X$542,7,FALSE) -> 0 | BH16: =VLOOKUP($BA16,'[2]NonStandard DIS'!$Q$1:$X$542,8,FALSE) -> 0 | BI16: =SUM(BB16:BH16) -> 1 | BJ16: =SUMPRODUCT($BB$1:$BH$1,BB16:BH16) -> 0.0697285 | BK16: =(1+BJ16)^(1/12)-1 -> 0.0056328785 | BL16: 0 | BM16: =IF(BL16=0,0,SUMPRODUCT($BB$3:$BH$3,BB16:BH16)) -> 0 | BN16: =(1+BM16)^(1/12)-1 -> 0 | BO16: =SUMPRODUCT($BB$2:$BH$2,BB16:BH16) -> 0.0056776 | BP16: =(1+BO16)^(1/12)-1 -> 0.00047190658
... A436: Lifecycle | B436: Balanced | C436: =A436&"_"&B436&"_"&D436 -> Lifecycle_Balanced_109 | D436: 109 | E436: =VLOOKUP($D436,'[2]LC Balanced'!$Q$2:$U$542,2,FALSE) -> 0.37316667 | F436: =VLOOKUP($D436,'[2]LC Balanced'!$Q$2:$U$542,3,FALSE) -> 0.249 | G436: =VLOOKUP($D436,'[2]LC Balanced'!$Q$2:$U$542,4,FALSE) -> 0.37783333 | H436: =VLOOKUP($D436,'[2]LC Balanced'!$Q$2:$U$542,5,FALSE) -> 0 | I436: =SUM(E436:H436) -> 1 | J436: =SUMPRODUCT($E$1:$H$1,E436:H436) -> 0.051961387 | K436: =(1+J436)^(1/12)-1 -> 0.00423029 | L436: 0 | M436: =IF($L436=0,0,SUMPRODUCT($E$3:$H$3,E436:H436)) -> 0 | N436: =1-(1-M436)^(1/12) -> 0 | O436: =SUMPRODUCT($E$2:$H$2,E436:H436) -> 0.0050851 | P436: =1-(1-O436)^(1/12) -> 0.0004247492 | R436: Autopilot | S436: Balanced | T436: =R436&"_"&S436&"_"&U436 -> Autopilot_Balanced_109 | U436: 109 | V436: =VLOOKUP($U436,'[2]AP Balanced'!$Q$1:$T$542,2,FALSE) -> 0.125437 | W436: =VLOOKUP($U436,'[2]AP Balanced'!$Q$1:$T$542,3,FALSE) -> 0.874563 | X436: =VLOOKUP($U436,'[2]AP Balanced'!$Q$1:$T$542,4,FALSE) -> 0 | Y436: =SUM(V436:X436) -> 1 | Z436: =SUMPRODUCT($V$1:$X$1,V436:X436) -> 0.053015176 | AA436: =(1+Z436)^(1/12)-1 -> 0.0043140828 | AB436: 1 | AC436: =IF($AB436=0,0,SUMPRODUCT($V$3:$X$3,V436:X436)) -> 0.006750874 | AD436: =1-(1-AC436)^(1/12) -> 0.00056432106 | AE436: =SUMPRODUCT($V$2:$X$2,V436:X436) -> 0.0025 | AF436: =1-(1-AE436)^(1/12) -> 0.00020857243 | AH436: Lifecycle | AI436: Balanced | AJ436: =AH436&"_"&AI436&"_"&AK436 -> Lifecycle_Balanced_109 | AK436: 109 | AL436: =VLOOKUP($U436,[2]Standard_Balanced!$Q$1:$T$542,2,FALSE) -> 0.083509247 | AM436: =VLOOKUP($U436,[2]Standard_Balanced!$Q$1:$T$542,3,FALSE) -> 0.91649075 | AN436: =VLOOKUP($U436,[2]Standard_Balanced!$Q$1:$T$542,4,FALSE) -> 0 | AO436: =SUM(AL436:AN436) -> 1 | AP436: =SUMPRODUCT($AL$1:$AN$1,AL436:AN436) -> 0.052458585 | AQ436: =(1+AP436)^(1/12)-1 -> 0.0042698346 | AR436: 0 | AS436: =IF(AR436=0,0,SUMPRODUCT($AL$3:$AN$3,AL436:AN436)) -> 0 | AT436: =1-(1-AS436)^(1/12) -> 0 | AU436: =SUMPRODUCT($AL$2:$AN$2,AL436:AN436) -> 0.0025 | AV436: =1-(1-AU436)^(1/12) -> 0.00020857243 | AX436: DIS | AY436: Non-Standard | AZ436: =AX436&"_"&AY436&"_"&BA436 -> DIS_Non-Standard_109 | BA436: 109 | BB436: =VLOOKUP($BA436,'[2]NonStandard DIS'!$Q$1:$X$542,2,FALSE) -> 0.026916667 | BC436: =VLOOKUP($BA436,'[2]NonStandard DIS'!$Q$1:$X$542,3,FALSE) -> 0.31825 | BD436: =VLOOKUP($BA436,'[2]NonStandard DIS'!$Q$1:$X$542,4,FALSE) -> 0.65483333 | BE436: =VLOOKUP($BA436,'[2]NonStandard DIS'!$Q$1:$X$542,5,FALSE) -> 0 | BF436: =VLOOKUP($BA436,'[2]NonStandard DIS'!$Q$1:$X$542,6,FALSE) -> 0 | BG436: =VLOOKUP($BA436,'[2]NonStandard DIS'!$Q$1:$X$542,7,FALSE) -> 0 | BH436: =VLOOKUP($BA436,'[2]NonStandard DIS'!$Q$1:$X$542,8,FALSE) -> 0 | BI436: =SUM(BB436:BH436) -> 1 | BJ436: =SUMPRODUCT($BB$1:$BH$1,BB436:BH436) -> 0.058396444 | BK436: =(1+BJ436)^(1/12)-1 -> 0.0047407833 | BL436: 0 | BM436: =IF(BL436=0,0,SUMPRODUCT($BB$3:$BH$3,BB436:BH436)) -> 0 | BN436: =(1+BM436)^(1/12)-1 -> 0 | BO436: =SUMPRODUCT($BB$2:$BH$2,BB436:BH436) -> 0.006657075 | BP436: =(1+BO436)^(1/12)-1 -> 0.00055307076
A437: Lifecycle | B437: Balanced | C437: =A437&"_"&B437&"_"&D437 -> Lifecycle_Balanced_108 | D437: 108 | E437: =VLOOKUP($D437,'[2]LC Balanced'!$Q$2:$U$542,2,FALSE) -> 0.377 | F437: =VLOOKUP($D437,'[2]LC Balanced'!$Q$2:$U$542,3,FALSE) -> 0.247 | G437: =VLOOKUP($D437,'[2]LC Balanced'!$Q$2:$U$542,4,FALSE) -> 0.376 | H437: =VLOOKUP($D437,'[2]LC Balanced'!$Q$2:$U$542,5,FALSE) -> 0 | I437: =SUM(E437:H437) -> 1 | J437: =SUMPRODUCT($E$1:$H$1,E437:H437) -> 0.051911975 | K437: =(1+J437)^(1/12)-1 -> 0.004226359 | L437: 0 | M437: =IF($L437=0,0,SUMPRODUCT($E$3:$H$3,E437:H437)) -> 0 | N437: =1-(1-M437)^(1/12) -> 0 | O437: =SUMPRODUCT($E$2:$H$2,E437:H437) -> 0.0050693 | P437: =1-(1-O437)^(1/12) -> 0.00042342637 | R437: Autopilot | S437: Balanced | T437: =R437&"_"&S437&"_"&U437 -> Autopilot_Balanced_108 | U437: 108 | V437: =VLOOKUP($U437,'[2]AP Balanced'!$Q$1:$T$542,2,FALSE) -> 0.079697633 | W437: =VLOOKUP($U437,'[2]AP Balanced'!$Q$1:$T$542,3,FALSE) -> 0.92030237 | X437: =VLOOKUP($U437,'[2]AP Balanced'!$Q$1:$T$542,4,FALSE) -> 0 | Y437: =SUM(V437:X437) -> 1 | Z437: =SUMPRODUCT($V$1:$X$1,V437:X437) -> 0.052407986 | AA437: =(1+Z437)^(1/12)-1 -> 0.004265811 | AB437: 1 | AC437: =IF($AB437=0,0,SUMPRODUCT($V$3:$X$3,V437:X437)) -> 0.0066593953 | AD437: =1-(1-AC437)^(1/12) -> 0.00055665068 | AE437: =SUMPRODUCT($V$2:$X$2,V437:X437) -> 0.0025 | AF437: =1-(1-AE437)^(1/12) -> 0.00020857243 | AH437: Lifecycle | AI437: Balanced | AJ437: =AH437&"_"&AI437&"_"&AK437 -> Lifecycle_Balanced_108 | AK437: 108 | AL437: =VLOOKUP($U437,[2]Standard_Balanced!$Q$1:$T$542,2,FALSE) -> 0.079697633 | AM437: =VLOOKUP($U437,[2]Standard_Balanced!$Q$1:$T$542,3,FALSE) -> 0.92030237 | AN437: =VLOOKUP($U437,[2]Standard_Balanced!$Q$1:$T$542,4,FALSE) -> 0 | AO437: =SUM(AL437:AN437) -> 1 | AP437: =SUMPRODUCT($AL$1:$AN$1,AL437:AN437) -> 0.052407986 | AQ437: =(1+AP437)^(1/12)-1 -> 0.004265811 | AR437: 0 | AS437: =IF(AR437=0,0,SUMPRODUCT($AL$3:$AN$3,AL437:AN437)) -> 0 | AT437: =1-(1-AS437)^(1/12) -> 0 | AU437: =SUMPRODUCT($AL$2:$AN$2,AL437:AN437) -> 0.0025 | AV437: =1-(1-AU437)^(1/12) -> 0.00020857243 | AX437: DIS | AY437: Non-Standard | AZ437: =AX437&"_"&AY437&"_"&BA437 -> DIS_Non-Standard_108 | BA437: 108 | BB437: 0.028 | BC437: 0.323 | BD437: 0.649 | BE437: =VLOOKUP($BA437,'[2]NonStandard DIS'!$Q$1:$X$542,5,FALSE) -> 0 | BF437: =VLOOKUP($BA437,'[2]NonStandard DIS'!$Q$1:$X$542,6,FALSE) -> 0 | BG437: 0 | BH437: =VLOOKUP($BA437,'[2]NonStandard DIS'!$Q$1:$X$542,8,FALSE) -> 0 | BI437: =SUM(BB437:BH437) -> 1 | BJ437: =SUMPRODUCT($BB$1:$BH$1,BB437:BH437) -> 0.0582884 | BK437: =(1+BJ437)^(1/12)-1 -> 0.0047322357 | BL437: 0 | BM437: =IF(BL437=0,0,SUMPRODUCT($BB$3:$BH$3,BB437:BH437)) -> 0 | BN437: =(1+BM437)^(1/12)-1 -> 0 | BO437: =SUMPRODUCT($BB$2:$BH$2,BB437:BH437) -> 0.0066457 | BP437: =(1+BO437)^(1/12)-1 -> 0.00055212859
